Workbook

Sheet INPUT DATA
A1: Input Data Sheet for Electronic-Class Record (ECR)
B7: SCHOOL INFORMATION | I7: LEARNERS' NAMES
C10: REGION | D10: : | J10: MALE | M10: FEMALE
C11: DIVISION | D11: : | J11: 1 | M11: 1
J12: 2 | M12: 2
C13: SCHOOL ID | D13: : | J13: 3 | M13: 3
C14: SCHOOL NAME | D14: : | J14: 4 | M14: 4
C15: SCHOOL YEAR | D15: : | J15: 5 | M15: 5
C16: SCHOOL HEAD | D16: : | J16: 6 | M16: 6
J17: 7 | M17: 7
J18: 8 | M18: 8
J19: 9 | M19: 9
B20: TEACHER, GRADE LEVEL, SECTION INFORMATION | J20: 10 | M20: 10
J21: 11 | M21: 11
J22: 12 | M22: 12
C23: SUBJECT TEACHER | D23: : | J23: 13 | M23: 13
C24: SUBJECT | D24: : | J24: 14 | M24: 14
C25: GRADE LEVEL | D25: : | J25: 15 | M25: 15
C26: SECTION | D26: : | J26: 16 | M26: 16
J27: 17 | M27: 17
C28: IMPORTANT NOTE: This is the official and final version of the file. All tabs are password-protected to prevent accidental formula edits and maintain the accuracy and integrity of the data. If you identify any inconsistencies or issues, particularly with the formulas, please report them for appropriate review and necessary correction. | J28: 18 | M28: 18
J29: 19 | M29: 19
J30: 20 | M30: 20
J31: 21 | M31: 21
J32: 22 | M32: 22
J33: 23 | M33: 23
J34: 24 | M34: 24
J35: 25 | M35: 25
J36: 26 | M36: 26
J37: 27 | M37: 27
J38: 28 | M38: 28
J39: 29 | M39: 29
J40: 30 | M40: 30
... J60: 50 | M60: 50
O62: 2026_v1.0

Sheet TERM 1
B2: CLASS RECORD
E5: REGION | F5: ='INPUT DATA'!E10 -> 0 | Y5: DIVISION | Z5: ='INPUT DATA'!E11 -> 0 | AP5: SCHOOL ID | AQ5: ='INPUT DATA'!E13 -> 0
E7: SCHOOL NAME | F7: ='INPUT DATA'!E14 -> 0 | AP7: SCHOOL YEAR | AQ7: ='INPUT DATA'!E15 -> 0
B10: FIRST TERM | F10: GRADE LEVEL | J10: ='INPUT DATA'!E25 -> 0 | V10: TEACHER | AA10: ='INPUT DATA'!E23 -> 0 | AN10: SUBJECT | AR10: ='INPUT DATA'!E24 -> 0
F11: SECTION | J11: ='INPUT DATA'!E26 -> 0
F12: WRITTEN / ORAL WORKS (WWs) - 20% | V12: PRODUCT / PERFORMANCE TASKS (PTs) - 50% | AN12: EXAMINATIONS (EXs) - 30% | AV12: Initial Grade | AW12: Term Grade | AX12: Descriptor
F14: COGNITIVE DOMAIN | N14: AFFECTIVE DOMAIN | V14: COGNITIVE DOMAIN | AB14: AFFECTIVE DOMAIN | AH14: BEHAVIORAL DOMAIN
F15: 1 | G15: 2 | H15: 3 | I15: 4 | J15: 5 | K15: Total | L15: PS | M15: WS | N15: 1 | O15: 2 | P15: 3 | Q15: 4 | R15: 5 | S15: Total | T15: PS | U15: WS | V15: 1 | W15: 2 | X15: 3 | Y15: Total | Z15: PS | AA15: WS | AB15: 1 | AC15: 2 | AD15: 3 | AE15: Total | AF15: PS | AG15: WS | AH15: 1 | AI15: 2 | AJ15: 3 | AK15: Total | AL15: PS | AM15: WS | AN15: ST1 | AO15: ST2 | AP15: TE | AQ15: WS ST1 | AR15: WS ST2 | AS15: WS TE | AT15: PS | AU15: WS
B16: HIGHEST POSSIBLE SCORE | K16: =IF(COUNT($F16:$J16)=0,"",SUM($F16:$J16)) | L16: 100 | M16: 0.1 | S16: =IF(COUNT($N16:$R16)=0,"",SUM($N16:$R16)) | T16: 100 | U16: 0.1 | Y16: =IF(COUNT($V16:$X16)=0,"",SUM($V16:$X16)) | Z16: 100 | AA16: 0.1 | AE16: =IF(COUNT($AB16:$AD16)=0,"",SUM($AB16:$AD16)) | AF16: 100 | AG16: 0.1 | AK16: =IF(COUNT($AH16:$AJ16)=0,"",SUM($AH16:$AJ16)) | AL16: 100 | AM16: 0.3 | AQ16: 30 | AR16: 30 | AS16: 40 | AT16: 100 | AU16: 0.3
B17: LEARNERS' NAMES
B18: MALE
B19: 1 | C19: =IF('INPUT DATA'!K11="","",'INPUT DATA'!K11) | K19: =IF(COUNT($F19:$J19)=0,"",SUM($F19:$J19)) | L19: =IF(ISERROR(IF($K19="","",ROUND(($K19/$K$16)*$L$16,2))),"",IF($K19="","",ROUND(($K19/$K$16)*$L$16,2))) | M19: =IF($L19="","",ROUND($L19*$M$16,2)) | S19: =IF(COUNT($N19:$R19)=0,"",SUM($N19:$R19)) | T19: =IF(ISERROR(IF($S19="","",ROUND(($S19/$S$16)*$T$16,2))),"",IF($S19="","",ROUND(($S19/$S$16)*$T$16,2))) | U19: =IF($T19="","",ROUND($T19*$U$16,2)) | Y19: =IF(COUNT($V19:$X19)=0,"",SUM($V19:$X19)) | Z19: =IF(ISERROR(IF($Y19="","",ROUND(($Y19/$Y$16)*$Z$16,2))),"",IF($Y19="","",ROUND(($Y19/$Y$16)*$Z$16,2))) | AA19: =IF($Z19="","",ROUND($Z19*$AA$16,2)) | AE19: =IF(COUNT($AB19:$AD19)=0,"",SUM($AB19:$AD19)) | AF19: =IF(ISERROR(IF($AE19="","",ROUND(($AE19/$AE$16)*$AF$16,2))),"",IF($AE19="","",ROUND(($AE19/$AE$16)*$AF$16,2))) | AG19: =IF($AF19="","",ROUND($AF19*$AG$16,2)) | AK19: =IF(COUNT($AH19:$AJ19)=0,"",SUM($AH19:$AJ19)) | AL19: =IF(ISERROR(IF($AK19="","",ROUND(($AK19/$AK$16)*$AL$16,2))),"",IF($AK19="","",ROUND(($AK19/$AK$16)*$AL$16,2))) | AM19: =IF($AL19="","",ROUND($AL19*$AM$16,2)) | AQ19: =IFERROR(IF(AN19="","",ROUND(AN19/$AN$16*$AQ$16,2)),"") | AR19: =IFERROR(IF(AO19="","",ROUND(AO19/$AO$16*$AR$16,2)),"") | AS19: =IFERROR(IF(AP19="","",ROUND(AP19/$AP$16*$AS$16,2)),"") | AT19: =IF(COUNT($AQ19:$AS19)=0,"",SUM($AQ19:$AS19)) | AU19: =IFERROR(IF(AT19="","",ROUND(AT19*$AU$16,2)),"") | AV19: =IF(C19="","",IFERROR(ROUND(M19+U19+AA19+AG19+AM19+AU19,2),"")) | AW19: =IF(C19="","",IFERROR(_xlfn.XLOOKUP(AV19,HELPER!$C$8:$C$48,HELPER!$D$8:$D$48,,1),"")) | AX19: =IF(C19="","",IFERROR(_xlfn.XLOOKUP(AW19,HELPER!$F$8:$F$48,HELPER!$G$8:$G$48,,1),""))
B20: 2 | C20: =IF('INPUT DATA'!K12="","",'INPUT DATA'!K12) | K20: =IF(COUNT($F20:$J20)=0,"",SUM($F20:$J20)) | L20: =IF(ISERROR(IF($K20="","",ROUND(($K20/$K$16)*$L$16,2))),"",IF($K20="","",ROUND(($K20/$K$16)*$L$16,2))) | M20: =IF($L20="","",ROUND($L20*$M$16,2)) | S20: =IF(COUNT($N20:$R20)=0,"",SUM($N20:$R20)) | T20: =IF(ISERROR(IF($S20="","",ROUND(($S20/$S$16)*$T$16,2))),"",IF($S20="","",ROUND(($S20/$S$16)*$T$16,2))) | U20: =IF($T20="","",ROUND($T20*$U$16,2)) | Y20: =IF(COUNT($V20:$X20)=0,"",SUM($V20:$X20)) | Z20: =IF(ISERROR(IF($Y20="","",ROUND(($Y20/$Y$16)*$Z$16,2))),"",IF($Y20="","",ROUND(($Y20/$Y$16)*$Z$16,2))) | AA20: =IF($Z20="","",ROUND($Z20*$AA$16,2)) | AE20: =IF(COUNT($AB20:$AD20)=0,"",SUM($AB20:$AD20)) | AF20: =IF(ISERROR(IF($AE20="","",ROUND(($AE20/$AE$16)*$AF$16,2))),"",IF($AE20="","",ROUND(($AE20/$AE$16)*$AF$16,2))) | AG20: =IF($AF20="","",ROUND($AF20*$AG$16,2)) | AK20: =IF(COUNT($AH20:$AJ20)=0,"",SUM($AH20:$AJ20)) | AL20: =IF(ISERROR(IF($AK20="","",ROUND(($AK20/$AK$16)*$AL$16,2))),"",IF($AK20="","",ROUND(($AK20/$AK$16)*$AL$16,2))) | AM20: =IF($AL20="","",ROUND($AL20*$AM$16,2)) | AQ20: =IFERROR(IF(AN20="","",ROUND(AN20/$AN$16*$AQ$16,2)),"") | AR20: =IFERROR(IF(AO20="","",ROUND(AO20/$AO$16*$AR$16,2)),"") | AS20: =IFERROR(IF(AP20="","",ROUND(AP20/$AP$16*$AS$16,2)),"") | AT20: =IF(COUNT($AQ20:$AS20)=0,"",SUM($AQ20:$AS20)) | AU20: =IFERROR(IF(AT20="","",ROUND(AT20*$AU$16,2)),"") | AV20: =IF(C20="","",IFERROR(ROUND(M20+U20+AA20+AG20+AM20+AU20,2),"")) | AW20: =IF(C20="","",IFERROR(_xlfn.XLOOKUP(AV20,HELPER!$C$8:$C$48,HELPER!$D$8:$D$48,,1),"")) | AX20: =IF(C20="","",IFERROR(_xlfn.XLOOKUP(AW20,HELPER!$F$8:$F$48,HELPER!$G$8:$G$48,,1),""))
B21: 3 | C21: =IF('INPUT DATA'!K13="","",'INPUT DATA'!K13) | K21: =IF(COUNT($F21:$J21)=0,"",SUM($F21:$J21)) | L21: =IF(ISERROR(IF($K21="","",ROUND(($K21/$K$16)*$L$16,2))),"",IF($K21="","",ROUND(($K21/$K$16)*$L$16,2))) | M21: =IF($L21="","",ROUND($L21*$M$16,2)) | S21: =IF(COUNT($N21:$R21)=0,"",SUM($N21:$R21)) | T21: =IF(ISERROR(IF($S21="","",ROUND(($S21/$S$16)*$T$16,2))),"",IF($S21="","",ROUND(($S21/$S$16)*$T$16,2))) | U21: =IF($T21="","",ROUND($T21*$U$16,2)) | Y21: =IF(COUNT($V21:$X21)=0,"",SUM($V21:$X21)) | Z21: =IF(ISERROR(IF($Y21="","",ROUND(($Y21/$Y$16)*$Z$16,2))),"",IF($Y21="","",ROUND(($Y21/$Y$16)*$Z$16,2))) | AA21: =IF($Z21="","",ROUND($Z21*$AA$16,2)) | AE21: =IF(COUNT($AB21:$AD21)=0,"",SUM($AB21:$AD21)) | AF21: =IF(ISERROR(IF($AE21="","",ROUND(($AE21/$AE$16)*$AF$16,2))),"",IF($AE21="","",ROUND(($AE21/$AE$16)*$AF$16,2))) | AG21: =IF($AF21="","",ROUND($AF21*$AG$16,2)) | AK21: =IF(COUNT($AH21:$AJ21)=0,"",SUM($AH21:$AJ21)) | AL21: =IF(ISERROR(IF($AK21="","",ROUND(($AK21/$AK$16)*$AL$16,2))),"",IF($AK21="","",ROUND(($AK21/$AK$16)*$AL$16,2))) | AM21: =IF($AL21="","",ROUND($AL21*$AM$16,2)) | AQ21: =IFERROR(IF(AN21="","",ROUND(AN21/$AN$16*$AQ$16,2)),"") | AR21: =IFERROR(IF(AO21="","",ROUND(AO21/$AO$16*$AR$16,2)),"") | AS21: =IFERROR(IF(AP21="","",ROUND(AP21/$AP$16*$AS$16,2)),"") | AT21: =IF(COUNT($AQ21:$AS21)=0,"",SUM($AQ21:$AS21)) | AU21: =IFERROR(IF(AT21="","",ROUND(AT21*$AU$16,2)),"") | AV21: =IF(C21="","",IFERROR(ROUND(M21+U21+AA21+AG21+AM21+AU21,2),"")) | AW21: =IF(C21="","",IFERROR(_xlfn.XLOOKUP(AV21,HELPER!$C$8:$C$48,HELPER!$D$8:$D$48,,1),"")) | AX21: =IF(C21="","",IFERROR(_xlfn.XLOOKUP(AW21,HELPER!$F$8:$F$48,HELPER!$G$8:$G$48,,1),""))
B22: 4 | C22: =IF('INPUT DATA'!K14="","",'INPUT DATA'!K14) | K22: =IF(COUNT($F22:$J22)=0,"",SUM($F22:$J22)) | L22: =IF(ISERROR(IF($K22="","",ROUND(($K22/$K$16)*$L$16,2))),"",IF($K22="","",ROUND(($K22/$K$16)*$L$16,2))) | M22: =IF($L22="","",ROUND($L22*$M$16,2)) | S22: =IF(COUNT($N22:$R22)=0,"",SUM($N22:$R22)) | T22: =IF(ISERROR(IF($S22="","",ROUND(($S22/$S$16)*$T$16,2))),"",IF($S22="","",ROUND(($S22/$S$16)*$T$16,2))) | U22: =IF($T22="","",ROUND($T22*$U$16,2)) | Y22: =IF(COUNT($V22:$X22)=0,"",SUM($V22:$X22)) | Z22: =IF(ISERROR(IF($Y22="","",ROUND(($Y22/$Y$16)*$Z$16,2))),"",IF($Y22="","",ROUND(($Y22/$Y$16)*$Z$16,2))) | AA22: =IF($Z22="","",ROUND($Z22*$AA$16,2)) | AE22: =IF(COUNT($AB22:$AD22)=0,"",SUM($AB22:$AD22)) | AF22: =IF(ISERROR(IF($AE22="","",ROUND(($AE22/$AE$16)*$AF$16,2))),"",IF($AE22="","",ROUND(($AE22/$AE$16)*$AF$16,2))) | AG22: =IF($AF22="","",ROUND($AF22*$AG$16,2)) | AK22: =IF(COUNT($AH22:$AJ22)=0,"",SUM($AH22:$AJ22)) | AL22: =IF(ISERROR(IF($AK22="","",ROUND(($AK22/$AK$16)*$AL$16,2))),"",IF($AK22="","",ROUND(($AK22/$AK$16)*$AL$16,2))) | AM22: =IF($AL22="","",ROUND($AL22*$AM$16,2)) | AQ22: =IFERROR(IF(AN22="","",ROUND(AN22/$AN$16*$AQ$16,2)),"") | AR22: =IFERROR(IF(AO22="","",ROUND(AO22/$AO$16*$AR$16,2)),"") | AS22: =IFERROR(IF(AP22="","",ROUND(AP22/$AP$16*$AS$16,2)),"") | AT22: =IF(COUNT($AQ22:$AS22)=0,"",SUM($AQ22:$AS22)) | AU22: =IFERROR(IF(AT22="","",ROUND(AT22*$AU$16,2)),"") | AV22: =IF(C22="","",IFERROR(ROUND(M22+U22+AA22+AG22+AM22+AU22,2),"")) | AW22: =IF(C22="","",IFERROR(_xlfn.XLOOKUP(AV22,HELPER!$C$8:$C$48,HELPER!$D$8:$D$48,,1),"")) | AX22: =IF(C22="","",IFERROR(_xlfn.XLOOKUP(AW22,HELPER!$F$8:$F$48,HELPER!$G$8:$G$48,,1),""))
B23: 5 | C23: =IF('INPUT DATA'!K15="","",'INPUT DATA'!K15) | K23: =IF(COUNT($F23:$J23)=0,"",SUM($F23:$J23)) | L23: =IF(ISERROR(IF($K23="","",ROUND(($K23/$K$16)*$L$16,2))),"",IF($K23="","",ROUND(($K23/$K$16)*$L$16,2))) | M23: =IF($L23="","",ROUND($L23*$M$16,2)) | S23: =IF(COUNT($N23:$R23)=0,"",SUM($N23:$R23)) | T23: =IF(ISERROR(IF($S23="","",ROUND(($S23/$S$16)*$T$16,2))),"",IF($S23="","",ROUND(($S23/$S$16)*$T$16,2))) | U23: =IF($T23="","",ROUND($T23*$U$16,2)) | Y23: =IF(COUNT($V23:$X23)=0,"",SUM($V23:$X23)) | Z23: =IF(ISERROR(IF($Y23="","",ROUND(($Y23/$Y$16)*$Z$16,2))),"",IF($Y23="","",ROUND(($Y23/$Y$16)*$Z$16,2))) | AA23: =IF($Z23="","",ROUND($Z23*$AA$16,2)) | AE23: =IF(COUNT($AB23:$AD23)=0,"",SUM($AB23:$AD23)) | AF23: =IF(ISERROR(IF($AE23="","",ROUND(($AE23/$AE$16)*$AF$16,2))),"",IF($AE23="","",ROUND(($AE23/$AE$16)*$AF$16,2))) | AG23: =IF($AF23="","",ROUND($AF23*$AG$16,2)) | AK23: =IF(COUNT($AH23:$AJ23)=0,"",SUM($AH23:$AJ23)) | AL23: =IF(ISERROR(IF($AK23="","",ROUND(($AK23/$AK$16)*$AL$16,2))),"",IF($AK23="","",ROUND(($AK23/$AK$16)*$AL$16,2))) | AM23: =IF($AL23="","",ROUND($AL23*$AM$16,2)) | AQ23: =IFERROR(IF(AN23="","",ROUND(AN23/$AN$16*$AQ$16,2)),"") | AR23: =IFERROR(IF(AO23="","",ROUND(AO23/$AO$16*$AR$16,2)),"") | AS23: =IFERROR(IF(AP23="","",ROUND(AP23/$AP$16*$AS$16,2)),"") | AT23: =IF(COUNT($AQ23:$AS23)=0,"",SUM($AQ23:$AS23)) | AU23: =IFERROR(IF(AT23="","",ROUND(AT23*$AU$16,2)),"") | AV23: =IF(C23="","",IFERROR(ROUND(M23+U23+AA23+AG23+AM23+AU23,2),"")) | AW23: =IF(C23="","",IFERROR(_xlfn.XLOOKUP(AV23,HELPER!$C$8:$C$48,HELPER!$D$8:$D$48,,1),"")) | AX23: =IF(C23="","",IFERROR(_xlfn.XLOOKUP(AW23,HELPER!$F$8:$F$48,HELPER!$G$8:$G$48,,1),""))
B24: 6 | C24: =IF('INPUT DATA'!K16="","",'INPUT DATA'!K16) | K24: =IF(COUNT($F24:$J24)=0,"",SUM($F24:$J24)) | L24: =IF(ISERROR(IF($K24="","",ROUND(($K24/$K$16)*$L$16,2))),"",IF($K24="","",ROUND(($K24/$K$16)*$L$16,2))) | M24: =IF($L24="","",ROUND($L24*$M$16,2)) | S24: =IF(COUNT($N24:$R24)=0,"",SUM($N24:$R24)) | T24: =IF(ISERROR(IF($S24="","",ROUND(($S24/$S$16)*$T$16,2))),"",IF($S24="","",ROUND(($S24/$S$16)*$T$16,2))) | U24: =IF($T24="","",ROUND($T24*$U$16,2)) | Y24: =IF(COUNT($V24:$X24)=0,"",SUM($V24:$X24)) | Z24: =IF(ISERROR(IF($Y24="","",ROUND(($Y24/$Y$16)*$Z$16,2))),"",IF($Y24="","",ROUND(($Y24/$Y$16)*$Z$16,2))) | AA24: =IF($Z24="","",ROUND($Z24*$AA$16,2)) | AE24: =IF(COUNT($AB24:$AD24)=0,"",SUM($AB24:$AD24)) | AF24: =IF(ISERROR(IF($AE24="","",ROUND(($AE24/$AE$16)*$AF$16,2))),"",IF($AE24="","",ROUND(($AE24/$AE$16)*$AF$16,2))) | AG24: =IF($AF24="","",ROUND($AF24*$AG$16,2)) | AK24: =IF(COUNT($AH24:$AJ24)=0,"",SUM($AH24:$AJ24)) | AL24: =IF(ISERROR(IF($AK24="","",ROUND(($AK24/$AK$16)*$AL$16,2))),"",IF($AK24="","",ROUND(($AK24/$AK$16)*$AL$16,2))) | AM24: =IF($AL24="","",ROUND($AL24*$AM$16,2)) | AQ24: =IFERROR(IF(AN24="","",ROUND(AN24/$AN$16*$AQ$16,2)),"") | AR24: =IFERROR(IF(AO24="","",ROUND(AO24/$AO$16*$AR$16,2)),"") | AS24: =IFERROR(IF(AP24="","",ROUND(AP24/$AP$16*$AS$16,2)),"") | AT24: =IF(COUNT($AQ24:$AS24)=0,"",SUM($AQ24:$AS24)) | AU24: =IFERROR(IF(AT24="","",ROUND(AT24*$AU$16,2)),"") | AV24: =IF(C24="","",IFERROR(ROUND(M24+U24+AA24+AG24+AM24+AU24,2),"")) | AW24: =IF(C24="","",IFERROR(_xlfn.XLOOKUP(AV24,HELPER!$C$8:$C$48,HELPER!$D$8:$D$48,,1),"")) | AX24: =IF(C24="","",IFERROR(_xlfn.XLOOKUP(AW24,HELPER!$F$8:$F$48,HELPER!$G$8:$G$48,,1),""))
B25: 7 | C25: =IF('INPUT DATA'!K17="","",'INPUT DATA'!K17) | K25: =IF(COUNT($F25:$J25)=0,"",SUM($F25:$J25)) | L25: =IF(ISERROR(IF($K25="","",ROUND(($K25/$K$16)*$L$16,2))),"",IF($K25="","",ROUND(($K25/$K$16)*$L$16,2))) | M25: =IF($L25="","",ROUND($L25*$M$16,2)) | S25: =IF(COUNT($N25:$R25)=0,"",SUM($N25:$R25)) | T25: =IF(ISERROR(IF($S25="","",ROUND(($S25/$S$16)*$T$16,2))),"",IF($S25="","",ROUND(($S25/$S$16)*$T$16,2))) | U25: =IF($T25="","",ROUND($T25*$U$16,2)) | Y25: =IF(COUNT($V25:$X25)=0,"",SUM($V25:$X25)) | Z25: =IF(ISERROR(IF($Y25="","",ROUND(($Y25/$Y$16)*$Z$16,2))),"",IF($Y25="","",ROUND(($Y25/$Y$16)*$Z$16,2))) | AA25: =IF($Z25="","",ROUND($Z25*$AA$16,2)) | AE25: =IF(COUNT($AB25:$AD25)=0,"",SUM($AB25:$AD25)) | AF25: =IF(ISERROR(IF($AE25="","",ROUND(($AE25/$AE$16)*$AF$16,2))),"",IF($AE25="","",ROUND(($AE25/$AE$16)*$AF$16,2))) | AG25: =IF($AF25="","",ROUND($AF25*$AG$16,2)) | AK25: =IF(COUNT($AH25:$AJ25)=0,"",SUM($AH25:$AJ25)) | AL25: =IF(ISERROR(IF($AK25="","",ROUND(($AK25/$AK$16)*$AL$16,2))),"",IF($AK25="","",ROUND(($AK25/$AK$16)*$AL$16,2))) | AM25: =IF($AL25="","",ROUND($AL25*$AM$16,2)) | AQ25: =IFERROR(IF(AN25="","",ROUND(AN25/$AN$16*$AQ$16,2)),"") | AR25: =IFERROR(IF(AO25="","",ROUND(AO25/$AO$16*$AR$16,2)),"") | AS25: =IFERROR(IF(AP25="","",ROUND(AP25/$AP$16*$AS$16,2)),"") | AT25: =IF(COUNT($AQ25:$AS25)=0,"",SUM($AQ25:$AS25)) | AU25: =IFERROR(IF(AT25="","",ROUND(AT25*$AU$16,2)),"") | AV25: =IF(C25="","",IFERROR(ROUND(M25+U25+AA25+AG25+AM25+AU25,2),"")) | AW25: =IF(C25="","",IFERROR(_xlfn.XLOOKUP(AV25,HELPER!$C$8:$C$48,HELPER!$D$8:$D$48,,1),"")) | AX25: =IF(C25="","",IFERROR(_xlfn.XLOOKUP(AW25,HELPER!$F$8:$F$48,HELPER!$G$8:$G$48,,1),""))
B26: 8 | C26: =IF('INPUT DATA'!K18="","",'INPUT DATA'!K18) | K26: =IF(COUNT($F26:$J26)=0,"",SUM($F26:$J26)) | L26: =IF(ISERROR(IF($K26="","",ROUND(($K26/$K$16)*$L$16,2))),"",IF($K26="","",ROUND(($K26/$K$16)*$L$16,2))) | M26: =IF($L26="","",ROUND($L26*$M$16,2)) | S26: =IF(COUNT($N26:$R26)=0,"",SUM($N26:$R26)) | T26: =IF(ISERROR(IF($S26="","",ROUND(($S26/$S$16)*$T$16,2))),"",IF($S26="","",ROUND(($S26/$S$16)*$T$16,2))) | U26: =IF($T26="","",ROUND($T26*$U$16,2)) | Y26: =IF(COUNT($V26:$X26)=0,"",SUM($V26:$X26)) | Z26: =IF(ISERROR(IF($Y26="","",ROUND(($Y26/$Y$16)*$Z$16,2))),"",IF($Y26="","",ROUND(($Y26/$Y$16)*$Z$16,2))) | AA26: =IF($Z26="","",ROUND($Z26*$AA$16,2)) | AE26: =IF(COUNT($AB26:$AD26)=0,"",SUM($AB26:$AD26)) | AF26: =IF(ISERROR(IF($AE26="","",ROUND(($AE26/$AE$16)*$AF$16,2))),"",IF($AE26="","",ROUND(($AE26/$AE$16)*$AF$16,2))) | AG26: =IF($AF26="","",ROUND($AF26*$AG$16,2)) | AK26: =IF(COUNT($AH26:$AJ26)=0,"",SUM($AH26:$AJ26)) | AL26: =IF(ISERROR(IF($AK26="","",ROUND(($AK26/$AK$16)*$AL$16,2))),"",IF($AK26="","",ROUND(($AK26/$AK$16)*$AL$16,2))) | AM26: =IF($AL26="","",ROUND($AL26*$AM$16,2)) | AQ26: =IFERROR(IF(AN26="","",ROUND(AN26/$AN$16*$AQ$16,2)),"") | AR26: =IFERROR(IF(AO26="","",ROUND(AO26/$AO$16*$AR$16,2)),"") | AS26: =IFERROR(IF(AP26="","",ROUND(AP26/$AP$16*$AS$16,2)),"") | AT26: =IF(COUNT($AQ26:$AS26)=0,"",SUM($AQ26:$AS26)) | AU26: =IFERROR(IF(AT26="","",ROUND(AT26*$AU$16,2)),"") | AV26: =IF(C26="","",IFERROR(ROUND(M26+U26+AA26+AG26+AM26+AU26,2),"")) | AW26: =IF(C26="","",IFERROR(_xlfn.XLOOKUP(AV26,HELPER!$C$8:$C$48,HELPER!$D$8:$D$48,,1),"")) | AX26: =IF(C26="","",IFERROR(_xlfn.XLOOKUP(AW26,HELPER!$F$8:$F$48,HELPER!$G$8:$G$48,,1),""))
B27: 9 | C27: =IF('INPUT DATA'!K19="","",'INPUT DATA'!K19) | K27: =IF(COUNT($F27:$J27)=0,"",SUM($F27:$J27)) | L27: =IF(ISERROR(IF($K27="","",ROUND(($K27/$K$16)*$L$16,2))),"",IF($K27="","",ROUND(($K27/$K$16)*$L$16,2))) | M27: =IF($L27="","",ROUND($L27*$M$16,2)) | S27: =IF(COUNT($N27:$R27)=0,"",SUM($N27:$R27)) | T27: =IF(ISERROR(IF($S27="","",ROUND(($S27/$S$16)*$T$16,2))),"",IF($S27="","",ROUND(($S27/$S$16)*$T$16,2))) | U27: =IF($T27="","",ROUND($T27*$U$16,2)) | Y27: =IF(COUNT($V27:$X27)=0,"",SUM($V27:$X27)) | Z27: =IF(ISERROR(IF($Y27="","",ROUND(($Y27/$Y$16)*$Z$16,2))),"",IF($Y27="","",ROUND(($Y27/$Y$16)*$Z$16,2))) | AA27: =IF($Z27="","",ROUND($Z27*$AA$16,2)) | AE27: =IF(COUNT($AB27:$AD27)=0,"",SUM($AB27:$AD27)) | AF27: =IF(ISERROR(IF($AE27="","",ROUND(($AE27/$AE$16)*$AF$16,2))),"",IF($AE27="","",ROUND(($AE27/$AE$16)*$AF$16,2))) | AG27: =IF($AF27="","",ROUND($AF27*$AG$16,2)) | AK27: =IF(COUNT($AH27:$AJ27)=0,"",SUM($AH27:$AJ27)) | AL27: =IF(ISERROR(IF($AK27="","",ROUND(($AK27/$AK$16)*$AL$16,2))),"",IF($AK27="","",ROUND(($AK27/$AK$16)*$AL$16,2))) | AM27: =IF($AL27="","",ROUND($AL27*$AM$16,2)) | AQ27: =IFERROR(IF(AN27="","",ROUND(AN27/$AN$16*$AQ$16,2)),"") | AR27: =IFERROR(IF(AO27="","",ROUND(AO27/$AO$16*$AR$16,2)),"") | AS27: =IFERROR(IF(AP27="","",ROUND(AP27/$AP$16*$AS$16,2)),"") | AT27: =IF(COUNT($AQ27:$AS27)=0,"",SUM($AQ27:$AS27)) | AU27: =IFERROR(IF(AT27="","",ROUND(AT27*$AU$16,2)),"") | AV27: =IF(C27="","",IFERROR(ROUND(M27+U27+AA27+AG27+AM27+AU27,2),"")) | AW27: =IF(C27="","",IFERROR(_xlfn.XLOOKUP(AV27,HELPER!$C$8:$C$48,HELPER!$D$8:$D$48,,1),"")) | AX27: =IF(C27="","",IFERROR(_xlfn.XLOOKUP(AW27,HELPER!$F$8:$F$48,HELPER!$G$8:$G$48,,1),""))
B28: 10 | C28: =IF('INPUT DATA'!K20="","",'INPUT DATA'!K20) | K28: =IF(COUNT($F28:$J28)=0,"",SUM($F28:$J28)) | L28: =IF(ISERROR(IF($K28="","",ROUND(($K28/$K$16)*$L$16,2))),"",IF($K28="","",ROUND(($K28/$K$16)*$L$16,2))) | M28: =IF($L28="","",ROUND($L28*$M$16,2)) | S28: =IF(COUNT($N28:$R28)=0,"",SUM($N28:$R28)) | T28: =IF(ISERROR(IF($S28="","",ROUND(($S28/$S$16)*$T$16,2))),"",IF($S28="","",ROUND(($S28/$S$16)*$T$16,2))) | U28: =IF($T28="","",ROUND($T28*$U$16,2)) | Y28: =IF(COUNT($V28:$X28)=0,"",SUM($V28:$X28)) | Z28: =IF(ISERROR(IF($Y28="","",ROUND(($Y28/$Y$16)*$Z$16,2))),"",IF($Y28="","",ROUND(($Y28/$Y$16)*$Z$16,2))) | AA28: =IF($Z28="","",ROUND($Z28*$AA$16,2)) | AE28: =IF(COUNT($AB28:$AD28)=0,"",SUM($AB28:$AD28)) | AF28: =IF(ISERROR(IF($AE28="","",ROUND(($AE28/$AE$16)*$AF$16,2))),"",IF($AE28="","",ROUND(($AE28/$AE$16)*$AF$16,2))) | AG28: =IF($AF28="","",ROUND($AF28*$AG$16,2)) | AK28: =IF(COUNT($AH28:$AJ28)=0,"",SUM($AH28:$AJ28)) | AL28: =IF(ISERROR(IF($AK28="","",ROUND(($AK28/$AK$16)*$AL$16,2))),"",IF($AK28="","",ROUND(($AK28/$AK$16)*$AL$16,2))) | AM28: =IF($AL28="","",ROUND($AL28*$AM$16,2)) | AQ28: =IFERROR(IF(AN28="","",ROUND(AN28/$AN$16*$AQ$16,2)),"") | AR28: =IFERROR(IF(AO28="","",ROUND(AO28/$AO$16*$AR$16,2)),"") | AS28: =IFERROR(IF(AP28="","",ROUND(AP28/$AP$16*$AS$16,2)),"") | AT28: =IF(COUNT($AQ28:$AS28)=0,"",SUM($AQ28:$AS28)) | AU28: =IFERROR(IF(AT28="","",ROUND(AT28*$AU$16,2)),"") | AV28: =IF(C28="","",IFERROR(ROUND(M28+U28+AA28+AG28+AM28+AU28,2),"")) | AW28: =IF(C28="","",IFERROR(_xlfn.XLOOKUP(AV28,HELPER!$C$8:$C$48,HELPER!$D$8:$D$48,,1),"")) | AX28: =IF(C28="","",IFERROR(_xlfn.XLOOKUP(AW28,HELPER!$F$8:$F$48,HELPER!$G$8:$G$48,,1),""))
B29: 11 | C29: =IF('INPUT DATA'!K21="","",'INPUT DATA'!K21) | K29: =IF(COUNT($F29:$J29)=0,"",SUM($F29:$J29)) | L29: =IF(ISERROR(IF($K29="","",ROUND(($K29/$K$16)*$L$16,2))),"",IF($K29="","",ROUND(($K29/$K$16)*$L$16,2))) | M29: =IF($L29="","",ROUND($L29*$M$16,2)) | S29: =IF(COUNT($N29:$R29)=0,"",SUM($N29:$R29)) | T29: =IF(ISERROR(IF($S29="","",ROUND(($S29/$S$16)*$T$16,2))),"",IF($S29="","",ROUND(($S29/$S$16)*$T$16,2))) | U29: =IF($T29="","",ROUND($T29*$U$16,2)) | Y29: =IF(COUNT($V29:$X29)=0,"",SUM($V29:$X29)) | Z29: =IF(ISERROR(IF($Y29="","",ROUND(($Y29/$Y$16)*$Z$16,2))),"",IF($Y29="","",ROUND(($Y29/$Y$16)*$Z$16,2))) | AA29: =IF($Z29="","",ROUND($Z29*$AA$16,2)) | AE29: =IF(COUNT($AB29:$AD29)=0,"",SUM($AB29:$AD29)) | AF29: =IF(ISERROR(IF($AE29="","",ROUND(($AE29/$AE$16)*$AF$16,2))),"",IF($AE29="","",ROUND(($AE29/$AE$16)*$AF$16,2))) | AG29: =IF($AF29="","",ROUND($AF29*$AG$16,2)) | AK29: =IF(COUNT($AH29:$AJ29)=0,"",SUM($AH29:$AJ29)) | AL29: =IF(ISERROR(IF($AK29="","",ROUND(($AK29/$AK$16)*$AL$16,2))),"",IF($AK29="","",ROUND(($AK29/$AK$16)*$AL$16,2))) | AM29: =IF($AL29="","",ROUND($AL29*$AM$16,2)) | AQ29: =IFERROR(IF(AN29="","",ROUND(AN29/$AN$16*$AQ$16,2)),"") | AR29: =IFERROR(IF(AO29="","",ROUND(AO29/$AO$16*$AR$16,2)),"") | AS29: =IFERROR(IF(AP29="","",ROUND(AP29/$AP$16*$AS$16,2)),"") | AT29: =IF(COUNT($AQ29:$AS29)=0,"",SUM($AQ29:$AS29)) | AU29: =IFERROR(IF(AT29="","",ROUND(AT29*$AU$16,2)),"") | AV29: =IF(C29="","",IFERROR(ROUND(M29+U29+AA29+AG29+AM29+AU29,2),"")) | AW29: =IF(C29="","",IFERROR(_xlfn.XLOOKUP(AV29,HELPER!$C$8:$C$48,HELPER!$D$8:$D$48,,1),"")) | AX29: =IF(C29="","",IFERROR(_xlfn.XLOOKUP(AW29,HELPER!$F$8:$F$48,HELPER!$G$8:$G$48,,1),""))
B30: 12 | C30: =IF('INPUT DATA'!K22="","",'INPUT DATA'!K22) | K30: =IF(COUNT($F30:$J30)=0,"",SUM($F30:$J30)) | L30: =IF(ISERROR(IF($K30="","",ROUND(($K30/$K$16)*$L$16,2))),"",IF($K30="","",ROUND(($K30/$K$16)*$L$16,2))) | M30: =IF($L30="","",ROUND($L30*$M$16,2)) | S30: =IF(COUNT($N30:$R30)=0,"",SUM($N30:$R30)) | T30: =IF(ISERROR(IF($S30="","",ROUND(($S30/$S$16)*$T$16,2))),"",IF($S30="","",ROUND(($S30/$S$16)*$T$16,2))) | U30: =IF($T30="","",ROUND($T30*$U$16,2)) | Y30: =IF(COUNT($V30:$X30)=0,"",SUM($V30:$X30)) | Z30: =IF(ISERROR(IF($Y30="","",ROUND(($Y30/$Y$16)*$Z$16,2))),"",IF($Y30="","",ROUND(($Y30/$Y$16)*$Z$16,2))) | AA30: =IF($Z30="","",ROUND($Z30*$AA$16,2)) | AE30: =IF(COUNT($AB30:$AD30)=0,"",SUM($AB30:$AD30)) | AF30: =IF(ISERROR(IF($AE30="","",ROUND(($AE30/$AE$16)*$AF$16,2))),"",IF($AE30="","",ROUND(($AE30/$AE$16)*$AF$16,2))) | AG30: =IF($AF30="","",ROUND($AF30*$AG$16,2)) | AK30: =IF(COUNT($AH30:$AJ30)=0,"",SUM($AH30:$AJ30)) | AL30: =IF(ISERROR(IF($AK30="","",ROUND(($AK30/$AK$16)*$AL$16,2))),"",IF($AK30="","",ROUND(($AK30/$AK$16)*$AL$16,2))) | AM30: =IF($AL30="","",ROUND($AL30*$AM$16,2)) | AQ30: =IFERROR(IF(AN30="","",ROUND(AN30/$AN$16*$AQ$16,2)),"") | AR30: =IFERROR(IF(AO30="","",ROUND(AO30/$AO$16*$AR$16,2)),"") | AS30: =IFERROR(IF(AP30="","",ROUND(AP30/$AP$16*$AS$16,2)),"") | AT30: =IF(COUNT($AQ30:$AS30)=0,"",SUM($AQ30:$AS30)) | AU30: =IFERROR(IF(AT30="","",ROUND(AT30*$AU$16,2)),"") | AV30: =IF(C30="","",IFERROR(ROUND(M30+U30+AA30+AG30+AM30+AU30,2),"")) | AW30: =IF(C30="","",IFERROR(_xlfn.XLOOKUP(AV30,HELPER!$C$8:$C$48,HELPER!$D$8:$D$48,,1),"")) | AX30: =IF(C30="","",IFERROR(_xlfn.XLOOKUP(AW30,HELPER!$F$8:$F$48,HELPER!$G$8:$G$48,,1),""))
... B68: 50 | C68: =IF('INPUT DATA'!K60="","",'INPUT DATA'!K60) | K68: =IF(COUNT($F68:$J68)=0,"",SUM($F68:$J68)) | L68: =IF(ISERROR(IF($K68="","",ROUND(($K68/$K$16)*$L$16,2))),"",IF($K68="","",ROUND(($K68/$K$16)*$L$16,2))) | M68: =IF($L68="","",ROUND($L68*$M$16,2)) | S68: =IF(COUNT($N68:$R68)=0,"",SUM($N68:$R68)) | T68: =IF(ISERROR(IF($S68="","",ROUND(($S68/$S$16)*$T$16,2))),"",IF($S68="","",ROUND(($S68/$S$16)*$T$16,2))) | U68: =IF($T68="","",ROUND($T68*$U$16,2)) | Y68: =IF(COUNT($V68:$X68)=0,"",SUM($V68:$X68)) | Z68: =IF(ISERROR(IF($Y68="","",ROUND(($Y68/$Y$16)*$Z$16,2))),"",IF($Y68="","",ROUND(($Y68/$Y$16)*$Z$16,2))) | AA68: =IF($Z68="","",ROUND($Z68*$AA$16,2)) | AE68: =IF(COUNT($AB68:$AD68)=0,"",SUM($AB68:$AD68)) | AF68: =IF(ISERROR(IF($AE68="","",ROUND(($AE68/$AE$16)*$AF$16,2))),"",IF($AE68="","",ROUND(($AE68/$AE$16)*$AF$16,2))) | AG68: =IF($AF68="","",ROUND($AF68*$AG$16,2)) | AK68: =IF(COUNT($AH68:$AJ68)=0,"",SUM($AH68:$AJ68)) | AL68: =IF(ISERROR(IF($AK68="","",ROUND(($AK68/$AK$16)*$AL$16,2))),"",IF($AK68="","",ROUND(($AK68/$AK$16)*$AL$16,2))) | AM68: =IF($AL68="","",ROUND($AL68*$AM$16,2)) | AQ68: =IFERROR(IF(AN68="","",ROUND(AN68/$AN$16*$AQ$16,2)),"") | AR68: =IFERROR(IF(AO68="","",ROUND(AO68/$AO$16*$AR$16,2)),"") | AS68: =IFERROR(IF(AP68="","",ROUND(AP68/$AP$16*$AS$16,2)),"") | AT68: =IF(COUNT($AQ68:$AS68)=0,"",SUM($AQ68:$AS68)) | AU68: =IFERROR(IF(AT68="","",ROUND(AT68*$AU$16,2)),"") | AV68: =IF(C68="","",IFERROR(ROUND(M68+U68+AA68+AG68+AM68+AU68,2),"")) | AW68: =IF(C68="","",IFERROR(_xlfn.XLOOKUP(AV68,HELPER!$C$8:$C$48,HELPER!$D$8:$D$48,,1),"")) | AX68: =IF(C68="","",IFERROR(_xlfn.XLOOKUP(AW68,HELPER!$F$8:$F$48,HELPER!$G$8:$G$48,,1),""))
B69: FEMALE
B70: 1 | C70: =IF('INPUT DATA'!N11="","",'INPUT DATA'!N11) | K70: =IF(COUNT($F70:$J70)=0,"",SUM($F70:$J70)) | L70: =IF(ISERROR(IF($K70="","",ROUND(($K70/$K$16)*$L$16,2))),"",IF($K70="","",ROUND(($K70/$K$16)*$L$16,2))) | M70: =IF($L70="","",ROUND($L70*$M$16,2)) | S70: =IF(COUNT($N70:$R70)=0,"",SUM($N70:$R70)) | T70: =IF(ISERROR(IF($S70="","",ROUND(($S70/$S$16)*$T$16,2))),"",IF($S70="","",ROUND(($S70/$S$16)*$T$16,2))) | U70: =IF($T70="","",ROUND($T70*$U$16,2)) | Y70: =IF(COUNT($V70:$X70)=0,"",SUM($V70:$X70)) | Z70: =IF(ISERROR(IF($Y70="","",ROUND(($Y70/$Y$16)*$Z$16,2))),"",IF($Y70="","",ROUND(($Y70/$Y$16)*$Z$16,2))) | AA70: =IF($Z70="","",ROUND($Z70*$AA$16,2)) | AE70: =IF(COUNT($AB70:$AD70)=0,"",SUM($AB70:$AD70)) | AF70: =IF(ISERROR(IF($AE70="","",ROUND(($AE70/$AE$16)*$AF$16,2))),"",IF($AE70="","",ROUND(($AE70/$AE$16)*$AF$16,2))) | AG70: =IF($AF70="","",ROUND($AF70*$AG$16,2)) | AK70: =IF(COUNT($AH70:$AJ70)=0,"",SUM($AH70:$AJ70)) | AL70: =IF(ISERROR(IF($AK70="","",ROUND(($AK70/$AK$16)*$AL$16,2))),"",IF($AK70="","",ROUND(($AK70/$AK$16)*$AL$16,2))) | AM70: =IF($AL70="","",ROUND($AL70*$AM$16,2)) | AQ70: =IFERROR(IF(AN70="","",ROUND(AN70/$AN$16*$AQ$16,2)),"") | AR70: =IFERROR(IF(AO70="","",ROUND(AO70/$AO$16*$AR$16,2)),"") | AS70: =IFERROR(IF(AP70="","",ROUND(AP70/$AP$16*$AS$16,2)),"") | AT70: =IF(COUNT($AQ70:$AS70)=0,"",SUM($AQ70:$AS70)) | AU70: =IFERROR(IF(AT70="","",ROUND(AT70*$AU$16,2)),"") | AV70: =IF(C70="","",IFERROR(ROUND(M70+U70+AA70+AG70+AM70+AU70,2),"")) | AW70: =IF(C70="","",IFERROR(_xlfn.XLOOKUP(AV70,HELPER!$C$8:$C$48,HELPER!$D$8:$D$48,,1),"")) | AX70: =IF(C70="","",IFERROR(_xlfn.XLOOKUP(AW70,HELPER!$F$8:$F$48,HELPER!$G$8:$G$48,,1),""))
B71: 2 | C71: =IF('INPUT DATA'!N12="","",'INPUT DATA'!N12) | K71: =IF(COUNT($F71:$J71)=0,"",SUM($F71:$J71)) | L71: =IF(ISERROR(IF($K71="","",ROUND(($K71/$K$16)*$L$16,2))),"",IF($K71="","",ROUND(($K71/$K$16)*$L$16,2))) | M71: =IF($L71="","",ROUND($L71*$M$16,2)) | S71: =IF(COUNT($N71:$R71)=0,"",SUM($N71:$R71)) | T71: =IF(ISERROR(IF($S71="","",ROUND(($S71/$S$16)*$T$16,2))),"",IF($S71="","",ROUND(($S71/$S$16)*$T$16,2))) | U71: =IF($T71="","",ROUND($T71*$U$16,2)) | Y71: =IF(COUNT($V71:$X71)=0,"",SUM($V71:$X71)) | Z71: =IF(ISERROR(IF($Y71="","",ROUND(($Y71/$Y$16)*$Z$16,2))),"",IF($Y71="","",ROUND(($Y71/$Y$16)*$Z$16,2))) | AA71: =IF($Z71="","",ROUND($Z71*$AA$16,2)) | AE71: =IF(COUNT($AB71:$AD71)=0,"",SUM($AB71:$AD71)) | AF71: =IF(ISERROR(IF($AE71="","",ROUND(($AE71/$AE$16)*$AF$16,2))),"",IF($AE71="","",ROUND(($AE71/$AE$16)*$AF$16,2))) | AG71: =IF($AF71="","",ROUND($AF71*$AG$16,2)) | AK71: =IF(COUNT($AH71:$AJ71)=0,"",SUM($AH71:$AJ71)) | AL71: =IF(ISERROR(IF($AK71="","",ROUND(($AK71/$AK$16)*$AL$16,2))),"",IF($AK71="","",ROUND(($AK71/$AK$16)*$AL$16,2))) | AM71: =IF($AL71="","",ROUND($AL71*$AM$16,2)) | AQ71: =IFERROR(IF(AN71="","",ROUND(AN71/$AN$16*$AQ$16,2)),"") | AR71: =IFERROR(IF(AO71="","",ROUND(AO71/$AO$16*$AR$16,2)),"") | AS71: =IFERROR(IF(AP71="","",ROUND(AP71/$AP$16*$AS$16,2)),"") | AT71: =IF(COUNT($AQ71:$AS71)=0,"",SUM($AQ71:$AS71)) | AU71: =IFERROR(IF(AT71="","",ROUND(AT71*$AU$16,2)),"") | AV71: =IF(C71="","",IFERROR(ROUND(M71+U71+AA71+AG71+AM71+AU71,2),"")) | AW71: =IF(C71="","",IFERROR(_xlfn.XLOOKUP(AV71,HELPER!$C$8:$C$48,HELPER!$D$8:$D$48,,1),"")) | AX71: =IF(C71="","",IFERROR(_xlfn.XLOOKUP(AW71,HELPER!$F$8:$F$48,HELPER!$G$8:$G$48,,1),""))
B72: 3 | C72: =IF('INPUT DATA'!N13="","",'INPUT DATA'!N13) | K72: =IF(COUNT($F72:$J72)=0,"",SUM($F72:$J72)) | L72: =IF(ISERROR(IF($K72="","",ROUND(($K72/$K$16)*$L$16,2))),"",IF($K72="","",ROUND(($K72/$K$16)*$L$16,2))) | M72: =IF($L72="","",ROUND($L72*$M$16,2)) | S72: =IF(COUNT($N72:$R72)=0,"",SUM($N72:$R72)) | T72: =IF(ISERROR(IF($S72="","",ROUND(($S72/$S$16)*$T$16,2))),"",IF($S72="","",ROUND(($S72/$S$16)*$T$16,2))) | U72: =IF($T72="","",ROUND($T72*$U$16,2)) | Y72: =IF(COUNT($V72:$X72)=0,"",SUM($V72:$X72)) | Z72: =IF(ISERROR(IF($Y72="","",ROUND(($Y72/$Y$16)*$Z$16,2))),"",IF($Y72="","",ROUND(($Y72/$Y$16)*$Z$16,2))) | AA72: =IF($Z72="","",ROUND($Z72*$AA$16,2)) | AE72: =IF(COUNT($AB72:$AD72)=0,"",SUM($AB72:$AD72)) | AF72: =IF(ISERROR(IF($AE72="","",ROUND(($AE72/$AE$16)*$AF$16,2))),"",IF($AE72="","",ROUND(($AE72/$AE$16)*$AF$16,2))) | AG72: =IF($AF72="","",ROUND($AF72*$AG$16,2)) | AK72: =IF(COUNT($AH72:$AJ72)=0,"",SUM($AH72:$AJ72)) | AL72: =IF(ISERROR(IF($AK72="","",ROUND(($AK72/$AK$16)*$AL$16,2))),"",IF($AK72="","",ROUND(($AK72/$AK$16)*$AL$16,2))) | AM72: =IF($AL72="","",ROUND($AL72*$AM$16,2)) | AQ72: =IFERROR(IF(AN72="","",ROUND(AN72/$AN$16*$AQ$16,2)),"") | AR72: =IFERROR(IF(AO72="","",ROUND(AO72/$AO$16*$AR$16,2)),"") | AS72: =IFERROR(IF(AP72="","",ROUND(AP72/$AP$16*$AS$16,2)),"") | AT72: =IF(COUNT($AQ72:$AS72)=0,"",SUM($AQ72:$AS72)) | AU72: =IFERROR(IF(AT72="","",ROUND(AT72*$AU$16,2)),"") | AV72: =IF(C72="","",IFERROR(ROUND(M72+U72+AA72+AG72+AM72+AU72,2),"")) | AW72: =IF(C72="","",IFERROR(_xlfn.XLOOKUP(AV72,HELPER!$C$8:$C$48,HELPER!$D$8:$D$48,,1),"")) | AX72: =IF(C72="","",IFERROR(_xlfn.XLOOKUP(AW72,HELPER!$F$8:$F$48,HELPER!$G$8:$G$48,,1),""))
B73: 4 | C73: =IF('INPUT DATA'!N14="","",'INPUT DATA'!N14) | K73: =IF(COUNT($F73:$J73)=0,"",SUM($F73:$J73)) | L73: =IF(ISERROR(IF($K73="","",ROUND(($K73/$K$16)*$L$16,2))),"",IF($K73="","",ROUND(($K73/$K$16)*$L$16,2))) | M73: =IF($L73="","",ROUND($L73*$M$16,2)) | S73: =IF(COUNT($N73:$R73)=0,"",SUM($N73:$R73)) | T73: =IF(ISERROR(IF($S73="","",ROUND(($S73/$S$16)*$T$16,2))),"",IF($S73="","",ROUND(($S73/$S$16)*$T$16,2))) | U73: =IF($T73="","",ROUND($T73*$U$16,2)) | Y73: =IF(COUNT($V73:$X73)=0,"",SUM($V73:$X73)) | Z73: =IF(ISERROR(IF($Y73="","",ROUND(($Y73/$Y$16)*$Z$16,2))),"",IF($Y73="","",ROUND(($Y73/$Y$16)*$Z$16,2))) | AA73: =IF($Z73="","",ROUND($Z73*$AA$16,2)) | AE73: =IF(COUNT($AB73:$AD73)=0,"",SUM($AB73:$AD73)) | AF73: =IF(ISERROR(IF($AE73="","",ROUND(($AE73/$AE$16)*$AF$16,2))),"",IF($AE73="","",ROUND(($AE73/$AE$16)*$AF$16,2))) | AG73: =IF($AF73="","",ROUND($AF73*$AG$16,2)) | AK73: =IF(COUNT($AH73:$AJ73)=0,"",SUM($AH73:$AJ73)) | AL73: =IF(ISERROR(IF($AK73="","",ROUND(($AK73/$AK$16)*$AL$16,2))),"",IF($AK73="","",ROUND(($AK73/$AK$16)*$AL$16,2))) | AM73: =IF($AL73="","",ROUND($AL73*$AM$16,2)) | AQ73: =IFERROR(IF(AN73="","",ROUND(AN73/$AN$16*$AQ$16,2)),"") | AR73: =IFERROR(IF(AO73="","",ROUND(AO73/$AO$16*$AR$16,2)),"") | AS73: =IFERROR(IF(AP73="","",ROUND(AP73/$AP$16*$AS$16,2)),"") | AT73: =IF(COUNT($AQ73:$AS73)=0,"",SUM($AQ73:$AS73)) | AU73: =IFERROR(IF(AT73="","",ROUND(AT73*$AU$16,2)),"") | AV73: =IF(C73="","",IFERROR(ROUND(M73+U73+AA73+AG73+AM73+AU73,2),"")) | AW73: =IF(C73="","",IFERROR(_xlfn.XLOOKUP(AV73,HELPER!$C$8:$C$48,HELPER!$D$8:$D$48,,1),"")) | AX73: =IF(C73="","",IFERROR(_xlfn.XLOOKUP(AW73,HELPER!$F$8:$F$48,HELPER!$G$8:$G$48,,1),""))
B74: 5 | C74: =IF('INPUT DATA'!N15="","",'INPUT DATA'!N15) | K74: =IF(COUNT($F74:$J74)=0,"",SUM($F74:$J74)) | L74: =IF(ISERROR(IF($K74="","",ROUND(($K74/$K$16)*$L$16,2))),"",IF($K74="","",ROUND(($K74/$K$16)*$L$16,2))) | M74: =IF($L74="","",ROUND($L74*$M$16,2)) | S74: =IF(COUNT($N74:$R74)=0,"",SUM($N74:$R74)) | T74: =IF(ISERROR(IF($S74="","",ROUND(($S74/$S$16)*$T$16,2))),"",IF($S74="","",ROUND(($S74/$S$16)*$T$16,2))) | U74: =IF($T74="","",ROUND($T74*$U$16,2)) | Y74: =IF(COUNT($V74:$X74)=0,"",SUM($V74:$X74)) | Z74: =IF(ISERROR(IF($Y74="","",ROUND(($Y74/$Y$16)*$Z$16,2))),"",IF($Y74="","",ROUND(($Y74/$Y$16)*$Z$16,2))) | AA74: =IF($Z74="","",ROUND($Z74*$AA$16,2)) | AE74: =IF(COUNT($AB74:$AD74)=0,"",SUM($AB74:$AD74)) | AF74: =IF(ISERROR(IF($AE74="","",ROUND(($AE74/$AE$16)*$AF$16,2))),"",IF($AE74="","",ROUND(($AE74/$AE$16)*$AF$16,2))) | AG74: =IF($AF74="","",ROUND($AF74*$AG$16,2)) | AK74: =IF(COUNT($AH74:$AJ74)=0,"",SUM($AH74:$AJ74)) | AL74: =IF(ISERROR(IF($AK74="","",ROUND(($AK74/$AK$16)*$AL$16,2))),"",IF($AK74="","",ROUND(($AK74/$AK$16)*$AL$16,2))) | AM74: =IF($AL74="","",ROUND($AL74*$AM$16,2)) | AQ74: =IFERROR(IF(AN74="","",ROUND(AN74/$AN$16*$AQ$16,2)),"") | AR74: =IFERROR(IF(AO74="","",ROUND(AO74/$AO$16*$AR$16,2)),"") | AS74: =IFERROR(IF(AP74="","",ROUND(AP74/$AP$16*$AS$16,2)),"") | AT74: =IF(COUNT($AQ74:$AS74)=0,"",SUM($AQ74:$AS74)) | AU74: =IFERROR(IF(AT74="","",ROUND(AT74*$AU$16,2)),"") | AV74: =IF(C74="","",IFERROR(ROUND(M74+U74+AA74+AG74+AM74+AU74,2),"")) | AW74: =IF(C74="","",IFERROR(_xlfn.XLOOKUP(AV74,HELPER!$C$8:$C$48,HELPER!$D$8:$D$48,,1),"")) | AX74: =IF(C74="","",IFERROR(_xlfn.XLOOKUP(AW74,HELPER!$F$8:$F$48,HELPER!$G$8:$G$48,,1),""))
B75: 6 | C75: =IF('INPUT DATA'!N16="","",'INPUT DATA'!N16) | K75: =IF(COUNT($F75:$J75)=0,"",SUM($F75:$J75)) | L75: =IF(ISERROR(IF($K75="","",ROUND(($K75/$K$16)*$L$16,2))),"",IF($K75="","",ROUND(($K75/$K$16)*$L$16,2))) | M75: =IF($L75="","",ROUND($L75*$M$16,2)) | S75: =IF(COUNT($N75:$R75)=0,"",SUM($N75:$R75)) | T75: =IF(ISERROR(IF($S75="","",ROUND(($S75/$S$16)*$T$16,2))),"",IF($S75="","",ROUND(($S75/$S$16)*$T$16,2))) | U75: =IF($T75="","",ROUND($T75*$U$16,2)) | Y75: =IF(COUNT($V75:$X75)=0,"",SUM($V75:$X75)) | Z75: =IF(ISERROR(IF($Y75="","",ROUND(($Y75/$Y$16)*$Z$16,2))),"",IF($Y75="","",ROUND(($Y75/$Y$16)*$Z$16,2))) | AA75: =IF($Z75="","",ROUND($Z75*$AA$16,2)) | AE75: =IF(COUNT($AB75:$AD75)=0,"",SUM($AB75:$AD75)) | AF75: =IF(ISERROR(IF($AE75="","",ROUND(($AE75/$AE$16)*$AF$16,2))),"",IF($AE75="","",ROUND(($AE75/$AE$16)*$AF$16,2))) | AG75: =IF($AF75="","",ROUND($AF75*$AG$16,2)) | AK75: =IF(COUNT($AH75:$AJ75)=0,"",SUM($AH75:$AJ75)) | AL75: =IF(ISERROR(IF($AK75="","",ROUND(($AK75/$AK$16)*$AL$16,2))),"",IF($AK75="","",ROUND(($AK75/$AK$16)*$AL$16,2))) | AM75: =IF($AL75="","",ROUND($AL75*$AM$16,2)) | AQ75: =IFERROR(IF(AN75="","",ROUND(AN75/$AN$16*$AQ$16,2)),"") | AR75: =IFERROR(IF(AO75="","",ROUND(AO75/$AO$16*$AR$16,2)),"") | AS75: =IFERROR(IF(AP75="","",ROUND(AP75/$AP$16*$AS$16,2)),"") | AT75: =IF(COUNT($AQ75:$AS75)=0,"",SUM($AQ75:$AS75)) | AU75: =IFERROR(IF(AT75="","",ROUND(AT75*$AU$16,2)),"") | AV75: =IF(C75="","",IFERROR(ROUND(M75+U75+AA75+AG75+AM75+AU75,2),"")) | AW75: =IF(C75="","",IFERROR(_xlfn.XLOOKUP(AV75,HELPER!$C$8:$C$48,HELPER!$D$8:$D$48,,1),"")) | AX75: =IF(C75="","",IFERROR(_xlfn.XLOOKUP(AW75,HELPER!$F$8:$F$48,HELPER!$G$8:$G$48,,1),""))
B76: 7 | C76: =IF('INPUT DATA'!N17="","",'INPUT DATA'!N17) | K76: =IF(COUNT($F76:$J76)=0,"",SUM($F76:$J76)) | L76: =IF(ISERROR(IF($K76="","",ROUND(($K76/$K$16)*$L$16,2))),"",IF($K76="","",ROUND(($K76/$K$16)*$L$16,2))) | M76: =IF($L76="","",ROUND($L76*$M$16,2)) | S76: =IF(COUNT($N76:$R76)=0,"",SUM($N76:$R76)) | T76: =IF(ISERROR(IF($S76="","",ROUND(($S76/$S$16)*$T$16,2))),"",IF($S76="","",ROUND(($S76/$S$16)*$T$16,2))) | U76: =IF($T76="","",ROUND($T76*$U$16,2)) | Y76: =IF(COUNT($V76:$X76)=0,"",SUM($V76:$X76)) | Z76: =IF(ISERROR(IF($Y76="","",ROUND(($Y76/$Y$16)*$Z$16,2))),"",IF($Y76="","",ROUND(($Y76/$Y$16)*$Z$16,2))) | AA76: =IF($Z76="","",ROUND($Z76*$AA$16,2)) | AE76: =IF(COUNT($AB76:$AD76)=0,"",SUM($AB76:$AD76)) | AF76: =IF(ISERROR(IF($AE76="","",ROUND(($AE76/$AE$16)*$AF$16,2))),"",IF($AE76="","",ROUND(($AE76/$AE$16)*$AF$16,2))) | AG76: =IF($AF76="","",ROUND($AF76*$AG$16,2)) | AK76: =IF(COUNT($AH76:$AJ76)=0,"",SUM($AH76:$AJ76)) | AL76: =IF(ISERROR(IF($AK76="","",ROUND(($AK76/$AK$16)*$AL$16,2))),"",IF($AK76="","",ROUND(($AK76/$AK$16)*$AL$16,2))) | AM76: =IF($AL76="","",ROUND($AL76*$AM$16,2)) | AQ76: =IFERROR(IF(AN76="","",ROUND(AN76/$AN$16*$AQ$16,2)),"") | AR76: =IFERROR(IF(AO76="","",ROUND(AO76/$AO$16*$AR$16,2)),"") | AS76: =IFERROR(IF(AP76="","",ROUND(AP76/$AP$16*$AS$16,2)),"") | AT76: =IF(COUNT($AQ76:$AS76)=0,"",SUM($AQ76:$AS76)) | AU76: =IFERROR(IF(AT76="","",ROUND(AT76*$AU$16,2)),"") | AV76: =IF(C76="","",IFERROR(ROUND(M76+U76+AA76+AG76+AM76+AU76,2),"")) | AW76: =IF(C76="","",IFERROR(_xlfn.XLOOKUP(AV76,HELPER!$C$8:$C$48,HELPER!$D$8:$D$48,,1),"")) | AX76: =IF(C76="","",IFERROR(_xlfn.XLOOKUP(AW76,HELPER!$F$8:$F$48,HELPER!$G$8:$G$48,,1),""))
B77: 8 | C77: =IF('INPUT DATA'!N18="","",'INPUT DATA'!N18) | K77: =IF(COUNT($F77:$J77)=0,"",SUM($F77:$J77)) | L77: =IF(ISERROR(IF($K77="","",ROUND(($K77/$K$16)*$L$16,2))),"",IF($K77="","",ROUND(($K77/$K$16)*$L$16,2))) | M77: =IF($L77="","",ROUND($L77*$M$16,2)) | S77: =IF(COUNT($N77:$R77)=0,"",SUM($N77:$R77)) | T77: =IF(ISERROR(IF($S77="","",ROUND(($S77/$S$16)*$T$16,2))),"",IF($S77="","",ROUND(($S77/$S$16)*$T$16,2))) | U77: =IF($T77="","",ROUND($T77*$U$16,2)) | Y77: =IF(COUNT($V77:$X77)=0,"",SUM($V77:$X77)) | Z77: =IF(ISERROR(IF($Y77="","",ROUND(($Y77/$Y$16)*$Z$16,2))),"",IF($Y77="","",ROUND(($Y77/$Y$16)*$Z$16,2))) | AA77: =IF($Z77="","",ROUND($Z77*$AA$16,2)) | AE77: =IF(COUNT($AB77:$AD77)=0,"",SUM($AB77:$AD77)) | AF77: =IF(ISERROR(IF($AE77="","",ROUND(($AE77/$AE$16)*$AF$16,2))),"",IF($AE77="","",ROUND(($AE77/$AE$16)*$AF$16,2))) | AG77: =IF($AF77="","",ROUND($AF77*$AG$16,2)) | AK77: =IF(COUNT($AH77:$AJ77)=0,"",SUM($AH77:$AJ77)) | AL77: =IF(ISERROR(IF($AK77="","",ROUND(($AK77/$AK$16)*$AL$16,2))),"",IF($AK77="","",ROUND(($AK77/$AK$16)*$AL$16,2))) | AM77: =IF($AL77="","",ROUND($AL77*$AM$16,2)) | AQ77: =IFERROR(IF(AN77="","",ROUND(AN77/$AN$16*$AQ$16,2)),"") | AR77: =IFERROR(IF(AO77="","",ROUND(AO77/$AO$16*$AR$16,2)),"") | AS77: =IFERROR(IF(AP77="","",ROUND(AP77/$AP$16*$AS$16,2)),"") | AT77: =IF(COUNT($AQ77:$AS77)=0,"",SUM($AQ77:$AS77)) | AU77: =IFERROR(IF(AT77="","",ROUND(AT77*$AU$16,2)),"") | AV77: =IF(C77="","",IFERROR(ROUND(M77+U77+AA77+AG77+AM77+AU77,2),"")) | AW77: =IF(C77="","",IFERROR(_xlfn.XLOOKUP(AV77,HELPER!$C$8:$C$48,HELPER!$D$8:$D$48,,1),"")) | AX77: =IF(C77="","",IFERROR(_xlfn.XLOOKUP(AW77,HELPER!$F$8:$F$48,HELPER!$G$8:$G$48,,1),""))
B78: 9 | C78: =IF('INPUT DATA'!N19="","",'INPUT DATA'!N19) | K78: =IF(COUNT($F78:$J78)=0,"",SUM($F78:$J78)) | L78: =IF(ISERROR(IF($K78="","",ROUND(($K78/$K$16)*$L$16,2))),"",IF($K78="","",ROUND(($K78/$K$16)*$L$16,2))) | M78: =IF($L78="","",ROUND($L78*$M$16,2)) | S78: =IF(COUNT($N78:$R78)=0,"",SUM($N78:$R78)) | T78: =IF(ISERROR(IF($S78="","",ROUND(($S78/$S$16)*$T$16,2))),"",IF($S78="","",ROUND(($S78/$S$16)*$T$16,2))) | U78: =IF($T78="","",ROUND($T78*$U$16,2)) | Y78: =IF(COUNT($V78:$X78)=0,"",SUM($V78:$X78)) | Z78: =IF(ISERROR(IF($Y78="","",ROUND(($Y78/$Y$16)*$Z$16,2))),"",IF($Y78="","",ROUND(($Y78/$Y$16)*$Z$16,2))) | AA78: =IF($Z78="","",ROUND($Z78*$AA$16,2)) | AE78: =IF(COUNT($AB78:$AD78)=0,"",SUM($AB78:$AD78)) | AF78: =IF(ISERROR(IF($AE78="","",ROUND(($AE78/$AE$16)*$AF$16,2))),"",IF($AE78="","",ROUND(($AE78/$AE$16)*$AF$16,2))) | AG78: =IF($AF78="","",ROUND($AF78*$AG$16,2)) | AK78: =IF(COUNT($AH78:$AJ78)=0,"",SUM($AH78:$AJ78)) | AL78: =IF(ISERROR(IF($AK78="","",ROUND(($AK78/$AK$16)*$AL$16,2))),"",IF($AK78="","",ROUND(($AK78/$AK$16)*$AL$16,2))) | AM78: =IF($AL78="","",ROUND($AL78*$AM$16,2)) | AQ78: =IFERROR(IF(AN78="","",ROUND(AN78/$AN$16*$AQ$16,2)),"") | AR78: =IFERROR(IF(AO78="","",ROUND(AO78/$AO$16*$AR$16,2)),"") | AS78: =IFERROR(IF(AP78="","",ROUND(AP78/$AP$16*$AS$16,2)),"") | AT78: =IF(COUNT($AQ78:$AS78)=0,"",SUM($AQ78:$AS78)) | AU78: =IFERROR(IF(AT78="","",ROUND(AT78*$AU$16,2)),"") | AV78: =IF(C78="","",IFERROR(ROUND(M78+U78+AA78+AG78+AM78+AU78,2),"")) | AW78: =IF(C78="","",IFERROR(_xlfn.XLOOKUP(AV78,HELPER!$C$8:$C$48,HELPER!$D$8:$D$48,,1),"")) | AX78: =IF(C78="","",IFERROR(_xlfn.XLOOKUP(AW78,HELPER!$F$8:$F$48,HELPER!$G$8:$G$48,,1),""))
B79: 10 | C79: =IF('INPUT DATA'!N20="","",'INPUT DATA'!N20) | K79: =IF(COUNT($F79:$J79)=0,"",SUM($F79:$J79)) | L79: =IF(ISERROR(IF($K79="","",ROUND(($K79/$K$16)*$L$16,2))),"",IF($K79="","",ROUND(($K79/$K$16)*$L$16,2))) | M79: =IF($L79="","",ROUND($L79*$M$16,2)) | S79: =IF(COUNT($N79:$R79)=0,"",SUM($N79:$R79)) | T79: =IF(ISERROR(IF($S79="","",ROUND(($S79/$S$16)*$T$16,2))),"",IF($S79="","",ROUND(($S79/$S$16)*$T$16,2))) | U79: =IF($T79="","",ROUND($T79*$U$16,2)) | Y79: =IF(COUNT($V79:$X79)=0,"",SUM($V79:$X79)) | Z79: =IF(ISERROR(IF($Y79="","",ROUND(($Y79/$Y$16)*$Z$16,2))),"",IF($Y79="","",ROUND(($Y79/$Y$16)*$Z$16,2))) | AA79: =IF($Z79="","",ROUND($Z79*$AA$16,2)) | AE79: =IF(COUNT($AB79:$AD79)=0,"",SUM($AB79:$AD79)) | AF79: =IF(ISERROR(IF($AE79="","",ROUND(($AE79/$AE$16)*$AF$16,2))),"",IF($AE79="","",ROUND(($AE79/$AE$16)*$AF$16,2))) | AG79: =IF($AF79="","",ROUND($AF79*$AG$16,2)) | AK79: =IF(COUNT($AH79:$AJ79)=0,"",SUM($AH79:$AJ79)) | AL79: =IF(ISERROR(IF($AK79="","",ROUND(($AK79/$AK$16)*$AL$16,2))),"",IF($AK79="","",ROUND(($AK79/$AK$16)*$AL$16,2))) | AM79: =IF($AL79="","",ROUND($AL79*$AM$16,2)) | AQ79: =IFERROR(IF(AN79="","",ROUND(AN79/$AN$16*$AQ$16,2)),"") | AR79: =IFERROR(IF(AO79="","",ROUND(AO79/$AO$16*$AR$16,2)),"") | AS79: =IFERROR(IF(AP79="","",ROUND(AP79/$AP$16*$AS$16,2)),"") | AT79: =IF(COUNT($AQ79:$AS79)=0,"",SUM($AQ79:$AS79)) | AU79: =IFERROR(IF(AT79="","",ROUND(AT79*$AU$16,2)),"") | AV79: =IF(C79="","",IFERROR(ROUND(M79+U79+AA79+AG79+AM79+AU79,2),"")) | AW79: =IF(C79="","",IFERROR(_xlfn.XLOOKUP(AV79,HELPER!$C$8:$C$48,HELPER!$D$8:$D$48,,1),"")) | AX79: =IF(C79="","",IFERROR(_xlfn.XLOOKUP(AW79,HELPER!$F$8:$F$48,HELPER!$G$8:$G$48,,1),""))
B80: 11 | C80: =IF('INPUT DATA'!N21="","",'INPUT DATA'!N21) | K80: =IF(COUNT($F80:$J80)=0,"",SUM($F80:$J80)) | L80: =IF(ISERROR(IF($K80="","",ROUND(($K80/$K$16)*$L$16,2))),"",IF($K80="","",ROUND(($K80/$K$16)*$L$16,2))) | M80: =IF($L80="","",ROUND($L80*$M$16,2)) | S80: =IF(COUNT($N80:$R80)=0,"",SUM($N80:$R80)) | T80: =IF(ISERROR(IF($S80="","",ROUND(($S80/$S$16)*$T$16,2))),"",IF($S80="","",ROUND(($S80/$S$16)*$T$16,2))) | U80: =IF($T80="","",ROUND($T80*$U$16,2)) | Y80: =IF(COUNT($V80:$X80)=0,"",SUM($V80:$X80)) | Z80: =IF(ISERROR(IF($Y80="","",ROUND(($Y80/$Y$16)*$Z$16,2))),"",IF($Y80="","",ROUND(($Y80/$Y$16)*$Z$16,2))) | AA80: =IF($Z80="","",ROUND($Z80*$AA$16,2)) | AE80: =IF(COUNT($AB80:$AD80)=0,"",SUM($AB80:$AD80)) | AF80: =IF(ISERROR(IF($AE80="","",ROUND(($AE80/$AE$16)*$AF$16,2))),"",IF($AE80="","",ROUND(($AE80/$AE$16)*$AF$16,2))) | AG80: =IF($AF80="","",ROUND($AF80*$AG$16,2)) | AK80: =IF(COUNT($AH80:$AJ80)=0,"",SUM($AH80:$AJ80)) | AL80: =IF(ISERROR(IF($AK80="","",ROUND(($AK80/$AK$16)*$AL$16,2))),"",IF($AK80="","",ROUND(($AK80/$AK$16)*$AL$16,2))) | AM80: =IF($AL80="","",ROUND($AL80*$AM$16,2)) | AQ80: =IFERROR(IF(AN80="","",ROUND(AN80/$AN$16*$AQ$16,2)),"") | AR80: =IFERROR(IF(AO80="","",ROUND(AO80/$AO$16*$AR$16,2)),"") | AS80: =IFERROR(IF(AP80="","",ROUND(AP80/$AP$16*$AS$16,2)),"") | AT80: =IF(COUNT($AQ80:$AS80)=0,"",SUM($AQ80:$AS80)) | AU80: =IFERROR(IF(AT80="","",ROUND(AT80*$AU$16,2)),"") | AV80: =IF(C80="","",IFERROR(ROUND(M80+U80+AA80+AG80+AM80+AU80,2),"")) | AW80: =IF(C80="","",IFERROR(_xlfn.XLOOKUP(AV80,HELPER!$C$8:$C$48,HELPER!$D$8:$D$48,,1),"")) | AX80: =IF(C80="","",IFERROR(_xlfn.XLOOKUP(AW80,HELPER!$F$8:$F$48,HELPER!$G$8:$G$48,,1),""))
B81: 12 | C81: =IF('INPUT DATA'!N22="","",'INPUT DATA'!N22) | K81: =IF(COUNT($F81:$J81)=0,"",SUM($F81:$J81)) | L81: =IF(ISERROR(IF($K81="","",ROUND(($K81/$K$16)*$L$16,2))),"",IF($K81="","",ROUND(($K81/$K$16)*$L$16,2))) | M81: =IF($L81="","",ROUND($L81*$M$16,2)) | S81: =IF(COUNT($N81:$R81)=0,"",SUM($N81:$R81)) | T81: =IF(ISERROR(IF($S81="","",ROUND(($S81/$S$16)*$T$16,2))),"",IF($S81="","",ROUND(($S81/$S$16)*$T$16,2))) | U81: =IF($T81="","",ROUND($T81*$U$16,2)) | Y81: =IF(COUNT($V81:$X81)=0,"",SUM($V81:$X81)) | Z81: =IF(ISERROR(IF($Y81="","",ROUND(($Y81/$Y$16)*$Z$16,2))),"",IF($Y81="","",ROUND(($Y81/$Y$16)*$Z$16,2))) | AA81: =IF($Z81="","",ROUND($Z81*$AA$16,2)) | AE81: =IF(COUNT($AB81:$AD81)=0,"",SUM($AB81:$AD81)) | AF81: =IF(ISERROR(IF($AE81="","",ROUND(($AE81/$AE$16)*$AF$16,2))),"",IF($AE81="","",ROUND(($AE81/$AE$16)*$AF$16,2))) | AG81: =IF($AF81="","",ROUND($AF81*$AG$16,2)) | AK81: =IF(COUNT($AH81:$AJ81)=0,"",SUM($AH81:$AJ81)) | AL81: =IF(ISERROR(IF($AK81="","",ROUND(($AK81/$AK$16)*$AL$16,2))),"",IF($AK81="","",ROUND(($AK81/$AK$16)*$AL$16,2))) | AM81: =IF($AL81="","",ROUND($AL81*$AM$16,2)) | AQ81: =IFERROR(IF(AN81="","",ROUND(AN81/$AN$16*$AQ$16,2)),"") | AR81: =IFERROR(IF(AO81="","",ROUND(AO81/$AO$16*$AR$16,2)),"") | AS81: =IFERROR(IF(AP81="","",ROUND(AP81/$AP$16*$AS$16,2)),"") | AT81: =IF(COUNT($AQ81:$AS81)=0,"",SUM($AQ81:$AS81)) | AU81: =IFERROR(IF(AT81="","",ROUND(AT81*$AU$16,2)),"") | AV81: =IF(C81="","",IFERROR(ROUND(M81+U81+AA81+AG81+AM81+AU81,2),"")) | AW81: =IF(C81="","",IFERROR(_xlfn.XLOOKUP(AV81,HELPER!$C$8:$C$48,HELPER!$D$8:$D$48,,1),"")) | AX81: =IF(C81="","",IFERROR(_xlfn.XLOOKUP(AW81,HELPER!$F$8:$F$48,HELPER!$G$8:$G$48,,1),""))
... B119: 50 | C119: =IF('INPUT DATA'!N60="","",'INPUT DATA'!N60) | K119: =IF(COUNT($F119:$J119)=0,"",SUM($F119:$J119)) | L119: =IF(ISERROR(IF($K119="","",ROUND(($K119/$K$16)*$L$16,2))),"",IF($K119="","",ROUND(($K119/$K$16)*$L$16,2))) | M119: =IF($L119="","",ROUND($L119*$M$16,2)) | S119: =IF(COUNT($N119:$R119)=0,"",SUM($N119:$R119)) | T119: =IF(ISERROR(IF($S119="","",ROUND(($S119/$S$16)*$T$16,2))),"",IF($S119="","",ROUND(($S119/$S$16)*$T$16,2))) | U119: =IF($T119="","",ROUND($T119*$U$16,2)) | Y119: =IF(COUNT($V119:$X119)=0,"",SUM($V119:$X119)) | Z119: =IF(ISERROR(IF($Y119="","",ROUND(($Y119/$Y$16)*$Z$16,2))),"",IF($Y119="","",ROUND(($Y119/$Y$16)*$Z$16,2))) | AA119: =IF($Z119="","",ROUND($Z119*$AA$16,2)) | AE119: =IF(COUNT($AB119:$AD119)=0,"",SUM($AB119:$AD119)) | AF119: =IF(ISERROR(IF($AE119="","",ROUND(($AE119/$AE$16)*$AF$16,2))),"",IF($AE119="","",ROUND(($AE119/$AE$16)*$AF$16,2))) | AG119: =IF($AF119="","",ROUND($AF119*$AG$16,2)) | AK119: =IF(COUNT($AH119:$AJ119)=0,"",SUM($AH119:$AJ119)) | AL119: =IF(ISERROR(IF($AK119="","",ROUND(($AK119/$AK$16)*$AL$16,2))),"",IF($AK119="","",ROUND(($AK119/$AK$16)*$AL$16,2))) | AM119: =IF($AL119="","",ROUND($AL119*$AM$16,2)) | AQ119: =IFERROR(IF(AN119="","",ROUND(AN119/$AN$16*$AQ$16,2)),"") | AR119: =IFERROR(IF(AO119="","",ROUND(AO119/$AO$16*$AR$16,2)),"") | AS119: =IFERROR(IF(AP119="","",ROUND(AP119/$AP$16*$AS$16,2)),"") | AT119: =IF(COUNT($AQ119:$AS119)=0,"",SUM($AQ119:$AS119)) | AU119: =IFERROR(IF(AT119="","",ROUND(AT119*$AU$16,2)),"") | AV119: =IF(C119="","",IFERROR(ROUND(M119+U119+AA119+AG119+AM119+AU119,2),"")) | AW119: =IF(C119="","",IFERROR(_xlfn.XLOOKUP(AV119,HELPER!$C$8:$C$48,HELPER!$D$8:$D$48,,1),"")) | AX119: =IF(C119="","",IFERROR(_xlfn.XLOOKUP(AW119,HELPER!$F$8:$F$48,HELPER!$G$8:$G$48,,1),""))

Sheet TERM 2
B2: CLASS RECORD
E5: REGION | F5: ='INPUT DATA'!E10 -> 0 | Y5: DIVISION | Z5: ='INPUT DATA'!E11 -> 0 | AP5: SCHOOL ID | AQ5: ='INPUT DATA'!E13 -> 0
E7: SCHOOL NAME | F7: ='INPUT DATA'!E14 -> 0 | AP7: SCHOOL YEAR | AQ7: ='INPUT DATA'!E15 -> 0
B10: SECOND TERM | F10: GRADE LEVEL | J10: ='INPUT DATA'!E25 -> 0 | V10: TEACHER | AA10: ='INPUT DATA'!E23 -> 0 | AN10: SUBJECT | AR10: ='INPUT DATA'!E24 -> 0
F11: SECTION | J11: ='INPUT DATA'!E26 -> 0
F12: WRITTEN / ORAL WORKS (WWs) - 20% | V12: PRODUCT / PERFORMANCE TASKS (PTs) - 50% | AN12: EXAMINATIONS (EXs) - 30% | AV12: Initial Grade | AW12: Term Grade | AX12: Descriptor
F14: COGNITIVE DOMAIN | N14: AFFECTIVE DOMAIN | V14: COGNITIVE DOMAIN | AB14: AFFECTIVE DOMAIN | AH14: BEHAVIORAL DOMAIN
F15: 1 | G15: 2 | H15: 3 | I15: 4 | J15: 5 | K15: Total | L15: PS | M15: WS | N15: 1 | O15: 2 | P15: 3 | Q15: 4 | R15: 5 | S15: Total | T15: PS | U15: WS | V15: 1 | W15: 2 | X15: 3 | Y15: Total | Z15: PS | AA15: WS | AB15: 1 | AC15: 2 | AD15: 3 | AE15: Total | AF15: PS | AG15: WS | AH15: 1 | AI15: 2 | AJ15: 3 | AK15: Total | AL15: PS | AM15: WS | AN15: ST1 | AO15: ST2 | AP15: TE | AQ15: WS ST1 | AR15: WS ST2 | AS15: WS TE | AT15: PS | AU15: WS
B16: HIGHEST POSSIBLE SCORE | K16: =IF(COUNT($F16:$J16)=0,"",SUM($F16:$J16)) | L16: 100 | M16: 0.1 | S16: =IF(COUNT($N16:$R16)=0,"",SUM($N16:$R16)) | T16: 100 | U16: 0.1 | Y16: =IF(COUNT($V16:$X16)=0,"",SUM($V16:$X16)) | Z16: 100 | AA16: 0.1 | AE16: =IF(COUNT($AB16:$AD16)=0,"",SUM($AB16:$AD16)) | AF16: 100 | AG16: 0.1 | AK16: =IF(COUNT($AH16:$AJ16)=0,"",SUM($AH16:$AJ16)) | AL16: 100 | AM16: 0.3 | AQ16: 30 | AR16: 30 | AS16: 40 | AT16: 100 | AU16: 0.3
B17: LEARNERS' NAMES
B18: MALE
B19: 1 | C19: =IF('INPUT DATA'!K11="","",'INPUT DATA'!K11) | K19: =IF(COUNT($F19:$J19)=0,"",SUM($F19:$J19)) | L19: =IF(ISERROR(IF($K19="","",ROUND(($K19/$K$16)*$L$16,2))),"",IF($K19="","",ROUND(($K19/$K$16)*$L$16,2))) | M19: =IF($L19="","",ROUND($L19*$M$16,2)) | S19: =IF(COUNT($N19:$R19)=0,"",SUM($N19:$R19)) | T19: =IF(ISERROR(IF($S19="","",ROUND(($S19/$S$16)*$T$16,2))),"",IF($S19="","",ROUND(($S19/$S$16)*$T$16,2))) | U19: =IF($T19="","",ROUND($T19*$U$16,2)) | Y19: =IF(COUNT($V19:$X19)=0,"",SUM($V19:$X19)) | Z19: =IF(ISERROR(IF($Y19="","",ROUND(($Y19/$Y$16)*$Z$16,2))),"",IF($Y19="","",ROUND(($Y19/$Y$16)*$Z$16,2))) | AA19: =IF($Z19="","",ROUND($Z19*$AA$16,2)) | AE19: =IF(COUNT($AB19:$AD19)=0,"",SUM($AB19:$AD19)) | AF19: =IF(ISERROR(IF($AE19="","",ROUND(($AE19/$AE$16)*$AF$16,2))),"",IF($AE19="","",ROUND(($AE19/$AE$16)*$AF$16,2))) | AG19: =IF($AF19="","",ROUND($AF19*$AG$16,2)) | AK19: =IF(COUNT($AH19:$AJ19)=0,"",SUM($AH19:$AJ19)) | AL19: =IF(ISERROR(IF($AK19="","",ROUND(($AK19/$AK$16)*$AL$16,2))),"",IF($AK19="","",ROUND(($AK19/$AK$16)*$AL$16,2))) | AM19: =IF($AL19="","",ROUND($AL19*$AM$16,2)) | AQ19: =IFERROR(IF(AN19="","",ROUND(AN19/$AN$16*$AQ$16,2)),"") | AR19: =IFERROR(IF(AO19="","",ROUND(AO19/$AO$16*$AR$16,2)),"") | AS19: =IFERROR(IF(AP19="","",ROUND(AP19/$AP$16*$AS$16,2)),"") | AT19: =IF(COUNT($AQ19:$AS19)=0,"",SUM($AQ19:$AS19)) | AU19: =IFERROR(IF(AT19="","",ROUND(AT19*$AU$16,2)),"") | AV19: =IF(C19="","",IFERROR(ROUND(M19+U19+AA19+AG19+AM19+AU19,2),"")) | AW19: =IF(C19="","",IFERROR(_xlfn.XLOOKUP(AV19,HELPER!$C$8:$C$48,HELPER!$D$8:$D$48,,1),"")) | AX19: =IF(C19="","",IFERROR(_xlfn.XLOOKUP(AW19,HELPER!$F$8:$F$48,HELPER!$G$8:$G$48,,1),""))
B20: 2 | C20: =IF('INPUT DATA'!K12="","",'INPUT DATA'!K12) | K20: =IF(COUNT($F20:$J20)=0,"",SUM($F20:$J20)) | L20: =IF(ISERROR(IF($K20="","",ROUND(($K20/$K$16)*$L$16,2))),"",IF($K20="","",ROUND(($K20/$K$16)*$L$16,2))) | M20: =IF($L20="","",ROUND($L20*$M$16,2)) | S20: =IF(COUNT($N20:$R20)=0,"",SUM($N20:$R20)) | T20: =IF(ISERROR(IF($S20="","",ROUND(($S20/$S$16)*$T$16,2))),"",IF($S20="","",ROUND(($S20/$S$16)*$T$16,2))) | U20: =IF($T20="","",ROUND($T20*$U$16,2)) | Y20: =IF(COUNT($V20:$X20)=0,"",SUM($V20:$X20)) | Z20: =IF(ISERROR(IF($Y20="","",ROUND(($Y20/$Y$16)*$Z$16,2))),"",IF($Y20="","",ROUND(($Y20/$Y$16)*$Z$16,2))) | AA20: =IF($Z20="","",ROUND($Z20*$AA$16,2)) | AE20: =IF(COUNT($AB20:$AD20)=0,"",SUM($AB20:$AD20)) | AF20: =IF(ISERROR(IF($AE20="","",ROUND(($AE20/$AE$16)*$AF$16,2))),"",IF($AE20="","",ROUND(($AE20/$AE$16)*$AF$16,2))) | AG20: =IF($AF20="","",ROUND($AF20*$AG$16,2)) | AK20: =IF(COUNT($AH20:$AJ20)=0,"",SUM($AH20:$AJ20)) | AL20: =IF(ISERROR(IF($AK20="","",ROUND(($AK20/$AK$16)*$AL$16,2))),"",IF($AK20="","",ROUND(($AK20/$AK$16)*$AL$16,2))) | AM20: =IF($AL20="","",ROUND($AL20*$AM$16,2)) | AQ20: =IFERROR(IF(AN20="","",ROUND(AN20/$AN$16*$AQ$16,2)),"") | AR20: =IFERROR(IF(AO20="","",ROUND(AO20/$AO$16*$AR$16,2)),"") | AS20: =IFERROR(IF(AP20="","",ROUND(AP20/$AP$16*$AS$16,2)),"") | AT20: =IF(COUNT($AQ20:$AS20)=0,"",SUM($AQ20:$AS20)) | AU20: =IFERROR(IF(AT20="","",ROUND(AT20*$AU$16,2)),"") | AV20: =IF(C20="","",IFERROR(ROUND(M20+U20+AA20+AG20+AM20+AU20,2),"")) | AW20: =IF(C20="","",IFERROR(_xlfn.XLOOKUP(AV20,HELPER!$C$8:$C$48,HELPER!$D$8:$D$48,,1),"")) | AX20: =IF(C20="","",IFERROR(_xlfn.XLOOKUP(AW20,HELPER!$F$8:$F$48,HELPER!$G$8:$G$48,,1),""))
B21: 3 | C21: =IF('INPUT DATA'!K13="","",'INPUT DATA'!K13) | K21: =IF(COUNT($F21:$J21)=0,"",SUM($F21:$J21)) | L21: =IF(ISERROR(IF($K21="","",ROUND(($K21/$K$16)*$L$16,2))),"",IF($K21="","",ROUND(($K21/$K$16)*$L$16,2))) | M21: =IF($L21="","",ROUND($L21*$M$16,2)) | S21: =IF(COUNT($N21:$R21)=0,"",SUM($N21:$R21)) | T21: =IF(ISERROR(IF($S21="","",ROUND(($S21/$S$16)*$T$16,2))),"",IF($S21="","",ROUND(($S21/$S$16)*$T$16,2))) | U21: =IF($T21="","",ROUND($T21*$U$16,2)) | Y21: =IF(COUNT($V21:$X21)=0,"",SUM($V21:$X21)) | Z21: =IF(ISERROR(IF($Y21="","",ROUND(($Y21/$Y$16)*$Z$16,2))),"",IF($Y21="","",ROUND(($Y21/$Y$16)*$Z$16,2))) | AA21: =IF($Z21="","",ROUND($Z21*$AA$16,2)) | AE21: =IF(COUNT($AB21:$AD21)=0,"",SUM($AB21:$AD21)) | AF21: =IF(ISERROR(IF($AE21="","",ROUND(($AE21/$AE$16)*$AF$16,2))),"",IF($AE21="","",ROUND(($AE21/$AE$16)*$AF$16,2))) | AG21: =IF($AF21="","",ROUND($AF21*$AG$16,2)) | AK21: =IF(COUNT($AH21:$AJ21)=0,"",SUM($AH21:$AJ21)) | AL21: =IF(ISERROR(IF($AK21="","",ROUND(($AK21/$AK$16)*$AL$16,2))),"",IF($AK21="","",ROUND(($AK21/$AK$16)*$AL$16,2))) | AM21: =IF($AL21="","",ROUND($AL21*$AM$16,2)) | AQ21: =IFERROR(IF(AN21="","",ROUND(AN21/$AN$16*$AQ$16,2)),"") | AR21: =IFERROR(IF(AO21="","",ROUND(AO21/$AO$16*$AR$16,2)),"") | AS21: =IFERROR(IF(AP21="","",ROUND(AP21/$AP$16*$AS$16,2)),"") | AT21: =IF(COUNT($AQ21:$AS21)=0,"",SUM($AQ21:$AS21)) | AU21: =IFERROR(IF(AT21="","",ROUND(AT21*$AU$16,2)),"") | AV21: =IF(C21="","",IFERROR(ROUND(M21+U21+AA21+AG21+AM21+AU21,2),"")) | AW21: =IF(C21="","",IFERROR(_xlfn.XLOOKUP(AV21,HELPER!$C$8:$C$48,HELPER!$D$8:$D$48,,1),"")) | AX21: =IF(C21="","",IFERROR(_xlfn.XLOOKUP(AW21,HELPER!$F$8:$F$48,HELPER!$G$8:$G$48,,1),""))
B22: 4 | C22: =IF('INPUT DATA'!K14="","",'INPUT DATA'!K14) | K22: =IF(COUNT($F22:$J22)=0,"",SUM($F22:$J22)) | L22: =IF(ISERROR(IF($K22="","",ROUND(($K22/$K$16)*$L$16,2))),"",IF($K22="","",ROUND(($K22/$K$16)*$L$16,2))) | M22: =IF($L22="","",ROUND($L22*$M$16,2)) | S22: =IF(COUNT($N22:$R22)=0,"",SUM($N22:$R22)) | T22: =IF(ISERROR(IF($S22="","",ROUND(($S22/$S$16)*$T$16,2))),"",IF($S22="","",ROUND(($S22/$S$16)*$T$16,2))) | U22: =IF($T22="","",ROUND($T22*$U$16,2)) | Y22: =IF(COUNT($V22:$X22)=0,"",SUM($V22:$X22)) | Z22: =IF(ISERROR(IF($Y22="","",ROUND(($Y22/$Y$16)*$Z$16,2))),"",IF($Y22="","",ROUND(($Y22/$Y$16)*$Z$16,2))) | AA22: =IF($Z22="","",ROUND($Z22*$AA$16,2)) | AE22: =IF(COUNT($AB22:$AD22)=0,"",SUM($AB22:$AD22)) | AF22: =IF(ISERROR(IF($AE22="","",ROUND(($AE22/$AE$16)*$AF$16,2))),"",IF($AE22="","",ROUND(($AE22/$AE$16)*$AF$16,2))) | AG22: =IF($AF22="","",ROUND($AF22*$AG$16,2)) | AK22: =IF(COUNT($AH22:$AJ22)=0,"",SUM($AH22:$AJ22)) | AL22: =IF(ISERROR(IF($AK22="","",ROUND(($AK22/$AK$16)*$AL$16,2))),"",IF($AK22="","",ROUND(($AK22/$AK$16)*$AL$16,2))) | AM22: =IF($AL22="","",ROUND($AL22*$AM$16,2)) | AQ22: =IFERROR(IF(AN22="","",ROUND(AN22/$AN$16*$AQ$16,2)),"") | AR22: =IFERROR(IF(AO22="","",ROUND(AO22/$AO$16*$AR$16,2)),"") | AS22: =IFERROR(IF(AP22="","",ROUND(AP22/$AP$16*$AS$16,2)),"") | AT22: =IF(COUNT($AQ22:$AS22)=0,"",SUM($AQ22:$AS22)) | AU22: =IFERROR(IF(AT22="","",ROUND(AT22*$AU$16,2)),"") | AV22: =IF(C22="","",IFERROR(ROUND(M22+U22+AA22+AG22+AM22+AU22,2),"")) | AW22: =IF(C22="","",IFERROR(_xlfn.XLOOKUP(AV22,HELPER!$C$8:$C$48,HELPER!$D$8:$D$48,,1),"")) | AX22: =IF(C22="","",IFERROR(_xlfn.XLOOKUP(AW22,HELPER!$F$8:$F$48,HELPER!$G$8:$G$48,,1),""))
B23: 5 | C23: =IF('INPUT DATA'!K15="","",'INPUT DATA'!K15) | K23: =IF(COUNT($F23:$J23)=0,"",SUM($F23:$J23)) | L23: =IF(ISERROR(IF($K23="","",ROUND(($K23/$K$16)*$L$16,2))),"",IF($K23="","",ROUND(($K23/$K$16)*$L$16,2))) | M23: =IF($L23="","",ROUND($L23*$M$16,2)) | S23: =IF(COUNT($N23:$R23)=0,"",SUM($N23:$R23)) | T23: =IF(ISERROR(IF($S23="","",ROUND(($S23/$S$16)*$T$16,2))),"",IF($S23="","",ROUND(($S23/$S$16)*$T$16,2))) | U23: =IF($T23="","",ROUND($T23*$U$16,2)) | Y23: =IF(COUNT($V23:$X23)=0,"",SUM($V23:$X23)) | Z23: =IF(ISERROR(IF($Y23="","",ROUND(($Y23/$Y$16)*$Z$16,2))),"",IF($Y23="","",ROUND(($Y23/$Y$16)*$Z$16,2))) | AA23: =IF($Z23="","",ROUND($Z23*$AA$16,2)) | AE23: =IF(COUNT($AB23:$AD23)=0,"",SUM($AB23:$AD23)) | AF23: =IF(ISERROR(IF($AE23="","",ROUND(($AE23/$AE$16)*$AF$16,2))),"",IF($AE23="","",ROUND(($AE23/$AE$16)*$AF$16,2))) | AG23: =IF($AF23="","",ROUND($AF23*$AG$16,2)) | AK23: =IF(COUNT($AH23:$AJ23)=0,"",SUM($AH23:$AJ23)) | AL23: =IF(ISERROR(IF($AK23="","",ROUND(($AK23/$AK$16)*$AL$16,2))),"",IF($AK23="","",ROUND(($AK23/$AK$16)*$AL$16,2))) | AM23: =IF($AL23="","",ROUND($AL23*$AM$16,2)) | AQ23: =IFERROR(IF(AN23="","",ROUND(AN23/$AN$16*$AQ$16,2)),"") | AR23: =IFERROR(IF(AO23="","",ROUND(AO23/$AO$16*$AR$16,2)),"") | AS23: =IFERROR(IF(AP23="","",ROUND(AP23/$AP$16*$AS$16,2)),"") | AT23: =IF(COUNT($AQ23:$AS23)=0,"",SUM($AQ23:$AS23)) | AU23: =IFERROR(IF(AT23="","",ROUND(AT23*$AU$16,2)),"") | AV23: =IF(C23="","",IFERROR(ROUND(M23+U23+AA23+AG23+AM23+AU23,2),"")) | AW23: =IF(C23="","",IFERROR(_xlfn.XLOOKUP(AV23,HELPER!$C$8:$C$48,HELPER!$D$8:$D$48,,1),"")) | AX23: =IF(C23="","",IFERROR(_xlfn.XLOOKUP(AW23,HELPER!$F$8:$F$48,HELPER!$G$8:$G$48,,1),""))
B24: 6 | C24: =IF('INPUT DATA'!K16="","",'INPUT DATA'!K16) | K24: =IF(COUNT($F24:$J24)=0,"",SUM($F24:$J24)) | L24: =IF(ISERROR(IF($K24="","",ROUND(($K24/$K$16)*$L$16,2))),"",IF($K24="","",ROUND(($K24/$K$16)*$L$16,2))) | M24: =IF($L24="","",ROUND($L24*$M$16,2)) | S24: =IF(COUNT($N24:$R24)=0,"",SUM($N24:$R24)) | T24: =IF(ISERROR(IF($S24="","",ROUND(($S24/$S$16)*$T$16,2))),"",IF($S24="","",ROUND(($S24/$S$16)*$T$16,2))) | U24: =IF($T24="","",ROUND($T24*$U$16,2)) | Y24: =IF(COUNT($V24:$X24)=0,"",SUM($V24:$X24)) | Z24: =IF(ISERROR(IF($Y24="","",ROUND(($Y24/$Y$16)*$Z$16,2))),"",IF($Y24="","",ROUND(($Y24/$Y$16)*$Z$16,2))) | AA24: =IF($Z24="","",ROUND($Z24*$AA$16,2)) | AE24: =IF(COUNT($AB24:$AD24)=0,"",SUM($AB24:$AD24)) | AF24: =IF(ISERROR(IF($AE24="","",ROUND(($AE24/$AE$16)*$AF$16,2))),"",IF($AE24="","",ROUND(($AE24/$AE$16)*$AF$16,2))) | AG24: =IF($AF24="","",ROUND($AF24*$AG$16,2)) | AK24: =IF(COUNT($AH24:$AJ24)=0,"",SUM($AH24:$AJ24)) | AL24: =IF(ISERROR(IF($AK24="","",ROUND(($AK24/$AK$16)*$AL$16,2))),"",IF($AK24="","",ROUND(($AK24/$AK$16)*$AL$16,2))) | AM24: =IF($AL24="","",ROUND($AL24*$AM$16,2)) | AQ24: =IFERROR(IF(AN24="","",ROUND(AN24/$AN$16*$AQ$16,2)),"") | AR24: =IFERROR(IF(AO24="","",ROUND(AO24/$AO$16*$AR$16,2)),"") | AS24: =IFERROR(IF(AP24="","",ROUND(AP24/$AP$16*$AS$16,2)),"") | AT24: =IF(COUNT($AQ24:$AS24)=0,"",SUM($AQ24:$AS24)) | AU24: =IFERROR(IF(AT24="","",ROUND(AT24*$AU$16,2)),"") | AV24: =IF(C24="","",IFERROR(ROUND(M24+U24+AA24+AG24+AM24+AU24,2),"")) | AW24: =IF(C24="","",IFERROR(_xlfn.XLOOKUP(AV24,HELPER!$C$8:$C$48,HELPER!$D$8:$D$48,,1),"")) | AX24: =IF(C24="","",IFERROR(_xlfn.XLOOKUP(AW24,HELPER!$F$8:$F$48,HELPER!$G$8:$G$48,,1),""))
B25: 7 | C25: =IF('INPUT DATA'!K17="","",'INPUT DATA'!K17) | K25: =IF(COUNT($F25:$J25)=0,"",SUM($F25:$J25)) | L25: =IF(ISERROR(IF($K25="","",ROUND(($K25/$K$16)*$L$16,2))),"",IF($K25="","",ROUND(($K25/$K$16)*$L$16,2))) | M25: =IF($L25="","",ROUND($L25*$M$16,2)) | S25: =IF(COUNT($N25:$R25)=0,"",SUM($N25:$R25)) | T25: =IF(ISERROR(IF($S25="","",ROUND(($S25/$S$16)*$T$16,2))),"",IF($S25="","",ROUND(($S25/$S$16)*$T$16,2))) | U25: =IF($T25="","",ROUND($T25*$U$16,2)) | Y25: =IF(COUNT($V25:$X25)=0,"",SUM($V25:$X25)) | Z25: =IF(ISERROR(IF($Y25="","",ROUND(($Y25/$Y$16)*$Z$16,2))),"",IF($Y25="","",ROUND(($Y25/$Y$16)*$Z$16,2))) | AA25: =IF($Z25="","",ROUND($Z25*$AA$16,2)) | AE25: =IF(COUNT($AB25:$AD25)=0,"",SUM($AB25:$AD25)) | AF25: =IF(ISERROR(IF($AE25="","",ROUND(($AE25/$AE$16)*$AF$16,2))),"",IF($AE25="","",ROUND(($AE25/$AE$16)*$AF$16,2))) | AG25: =IF($AF25="","",ROUND($AF25*$AG$16,2)) | AK25: =IF(COUNT($AH25:$AJ25)=0,"",SUM($AH25:$AJ25)) | AL25: =IF(ISERROR(IF($AK25="","",ROUND(($AK25/$AK$16)*$AL$16,2))),"",IF($AK25="","",ROUND(($AK25/$AK$16)*$AL$16,2))) | AM25: =IF($AL25="","",ROUND($AL25*$AM$16,2)) | AQ25: =IFERROR(IF(AN25="","",ROUND(AN25/$AN$16*$AQ$16,2)),"") | AR25: =IFERROR(IF(AO25="","",ROUND(AO25/$AO$16*$AR$16,2)),"") | AS25: =IFERROR(IF(AP25="","",ROUND(AP25/$AP$16*$AS$16,2)),"") | AT25: =IF(COUNT($AQ25:$AS25)=0,"",SUM($AQ25:$AS25)) | AU25: =IFERROR(IF(AT25="","",ROUND(AT25*$AU$16,2)),"") | AV25: =IF(C25="","",IFERROR(ROUND(M25+U25+AA25+AG25+AM25+AU25,2),"")) | AW25: =IF(C25="","",IFERROR(_xlfn.XLOOKUP(AV25,HELPER!$C$8:$C$48,HELPER!$D$8:$D$48,,1),"")) | AX25: =IF(C25="","",IFERROR(_xlfn.XLOOKUP(AW25,HELPER!$F$8:$F$48,HELPER!$G$8:$G$48,,1),""))
