Workbook

Sheet Home

Sheet INPUT DATA
A1: Input Data Sheet for Electronic-Class Record (ECR) for Class Adviser
B7: SCHOOL INFORMATION | J7: LEARNERS' DATA
C10: REGION | E10: : | K10: MALE | M10: LRN | N10: BIRTHDATE | P10: FEMALE | R10: LRN | S10: BIRTHDATE
C11: DIVISION | E11: : | K11: 1 | P11: 1
C12: CITY/MUNICIPALITY | E12: : | K12: 2 | P12: 2
C13: DISTRICT | E13: : | K13: 3 | P13: 3
K14: 4 | P14: 4
C15: SCHOOL ID | E15: : | K15: 5 | P15: 5
C16: SCHOOL NAME | E16: : | K16: 6 | P16: 6
K17: 7 | P17: 7
C18: SCHOOL YEAR | E18: : | K18: 8 | P18: 8
C19: SCHOOL HEAD | E19: : | K19: 9 | P19: 9
K20: 10 | P20: 10
K21: 11 | P21: 11
K22: 12 | P22: 12
B23: TEACHER, GRADE LEVEL, SECTION INFORMATION | K23: 13 | P23: 13
K24: 14 | P24: 14
K25: 15 | P25: 15
C26: ADVISER | E26: : | K26: 16 | P26: 16
C27: GRADE LEVEL | E27: : | G27: (Accepts Grade 11 only) | K27: 17 | P27: 17
C28: TRACK | E28: : | K28: 18 | P28: 18
C29: SECTION | E29: : | K29: 19 | P29: 19
K30: 20 | P30: 20
C31: IMPORTANT NOTE: This is the official and final version of the file. All tabs are password-protected to prevent accidental formula edits and maintain the accuracy and integrity of the data. If you identify any inconsistencies or issues, particularly with the formulas, please report them for appropriate review and necessary correction. | K31: 21 | P31: 21
K32: 22 | P32: 22
K33: 23 | P33: 23
K34: 24 | P34: 24
K35: 25 | P35: 25
K36: 26 | P36: 26
K37: 27 | P37: 27
K38: 28 | P38: 28
K39: 29 | P39: 29
K40: 30 | P40: 30
K41: 31 | P41: 31
K42: 32 | P42: 32
K43: 33 | P43: 33
... K60: 50 | P60: 50
T62: 2026_v1.0

Sheet TERM 1 SUMMARY
A1: CLASS SUMMARY
D5: REGION | E5: ='INPUT DATA'!F10 -> 0 | I5: DIVISION | J5: ='INPUT DATA'!F11 -> 0
D6: SCHOOL NAME | E6: ='INPUT DATA'!F16 -> 0 | I6: SCHOOL ID | J6: ='INPUT DATA'!F15 -> 0 | O6: SCHOOL YEAR | Q6: ='INPUT DATA'!F18 -> 0
B9: FIRST TERM | F9: GRADE LEVEL | G9: ='INPUT DATA'!F27 -> 0 | L9: SECTION | N9: ='INPUT DATA'!F29 -> 0
F10: TRACK | G10: ='INPUT DATA'!F28 -> 0 | L10: ADVISER | N10: ='INPUT DATA'!F26 -> 0
B11: LEARNERS' NAMES | F11: LRN | H11: Date of Birth | I11: Age | J11: Sex | K11: Learning Areas | R11: Final Grade | S11: Rank
K12: Core Subjects | Q12: Elective Subjects
K13: Effective Communication | L13: Mabisang Komunikasyon | M13: General Mathematics | N13: General Science | O13: Life and Career Skills | P13: PKLP | Q13: AE 1
B14: MALE
B15: 1 | C15: =IF('INPUT DATA'!L11="","",'INPUT DATA'!L11) | F15: =IF('INPUT DATA'!M11="","",'INPUT DATA'!M11) | H15: =IF('INPUT DATA'!N11="","",'INPUT DATA'!N11) | I15: =IF(H15="","",DATEDIF(H15,TODAY(),"Y")) | J15: M | R15: =IF(COUNT(K15:Q15)=0,"",ROUND(AVERAGE(K15:Q15),0)) | S15: =IF(R15="","",_xlfn.RANK.AVG(R15,$R$15:$R$115))
B16: 2 | C16: =IF('INPUT DATA'!L12="","",'INPUT DATA'!L12) | F16: =IF('INPUT DATA'!M12="","",'INPUT DATA'!M12) | H16: =IF('INPUT DATA'!N12="","",'INPUT DATA'!N12) | I16: =IF(H16="","",DATEDIF(H16,TODAY(),"Y")) | J16: M | R16: =IF(COUNT(K16:Q16)=0,"",ROUND(AVERAGE(K16:Q16),0)) | S16: =IF(R16="","",_xlfn.RANK.AVG(R16,$R$15:$R$115))
B17: 3 | C17: =IF('INPUT DATA'!L13="","",'INPUT DATA'!L13) | F17: =IF('INPUT DATA'!M13="","",'INPUT DATA'!M13) | H17: =IF('INPUT DATA'!N13="","",'INPUT DATA'!N13) | I17: =IF(H17="","",DATEDIF(H17,TODAY(),"Y")) | J17: M | R17: =IF(COUNT(K17:Q17)=0,"",ROUND(AVERAGE(K17:Q17),0)) | S17: =IF(R17="","",_xlfn.RANK.AVG(R17,$R$15:$R$115))
B18: 4 | C18: =IF('INPUT DATA'!L14="","",'INPUT DATA'!L14) | F18: =IF('INPUT DATA'!M14="","",'INPUT DATA'!M14) | H18: =IF('INPUT DATA'!N14="","",'INPUT DATA'!N14) | I18: =IF(H18="","",DATEDIF(H18,TODAY(),"Y")) | R18: =IF(COUNT(K18:Q18)=0,"",ROUND(AVERAGE(K18:Q18),0)) | S18: =IF(R18="","",_xlfn.RANK.AVG(R18,$R$15:$R$115))
B19: 5 | C19: =IF('INPUT DATA'!L15="","",'INPUT DATA'!L15) | F19: =IF('INPUT DATA'!M15="","",'INPUT DATA'!M15) | H19: =IF('INPUT DATA'!N15="","",'INPUT DATA'!N15) | I19: =IF(H19="","",DATEDIF(H19,TODAY(),"Y")) | R19: =IF(COUNT(K19:Q19)=0,"",ROUND(AVERAGE(K19:Q19),0)) | S19: =IF(R19="","",_xlfn.RANK.AVG(R19,$R$15:$R$115))
B20: 6 | C20: =IF('INPUT DATA'!L16="","",'INPUT DATA'!L16) | F20: =IF('INPUT DATA'!M16="","",'INPUT DATA'!M16) | H20: =IF('INPUT DATA'!N16="","",'INPUT DATA'!N16) | I20: =IF(H20="","",DATEDIF(H20,TODAY(),"Y")) | R20: =IF(COUNT(K20:Q20)=0,"",ROUND(AVERAGE(K20:Q20),0)) | S20: =IF(R20="","",_xlfn.RANK.AVG(R20,$R$15:$R$115))
B21: 7 | C21: =IF('INPUT DATA'!L17="","",'INPUT DATA'!L17) | F21: =IF('INPUT DATA'!M17="","",'INPUT DATA'!M17) | H21: =IF('INPUT DATA'!N17="","",'INPUT DATA'!N17) | I21: =IF(H21="","",DATEDIF(H21,TODAY(),"Y")) | R21: =IF(COUNT(K21:Q21)=0,"",ROUND(AVERAGE(K21:Q21),0)) | S21: =IF(R21="","",_xlfn.RANK.AVG(R21,$R$15:$R$115))
B22: 8 | C22: =IF('INPUT DATA'!L18="","",'INPUT DATA'!L18) | F22: =IF('INPUT DATA'!M18="","",'INPUT DATA'!M18) | H22: =IF('INPUT DATA'!N18="","",'INPUT DATA'!N18) | I22: =IF(H22="","",DATEDIF(H22,TODAY(),"Y")) | R22: =IF(COUNT(K22:Q22)=0,"",ROUND(AVERAGE(K22:Q22),0)) | S22: =IF(R22="","",_xlfn.RANK.AVG(R22,$R$15:$R$115))
B23: 9 | C23: =IF('INPUT DATA'!L19="","",'INPUT DATA'!L19) | F23: =IF('INPUT DATA'!M19="","",'INPUT DATA'!M19) | H23: =IF('INPUT DATA'!N19="","",'INPUT DATA'!N19) | I23: =IF(H23="","",DATEDIF(H23,TODAY(),"Y")) | R23: =IF(COUNT(K23:Q23)=0,"",ROUND(AVERAGE(K23:Q23),0)) | S23: =IF(R23="","",_xlfn.RANK.AVG(R23,$R$15:$R$115))
B24: 10 | C24: =IF('INPUT DATA'!L20="","",'INPUT DATA'!L20) | F24: =IF('INPUT DATA'!M20="","",'INPUT DATA'!M20) | H24: =IF('INPUT DATA'!N20="","",'INPUT DATA'!N20) | I24: =IF(H24="","",DATEDIF(H24,TODAY(),"Y")) | R24: =IF(COUNT(K24:Q24)=0,"",ROUND(AVERAGE(K24:Q24),0)) | S24: =IF(R24="","",_xlfn.RANK.AVG(R24,$R$15:$R$115))
B25: 11 | C25: =IF('INPUT DATA'!L21="","",'INPUT DATA'!L21) | F25: =IF('INPUT DATA'!M21="","",'INPUT DATA'!M21) | H25: =IF('INPUT DATA'!N21="","",'INPUT DATA'!N21) | I25: =IF(H25="","",DATEDIF(H25,TODAY(),"Y")) | R25: =IF(COUNT(K25:Q25)=0,"",ROUND(AVERAGE(K25:Q25),0)) | S25: =IF(R25="","",_xlfn.RANK.AVG(R25,$R$15:$R$115))
B26: 12 | C26: =IF('INPUT DATA'!L22="","",'INPUT DATA'!L22) | F26: =IF('INPUT DATA'!M22="","",'INPUT DATA'!M22) | H26: =IF('INPUT DATA'!N22="","",'INPUT DATA'!N22) | I26: =IF(H26="","",DATEDIF(H26,TODAY(),"Y")) | R26: =IF(COUNT(K26:Q26)=0,"",ROUND(AVERAGE(K26:Q26),0)) | S26: =IF(R26="","",_xlfn.RANK.AVG(R26,$R$15:$R$115))
B27: 13 | C27: =IF('INPUT DATA'!L23="","",'INPUT DATA'!L23) | F27: =IF('INPUT DATA'!M23="","",'INPUT DATA'!M23) | H27: =IF('INPUT DATA'!N23="","",'INPUT DATA'!N23) | I27: =IF(H27="","",DATEDIF(H27,TODAY(),"Y")) | R27: =IF(COUNT(K27:Q27)=0,"",ROUND(AVERAGE(K27:Q27),0)) | S27: =IF(R27="","",_xlfn.RANK.AVG(R27,$R$15:$R$115))
B28: 14 | C28: =IF('INPUT DATA'!L24="","",'INPUT DATA'!L24) | F28: =IF('INPUT DATA'!M24="","",'INPUT DATA'!M24) | H28: =IF('INPUT DATA'!N24="","",'INPUT DATA'!N24) | I28: =IF(H28="","",DATEDIF(H28,TODAY(),"Y")) | R28: =IF(COUNT(K28:Q28)=0,"",ROUND(AVERAGE(K28:Q28),0)) | S28: =IF(R28="","",_xlfn.RANK.AVG(R28,$R$15:$R$115))
B29: 15 | C29: =IF('INPUT DATA'!L25="","",'INPUT DATA'!L25) | F29: =IF('INPUT DATA'!M25="","",'INPUT DATA'!M25) | H29: =IF('INPUT DATA'!N25="","",'INPUT DATA'!N25) | I29: =IF(H29="","",DATEDIF(H29,TODAY(),"Y")) | R29: =IF(COUNT(K29:Q29)=0,"",ROUND(AVERAGE(K29:Q29),0)) | S29: =IF(R29="","",_xlfn.RANK.AVG(R29,$R$15:$R$115))
... B64: 50 | C64: =IF('INPUT DATA'!L60="","",'INPUT DATA'!L60) | F64: =IF('INPUT DATA'!M60="","",'INPUT DATA'!M60) | H64: =IF('INPUT DATA'!N60="","",'INPUT DATA'!N60) | I64: =IF(H64="","",DATEDIF(H64,TODAY(),"Y")) | R64: =IF(COUNT(K64:Q64)=0,"",ROUND(AVERAGE(K64:Q64),0)) | S64: =IF(R64="","",_xlfn.RANK.AVG(R64,$R$15:$R$115))
B65: FEMALE
B66: 1 | C66: =IF('INPUT DATA'!Q11="","",'INPUT DATA'!Q11) | F66: =IF('INPUT DATA'!T11="","",'INPUT DATA'!T11) | H66: =IF('INPUT DATA'!S11="","",'INPUT DATA'!S11) | I66: =IF(H66="","",DATEDIF(H66,TODAY(),"Y")) | J66: F | R66: =IF(COUNT(K66:Q66)=0,"",ROUND(AVERAGE(K66:Q66),0)) | S66: =IF(R66="","",_xlfn.RANK.AVG(R66,$R$15:$R$115))
B67: 2 | C67: =IF('INPUT DATA'!Q12="","",'INPUT DATA'!Q12) | F67: =IF('INPUT DATA'!T12="","",'INPUT DATA'!T12) | H67: =IF('INPUT DATA'!S12="","",'INPUT DATA'!S12) | I67: =IF(H67="","",DATEDIF(H67,TODAY(),"Y")) | J67: F | R67: =IF(COUNT(K67:Q67)=0,"",ROUND(AVERAGE(K67:Q67),0)) | S67: =IF(R67="","",_xlfn.RANK.AVG(R67,$R$15:$R$115))
B68: 3 | C68: =IF('INPUT DATA'!Q13="","",'INPUT DATA'!Q13) | F68: =IF('INPUT DATA'!T13="","",'INPUT DATA'!T13) | H68: =IF('INPUT DATA'!S13="","",'INPUT DATA'!S13) | I68: =IF(H68="","",DATEDIF(H68,TODAY(),"Y")) | J68: F | R68: =IF(COUNT(K68:Q68)=0,"",ROUND(AVERAGE(K68:Q68),0)) | S68: =IF(R68="","",_xlfn.RANK.AVG(R68,$R$15:$R$115))
B69: 4 | C69: =IF('INPUT DATA'!Q14="","",'INPUT DATA'!Q14) | F69: =IF('INPUT DATA'!T14="","",'INPUT DATA'!T14) | H69: =IF('INPUT DATA'!S14="","",'INPUT DATA'!S14) | I69: =IF(H69="","",DATEDIF(H69,TODAY(),"Y")) | R69: =IF(COUNT(K69:Q69)=0,"",ROUND(AVERAGE(K69:Q69),0)) | S69: =IF(R69="","",_xlfn.RANK.AVG(R69,$R$15:$R$115))
B70: 5 | C70: =IF('INPUT DATA'!Q15="","",'INPUT DATA'!Q15) | F70: =IF('INPUT DATA'!T15="","",'INPUT DATA'!T15) | H70: =IF('INPUT DATA'!S15="","",'INPUT DATA'!S15) | I70: =IF(H70="","",DATEDIF(H70,TODAY(),"Y")) | R70: =IF(COUNT(K70:Q70)=0,"",ROUND(AVERAGE(K70:Q70),0)) | S70: =IF(R70="","",_xlfn.RANK.AVG(R70,$R$15:$R$115))
B71: 6 | C71: =IF('INPUT DATA'!Q16="","",'INPUT DATA'!Q16) | F71: =IF('INPUT DATA'!T16="","",'INPUT DATA'!T16) | H71: =IF('INPUT DATA'!S16="","",'INPUT DATA'!S16) | I71: =IF(H71="","",DATEDIF(H71,TODAY(),"Y")) | R71: =IF(COUNT(K71:Q71)=0,"",ROUND(AVERAGE(K71:Q71),0)) | S71: =IF(R71="","",_xlfn.RANK.AVG(R71,$R$15:$R$115))
B72: 7 | C72: =IF('INPUT DATA'!Q17="","",'INPUT DATA'!Q17) | F72: =IF('INPUT DATA'!T17="","",'INPUT DATA'!T17) | H72: =IF('INPUT DATA'!S17="","",'INPUT DATA'!S17) | I72: =IF(H72="","",DATEDIF(H72,TODAY(),"Y")) | R72: =IF(COUNT(K72:Q72)=0,"",ROUND(AVERAGE(K72:Q72),0)) | S72: =IF(R72="","",_xlfn.RANK.AVG(R72,$R$15:$R$115))
B73: 8 | C73: =IF('INPUT DATA'!Q18="","",'INPUT DATA'!Q18) | F73: =IF('INPUT DATA'!T18="","",'INPUT DATA'!T18) | H73: =IF('INPUT DATA'!S18="","",'INPUT DATA'!S18) | I73: =IF(H73="","",DATEDIF(H73,TODAY(),"Y")) | R73: =IF(COUNT(K73:Q73)=0,"",ROUND(AVERAGE(K73:Q73),0)) | S73: =IF(R73="","",_xlfn.RANK.AVG(R73,$R$15:$R$115))
B74: 9 | C74: =IF('INPUT DATA'!Q19="","",'INPUT DATA'!Q19) | F74: =IF('INPUT DATA'!T19="","",'INPUT DATA'!T19) | H74: =IF('INPUT DATA'!S19="","",'INPUT DATA'!S19) | I74: =IF(H74="","",DATEDIF(H74,TODAY(),"Y")) | R74: =IF(COUNT(K74:Q74)=0,"",ROUND(AVERAGE(K74:Q74),0)) | S74: =IF(R74="","",_xlfn.RANK.AVG(R74,$R$15:$R$115))
B75: 10 | C75: =IF('INPUT DATA'!Q20="","",'INPUT DATA'!Q20) | F75: =IF('INPUT DATA'!T20="","",'INPUT DATA'!T20) | H75: =IF('INPUT DATA'!S20="","",'INPUT DATA'!S20) | I75: =IF(H75="","",DATEDIF(H75,TODAY(),"Y")) | R75: =IF(COUNT(K75:Q75)=0,"",ROUND(AVERAGE(K75:Q75),0)) | S75: =IF(R75="","",_xlfn.RANK.AVG(R75,$R$15:$R$115))
B76: 11 | C76: =IF('INPUT DATA'!Q21="","",'INPUT DATA'!Q21) | F76: =IF('INPUT DATA'!T21="","",'INPUT DATA'!T21) | H76: =IF('INPUT DATA'!S21="","",'INPUT DATA'!S21) | I76: =IF(H76="","",DATEDIF(H76,TODAY(),"Y")) | R76: =IF(COUNT(K76:Q76)=0,"",ROUND(AVERAGE(K76:Q76),0)) | S76: =IF(R76="","",_xlfn.RANK.AVG(R76,$R$15:$R$115))
B77: 12 | C77: =IF('INPUT DATA'!Q22="","",'INPUT DATA'!Q22) | F77: =IF('INPUT DATA'!T22="","",'INPUT DATA'!T22) | H77: =IF('INPUT DATA'!S22="","",'INPUT DATA'!S22) | I77: =IF(H77="","",DATEDIF(H77,TODAY(),"Y")) | R77: =IF(COUNT(K77:Q77)=0,"",ROUND(AVERAGE(K77:Q77),0)) | S77: =IF(R77="","",_xlfn.RANK.AVG(R77,$R$15:$R$115))
B78: 13 | C78: =IF('INPUT DATA'!Q23="","",'INPUT DATA'!Q23) | F78: =IF('INPUT DATA'!T23="","",'INPUT DATA'!T23) | H78: =IF('INPUT DATA'!S23="","",'INPUT DATA'!S23) | I78: =IF(H78="","",DATEDIF(H78,TODAY(),"Y")) | R78: =IF(COUNT(K78:Q78)=0,"",ROUND(AVERAGE(K78:Q78),0)) | S78: =IF(R78="","",_xlfn.RANK.AVG(R78,$R$15:$R$115))
B79: 14 | C79: =IF('INPUT DATA'!Q24="","",'INPUT DATA'!Q24) | F79: =IF('INPUT DATA'!T24="","",'INPUT DATA'!T24) | H79: =IF('INPUT DATA'!S24="","",'INPUT DATA'!S24) | I79: =IF(H79="","",DATEDIF(H79,TODAY(),"Y")) | R79: =IF(COUNT(K79:Q79)=0,"",ROUND(AVERAGE(K79:Q79),0)) | S79: =IF(R79="","",_xlfn.RANK.AVG(R79,$R$15:$R$115))
...

Sheet TERM 2 SUMMARY
A1: CLASS SUMMARY
D5: REGION | E5: ='INPUT DATA'!F10 -> 0 | I5: DIVISION | J5: ='INPUT DATA'!F11 -> 0
D6: SCHOOL NAME | E6: ='INPUT DATA'!F16 -> 0 | I6: SCHOOL ID | J6: ='INPUT DATA'!F15 -> 0 | O6: SCHOOL YEAR | Q6: ='INPUT DATA'!F18 -> 0
B9: SECOND TERM | F9: GRADE LEVEL | G9: ='INPUT DATA'!F27 -> 0 | L9: SECTION | N9: ='INPUT DATA'!F29 -> 0
F10: TRACK | G10: ='INPUT DATA'!F28 -> 0 | L10: ADVISER | N10: ='INPUT DATA'!F26 -> 0
B11: LEARNERS' NAMES | F11: LRN | H11: Date of Birth | I11: Age | J11: Sex | K11: Learning Areas | R11: Final Grade | S11: Rank
K12: Core Subjects | Q12: Elective Subjects
K13: Effective Communication | L13: Mabisang Komunikasyon | M13: General Mathematics | N13: General Science | O13: Life and Career Skills | P13: PKLP | Q13: AE 2
B15: 1 | C15: =IF('INPUT DATA'!L11="","",'INPUT DATA'!L11) | F15: =IF('INPUT DATA'!M11="","",'INPUT DATA'!M11) | H15: =IF('INPUT DATA'!N11="","",'INPUT DATA'!N11) | I15: =IF(H15="","",DATEDIF(H15,TODAY(),"Y")) | J15: M | R15: =IF(COUNT(K15:Q15)=0,"",ROUND(AVERAGE(K15:Q15),0)) | S15: =IF(R15="","",_xlfn.RANK.AVG(R15,$R$15:$R$115))
B16: 2 | C16: =IF('INPUT DATA'!L12="","",'INPUT DATA'!L12) | F16: =IF('INPUT DATA'!M12="","",'INPUT DATA'!M12) | H16: =IF('INPUT DATA'!N12="","",'INPUT DATA'!N12) | I16: =IF(H16="","",DATEDIF(H16,TODAY(),"Y")) | J16: M | R16: =IF(COUNT(K16:Q16)=0,"",ROUND(AVERAGE(K16:Q16),0)) | S16: =IF(R16="","",_xlfn.RANK.AVG(R16,$R$15:$R$115))
B17: 3 | C17: =IF('INPUT DATA'!L13="","",'INPUT DATA'!L13) | F17: =IF('INPUT DATA'!M13="","",'INPUT DATA'!M13) | H17: =IF('INPUT DATA'!N13="","",'INPUT DATA'!N13) | I17: =IF(H17="","",DATEDIF(H17,TODAY(),"Y")) | J17: M | R17: =IF(COUNT(K17:Q17)=0,"",ROUND(AVERAGE(K17:Q17),0)) | S17: =IF(R17="","",_xlfn.RANK.AVG(R17,$R$15:$R$115))
B18: 4 | C18: =IF('INPUT DATA'!L14="","",'INPUT DATA'!L14) | F18: =IF('INPUT DATA'!M14="","",'INPUT DATA'!M14) | H18: =IF('INPUT DATA'!N14="","",'INPUT DATA'!N14) | I18: =IF(H18="","",DATEDIF(H18,TODAY(),"Y")) | R18: =IF(COUNT(K18:Q18)=0,"",ROUND(AVERAGE(K18:Q18),0)) | S18: =IF(R18="","",_xlfn.RANK.AVG(R18,$R$15:$R$115))
B19: 5 | C19: =IF('INPUT DATA'!L15="","",'INPUT DATA'!L15) | F19: =IF('INPUT DATA'!M15="","",'INPUT DATA'!M15) | H19: =IF('INPUT DATA'!N15="","",'INPUT DATA'!N15) | I19: =IF(H19="","",DATEDIF(H19,TODAY(),"Y")) | R19: =IF(COUNT(K19:Q19)=0,"",ROUND(AVERAGE(K19:Q19),0)) | S19: =IF(R19="","",_xlfn.RANK.AVG(R19,$R$15:$R$115))
B20: 6 | C20: =IF('INPUT DATA'!L16="","",'INPUT DATA'!L16) | F20: =IF('INPUT DATA'!M16="","",'INPUT DATA'!M16) | H20: =IF('INPUT DATA'!N16="","",'INPUT DATA'!N16) | I20: =IF(H20="","",DATEDIF(H20,TODAY(),"Y")) | R20: =IF(COUNT(K20:Q20)=0,"",ROUND(AVERAGE(K20:Q20),0)) | S20: =IF(R20="","",_xlfn.RANK.AVG(R20,$R$15:$R$115))
B21: 7 | C21: =IF('INPUT DATA'!L17="","",'INPUT DATA'!L17) | F21: =IF('INPUT DATA'!M17="","",'INPUT DATA'!M17) | H21: =IF('INPUT DATA'!N17="","",'INPUT DATA'!N17) | I21: =IF(H21="","",DATEDIF(H21,TODAY(),"Y")) | R21: =IF(COUNT(K21:Q21)=0,"",ROUND(AVERAGE(K21:Q21),0)) | S21: =IF(R21="","",_xlfn.RANK.AVG(R21,$R$15:$R$115))
B22: 8 | C22: =IF('INPUT DATA'!L18="","",'INPUT DATA'!L18) | F22: =IF('INPUT DATA'!M18="","",'INPUT DATA'!M18) | H22: =IF('INPUT DATA'!N18="","",'INPUT DATA'!N18) | I22: =IF(H22="","",DATEDIF(H22,TODAY(),"Y")) | R22: =IF(COUNT(K22:Q22)=0,"",ROUND(AVERAGE(K22:Q22),0)) | S22: =IF(R22="","",_xlfn.RANK.AVG(R22,$R$15:$R$115))
B23: 9 | C23: =IF('INPUT DATA'!L19="","",'INPUT DATA'!L19) | F23: =IF('INPUT DATA'!M19="","",'INPUT DATA'!M19) | H23: =IF('INPUT DATA'!N19="","",'INPUT DATA'!N19) | I23: =IF(H23="","",DATEDIF(H23,TODAY(),"Y")) | R23: =IF(COUNT(K23:Q23)=0,"",ROUND(AVERAGE(K23:Q23),0)) | S23: =IF(R23="","",_xlfn.RANK.AVG(R23,$R$15:$R$115))
B24: 10 | C24: =IF('INPUT DATA'!L20="","",'INPUT DATA'!L20) | F24: =IF('INPUT DATA'!M20="","",'INPUT DATA'!M20) | H24: =IF('INPUT DATA'!N20="","",'INPUT DATA'!N20) | I24: =IF(H24="","",DATEDIF(H24,TODAY(),"Y")) | R24: =IF(COUNT(K24:Q24)=0,"",ROUND(AVERAGE(K24:Q24),0)) | S24: =IF(R24="","",_xlfn.RANK.AVG(R24,$R$15:$R$115))
B25: 11 | C25: =IF('INPUT DATA'!L21="","",'INPUT DATA'!L21) | F25: =IF('INPUT DATA'!M21="","",'INPUT DATA'!M21) | H25: =IF('INPUT DATA'!N21="","",'INPUT DATA'!N21) | I25: =IF(H25="","",DATEDIF(H25,TODAY(),"Y")) | R25: =IF(COUNT(K25:Q25)=0,"",ROUND(AVERAGE(K25:Q25),0)) | S25: =IF(R25="","",_xlfn.RANK.AVG(R25,$R$15:$R$115))
B26: 12 | C26: =IF('INPUT DATA'!L22="","",'INPUT DATA'!L22) | F26: =IF('INPUT DATA'!M22="","",'INPUT DATA'!M22) | H26: =IF('INPUT DATA'!N22="","",'INPUT DATA'!N22) | I26: =IF(H26="","",DATEDIF(H26,TODAY(),"Y")) | R26: =IF(COUNT(K26:Q26)=0,"",ROUND(AVERAGE(K26:Q26),0)) | S26: =IF(R26="","",_xlfn.RANK.AVG(R26,$R$15:$R$115))
B27: 13 | C27: =IF('INPUT DATA'!L23="","",'INPUT DATA'!L23) | F27: =IF('INPUT DATA'!M23="","",'INPUT DATA'!M23) | H27: =IF('INPUT DATA'!N23="","",'INPUT DATA'!N23) | I27: =IF(H27="","",DATEDIF(H27,TODAY(),"Y")) | R27: =IF(COUNT(K27:Q27)=0,"",ROUND(AVERAGE(K27:Q27),0)) | S27: =IF(R27="","",_xlfn.RANK.AVG(R27,$R$15:$R$115))
B28: 14 | C28: =IF('INPUT DATA'!L24="","",'INPUT DATA'!L24) | F28: =IF('INPUT DATA'!M24="","",'INPUT DATA'!M24) | H28: =IF('INPUT DATA'!N24="","",'INPUT DATA'!N24) | I28: =IF(H28="","",DATEDIF(H28,TODAY(),"Y")) | R28: =IF(COUNT(K28:Q28)=0,"",ROUND(AVERAGE(K28:Q28),0)) | S28: =IF(R28="","",_xlfn.RANK.AVG(R28,$R$15:$R$115))
B29: 15 | C29: =IF('INPUT DATA'!L25="","",'INPUT DATA'!L25) | F29: =IF('INPUT DATA'!M25="","",'INPUT DATA'!M25) | H29: =IF('INPUT DATA'!N25="","",'INPUT DATA'!N25) | I29: =IF(H29="","",DATEDIF(H29,TODAY(),"Y")) | R29: =IF(COUNT(K29:Q29)=0,"",ROUND(AVERAGE(K29:Q29),0)) | S29: =IF(R29="","",_xlfn.RANK.AVG(R29,$R$15:$R$115))
... B64: 50 | C64: =IF('INPUT DATA'!L60="","",'INPUT DATA'!L60) | F64: =IF('INPUT DATA'!M60="","",'INPUT DATA'!M60) | H64: =IF('INPUT DATA'!N60="","",'INPUT DATA'!N60) | I64: =IF(H64="","",DATEDIF(H64,TODAY(),"Y")) | R64: =IF(COUNT(K64:Q64)=0,"",ROUND(AVERAGE(K64:Q64),0)) | S64: =IF(R64="","",_xlfn.RANK.AVG(R64,$R$15:$R$115))
B65: FEMALE
B66: 1 | C66: =IF('INPUT DATA'!Q11="","",'INPUT DATA'!Q11) | F66: =IF('INPUT DATA'!T11="","",'INPUT DATA'!T11) | H66: =IF('INPUT DATA'!S11="","",'INPUT DATA'!S11) | I66: =IF(H66="","",DATEDIF(H66,TODAY(),"Y")) | J66: F | R66: =IF(COUNT(K66:Q66)=0,"",ROUND(AVERAGE(K66:Q66),0)) | S66: =IF(R66="","",_xlfn.RANK.AVG(R66,$R$15:$R$115))
B67: 2 | C67: =IF('INPUT DATA'!Q12="","",'INPUT DATA'!Q12) | F67: =IF('INPUT DATA'!T12="","",'INPUT DATA'!T12) | H67: =IF('INPUT DATA'!S12="","",'INPUT DATA'!S12) | I67: =IF(H67="","",DATEDIF(H67,TODAY(),"Y")) | J67: F | R67: =IF(COUNT(K67:Q67)=0,"",ROUND(AVERAGE(K67:Q67),0)) | S67: =IF(R67="","",_xlfn.RANK.AVG(R67,$R$15:$R$115))
B68: 3 | C68: =IF('INPUT DATA'!Q13="","",'INPUT DATA'!Q13) | F68: =IF('INPUT DATA'!T13="","",'INPUT DATA'!T13) | H68: =IF('INPUT DATA'!S13="","",'INPUT DATA'!S13) | I68: =IF(H68="","",DATEDIF(H68,TODAY(),"Y")) | J68: F | R68: =IF(COUNT(K68:Q68)=0,"",ROUND(AVERAGE(K68:Q68),0)) | S68: =IF(R68="","",_xlfn.RANK.AVG(R68,$R$15:$R$115))
B69: 4 | C69: =IF('INPUT DATA'!Q14="","",'INPUT DATA'!Q14) | F69: =IF('INPUT DATA'!T14="","",'INPUT DATA'!T14) | H69: =IF('INPUT DATA'!S14="","",'INPUT DATA'!S14) | I69: =IF(H69="","",DATEDIF(H69,TODAY(),"Y")) | R69: =IF(COUNT(K69:Q69)=0,"",ROUND(AVERAGE(K69:Q69),0)) | S69: =IF(R69="","",_xlfn.RANK.AVG(R69,$R$15:$R$115))
B70: 5 | C70: =IF('INPUT DATA'!Q15="","",'INPUT DATA'!Q15) | F70: =IF('INPUT DATA'!T15="","",'INPUT DATA'!T15) | H70: =IF('INPUT DATA'!S15="","",'INPUT DATA'!S15) | I70: =IF(H70="","",DATEDIF(H70,TODAY(),"Y")) | R70: =IF(COUNT(K70:Q70)=0,"",ROUND(AVERAGE(K70:Q70),0)) | S70: =IF(R70="","",_xlfn.RANK.AVG(R70,$R$15:$R$115))
B71: 6 | C71: =IF('INPUT DATA'!Q16="","",'INPUT DATA'!Q16) | F71: =IF('INPUT DATA'!T16="","",'INPUT DATA'!T16) | H71: =IF('INPUT DATA'!S16="","",'INPUT DATA'!S16) | I71: =IF(H71="","",DATEDIF(H71,TODAY(),"Y")) | R71: =IF(COUNT(K71:Q71)=0,"",ROUND(AVERAGE(K71:Q71),0)) | S71: =IF(R71="","",_xlfn.RANK.AVG(R71,$R$15:$R$115))
B72: 7 | C72: =IF('INPUT DATA'!Q17="","",'INPUT DATA'!Q17) | F72: =IF('INPUT DATA'!T17="","",'INPUT DATA'!T17) | H72: =IF('INPUT DATA'!S17="","",'INPUT DATA'!S17) | I72: =IF(H72="","",DATEDIF(H72,TODAY(),"Y")) | R72: =IF(COUNT(K72:Q72)=0,"",ROUND(AVERAGE(K72:Q72),0)) | S72: =IF(R72="","",_xlfn.RANK.AVG(R72,$R$15:$R$115))
B73: 8 | C73: =IF('INPUT DATA'!Q18="","",'INPUT DATA'!Q18) | F73: =IF('INPUT DATA'!T18="","",'INPUT DATA'!T18) | H73: =IF('INPUT DATA'!S18="","",'INPUT DATA'!S18) | I73: =IF(H73="","",DATEDIF(H73,TODAY(),"Y")) | R73: =IF(COUNT(K73:Q73)=0,"",ROUND(AVERAGE(K73:Q73),0)) | S73: =IF(R73="","",_xlfn.RANK.AVG(R73,$R$15:$R$115))
B74: 9 | C74: =IF('INPUT DATA'!Q19="","",'INPUT DATA'!Q19) | F74: =IF('INPUT DATA'!T19="","",'INPUT DATA'!T19) | H74: =IF('INPUT DATA'!S19="","",'INPUT DATA'!S19) | I74: =IF(H74="","",DATEDIF(H74,TODAY(),"Y")) | R74: =IF(COUNT(K74:Q74)=0,"",ROUND(AVERAGE(K74:Q74),0)) | S74: =IF(R74="","",_xlfn.RANK.AVG(R74,$R$15:$R$115))
B75: 10 | C75: =IF('INPUT DATA'!Q20="","",'INPUT DATA'!Q20) | F75: =IF('INPUT DATA'!T20="","",'INPUT DATA'!T20) | H75: =IF('INPUT DATA'!S20="","",'INPUT DATA'!S20) | I75: =IF(H75="","",DATEDIF(H75,TODAY(),"Y")) | R75: =IF(COUNT(K75:Q75)=0,"",ROUND(AVERAGE(K75:Q75),0)) | S75: =IF(R75="","",_xlfn.RANK.AVG(R75,$R$15:$R$115))
B76: 11 | C76: =IF('INPUT DATA'!Q21="","",'INPUT DATA'!Q21) | F76: =IF('INPUT DATA'!T21="","",'INPUT DATA'!T21) | H76: =IF('INPUT DATA'!S21="","",'INPUT DATA'!S21) | I76: =IF(H76="","",DATEDIF(H76,TODAY(),"Y")) | R76: =IF(COUNT(K76:Q76)=0,"",ROUND(AVERAGE(K76:Q76),0)) | S76: =IF(R76="","",_xlfn.RANK.AVG(R76,$R$15:$R$115))
B77: 12 | C77: =IF('INPUT DATA'!Q22="","",'INPUT DATA'!Q22) | F77: =IF('INPUT DATA'!T22="","",'INPUT DATA'!T22) | H77: =IF('INPUT DATA'!S22="","",'INPUT DATA'!S22) | I77: =IF(H77="","",DATEDIF(H77,TODAY(),"Y")) | R77: =IF(COUNT(K77:Q77)=0,"",ROUND(AVERAGE(K77:Q77),0)) | S77: =IF(R77="","",_xlfn.RANK.AVG(R77,$R$15:$R$115))
B78: 13 | C78: =IF('INPUT DATA'!Q23="","",'INPUT DATA'!Q23) | F78: =IF('INPUT DATA'!T23="","",'INPUT DATA'!T23) | H78: =IF('INPUT DATA'!S23="","",'INPUT DATA'!S23) | I78: =IF(H78="","",DATEDIF(H78,TODAY(),"Y")) | R78: =IF(COUNT(K78:Q78)=0,"",ROUND(AVERAGE(K78:Q78),0)) | S78: =IF(R78="","",_xlfn.RANK.AVG(R78,$R$15:$R$115))
B79: 14 | C79: =IF('INPUT DATA'!Q24="","",'INPUT DATA'!Q24) | F79: =IF('INPUT DATA'!T24="","",'INPUT DATA'!T24) | H79: =IF('INPUT DATA'!S24="","",'INPUT DATA'!S24) | I79: =IF(H79="","",DATEDIF(H79,TODAY(),"Y")) | R79: =IF(COUNT(K79:Q79)=0,"",ROUND(AVERAGE(K79:Q79),0)) | S79: =IF(R79="","",_xlfn.RANK.AVG(R79,$R$15:$R$115))
B80: 15 | C80: =IF('INPUT DATA'!Q25="","",'INPUT DATA'!Q25) | F80: =IF('INPUT DATA'!T25="","",'INPUT DATA'!T25) | H80: =IF('INPUT DATA'!S25="","",'INPUT DATA'!S25) | I80: =IF(H80="","",DATEDIF(H80,TODAY(),"Y")) | R80: =IF(COUNT(K80:Q80)=0,"",ROUND(AVERAGE(K80:Q80),0)) | S80: =IF(R80="","",_xlfn.RANK.AVG(R80,$R$15:$R$115))
...

Sheet TERM 3 SUMMARY
A1: CLASS SUMMARY
D5: REGION | E5: ='INPUT DATA'!F10 -> 0 | I5: DIVISION | J5: ='INPUT DATA'!F11 -> 0
D6: SCHOOL NAME | E6: ='INPUT DATA'!F16 -> 0 | I6: SCHOOL ID | J6: ='INPUT DATA'!F15 -> 0 | O6: SCHOOL YEAR | Q6: ='INPUT DATA'!F18 -> 0
B9: THIRD TERM | F9: GRADE LEVEL | G9: ='INPUT DATA'!F27 -> 0 | L9: SECTION | N9: ='INPUT DATA'!F29 -> 0
F10: TRACK | G10: ='INPUT DATA'!F28 -> 0 | L10: ADVISER | N10: ='INPUT DATA'!F26 -> 0
B11: LEARNERS' NAMES | F11: LRN | H11: Date of Birth | I11: Age | J11: Sex | K11: Learning Areas | R11: Final Grade | S11: Rank
K12: Core Subjects | Q12: Elective Subjects
K13: Effective Communication | L13: Mabisang Komunikasyon | M13: General Mathematics | N13: General Science | O13: Life and Career Skills | P13: PKLP | Q13: AE 3
B15: 1 | C15: =IF('INPUT DATA'!L11="","",'INPUT DATA'!L11) | F15: =IF('INPUT DATA'!M11="","",'INPUT DATA'!M11) | H15: =IF('INPUT DATA'!N11="","",'INPUT DATA'!N11) | I15: =IF(H15="","",DATEDIF(H15,TODAY(),"Y")) | J15: M | R15: =IF(COUNT(K15:Q15)=0,"",ROUND(AVERAGE(K15:Q15),0)) | S15: =IF(R15="","",_xlfn.RANK.AVG(R15,$R$15:$R$115))
B16: 2 | C16: =IF('INPUT DATA'!L12="","",'INPUT DATA'!L12) | F16: =IF('INPUT DATA'!M12="","",'INPUT DATA'!M12) | H16: =IF('INPUT DATA'!N12="","",'INPUT DATA'!N12) | I16: =IF(H16="","",DATEDIF(H16,TODAY(),"Y")) | J16: M | R16: =IF(COUNT(K16:Q16)=0,"",ROUND(AVERAGE(K16:Q16),0)) | S16: =IF(R16="","",_xlfn.RANK.AVG(R16,$R$15:$R$115))
B17: 3 | C17: =IF('INPUT DATA'!L13="","",'INPUT DATA'!L13) | F17: =IF('INPUT DATA'!M13="","",'INPUT DATA'!M13) | H17: =IF('INPUT DATA'!N13="","",'INPUT DATA'!N13) | I17: =IF(H17="","",DATEDIF(H17,TODAY(),"Y")) | J17: M | R17: =IF(COUNT(K17:Q17)=0,"",ROUND(AVERAGE(K17:Q17),0)) | S17: =IF(R17="","",_xlfn.RANK.AVG(R17,$R$15:$R$115))
B18: 4 | C18: =IF('INPUT DATA'!L14="","",'INPUT DATA'!L14) | F18: =IF('INPUT DATA'!M14="","",'INPUT DATA'!M14) | H18: =IF('INPUT DATA'!N14="","",'INPUT DATA'!N14) | I18: =IF(H18="","",DATEDIF(H18,TODAY(),"Y")) | R18: =IF(COUNT(K18:Q18)=0,"",ROUND(AVERAGE(K18:Q18),0)) | S18: =IF(R18="","",_xlfn.RANK.AVG(R18,$R$15:$R$115))
B19: 5 | C19: =IF('INPUT DATA'!L15="","",'INPUT DATA'!L15) | F19: =IF('INPUT DATA'!M15="","",'INPUT DATA'!M15) | H19: =IF('INPUT DATA'!N15="","",'INPUT DATA'!N15) | I19: =IF(H19="","",DATEDIF(H19,TODAY(),"Y")) | R19: =IF(COUNT(K19:Q19)=0,"",ROUND(AVERAGE(K19:Q19),0)) | S19: =IF(R19="","",_xlfn.RANK.AVG(R19,$R$15:$R$115))
B20: 6 | C20: =IF('INPUT DATA'!L16="","",'INPUT DATA'!L16) | F20: =IF('INPUT DATA'!M16="","",'INPUT DATA'!M16) | H20: =IF('INPUT DATA'!N16="","",'INPUT DATA'!N16) | I20: =IF(H20="","",DATEDIF(H20,TODAY(),"Y")) | R20: =IF(COUNT(K20:Q20)=0,"",ROUND(AVERAGE(K20:Q20),0)) | S20: =IF(R20="","",_xlfn.RANK.AVG(R20,$R$15:$R$115))
B21: 7 | C21: =IF('INPUT DATA'!L17="","",'INPUT DATA'!L17) | F21: =IF('INPUT DATA'!M17="","",'INPUT DATA'!M17) | H21: =IF('INPUT DATA'!N17="","",'INPUT DATA'!N17) | I21: =IF(H21="","",DATEDIF(H21,TODAY(),"Y")) | R21: =IF(COUNT(K21:Q21)=0,"",ROUND(AVERAGE(K21:Q21),0)) | S21: =IF(R21="","",_xlfn.RANK.AVG(R21,$R$15:$R$115))
B22: 8 | C22: =IF('INPUT DATA'!L18="","",'INPUT DATA'!L18) | F22: =IF('INPUT DATA'!M18="","",'INPUT DATA'!M18) | H22: =IF('INPUT DATA'!N18="","",'INPUT DATA'!N18) | I22: =IF(H22="","",DATEDIF(H22,TODAY(),"Y")) | R22: =IF(COUNT(K22:Q22)=0,"",ROUND(AVERAGE(K22:Q22),0)) | S22: =IF(R22="","",_xlfn.RANK.AVG(R22,$R$15:$R$115))
B23: 9 | C23: =IF('INPUT DATA'!L19="","",'INPUT DATA'!L19) | F23: =IF('INPUT DATA'!M19="","",'INPUT DATA'!M19) | H23: =IF('INPUT DATA'!N19="","",'INPUT DATA'!N19) | I23: =IF(H23="","",DATEDIF(H23,TODAY(),"Y")) | R23: =IF(COUNT(K23:Q23)=0,"",ROUND(AVERAGE(K23:Q23),0)) | S23: =IF(R23="","",_xlfn.RANK.AVG(R23,$R$15:$R$115))
B24: 10 | C24: =IF('INPUT DATA'!L20="","",'INPUT DATA'!L20) | F24: =IF('INPUT DATA'!M20="","",'INPUT DATA'!M20) | H24: =IF('INPUT DATA'!N20="","",'INPUT DATA'!N20) | I24: =IF(H24="","",DATEDIF(H24,TODAY(),"Y")) | R24: =IF(COUNT(K24:Q24)=0,"",ROUND(AVERAGE(K24:Q24),0)) | S24: =IF(R24="","",_xlfn.RANK.AVG(R24,$R$15:$R$115))
B25: 11 | C25: =IF('INPUT DATA'!L21="","",'INPUT DATA'!L21) | F25: =IF('INPUT DATA'!M21="","",'INPUT DATA'!M21) | H25: =IF('INPUT DATA'!N21="","",'INPUT DATA'!N21) | I25: =IF(H25="","",DATEDIF(H25,TODAY(),"Y")) | R25: =IF(COUNT(K25:Q25)=0,"",ROUND(AVERAGE(K25:Q25),0)) | S25: =IF(R25="","",_xlfn.RANK.AVG(R25,$R$15:$R$115))
B26: 12 | C26: =IF('INPUT DATA'!L22="","",'INPUT DATA'!L22) | F26: =IF('INPUT DATA'!M22="","",'INPUT DATA'!M22) | H26: =IF('INPUT DATA'!N22="","",'INPUT DATA'!N22) | I26: =IF(H26="","",DATEDIF(H26,TODAY(),"Y")) | R26: =IF(COUNT(K26:Q26)=0,"",ROUND(AVERAGE(K26:Q26),0)) | S26: =IF(R26="","",_xlfn.RANK.AVG(R26,$R$15:$R$115))
B27: 13 | C27: =IF('INPUT DATA'!L23="","",'INPUT DATA'!L23) | F27: =IF('INPUT DATA'!M23="","",'INPUT DATA'!M23) | H27: =IF('INPUT DATA'!N23="","",'INPUT DATA'!N23) | I27: =IF(H27="","",DATEDIF(H27,TODAY(),"Y")) | R27: =IF(COUNT(K27:Q27)=0,"",ROUND(AVERAGE(K27:Q27),0)) | S27: =IF(R27="","",_xlfn.RANK.AVG(R27,$R$15:$R$115))
B28: 14 | C28: =IF('INPUT DATA'!L24="","",'INPUT DATA'!L24) | F28: =IF('INPUT DATA'!M24="","",'INPUT DATA'!M24) | H28: =IF('INPUT DATA'!N24="","",'INPUT DATA'!N24) | I28: =IF(H28="","",DATEDIF(H28,TODAY(),"Y")) | R28: =IF(COUNT(K28:Q28)=0,"",ROUND(AVERAGE(K28:Q28),0)) | S28: =IF(R28="","",_xlfn.RANK.AVG(R28,$R$15:$R$115))
B29: 15 | C29: =IF('INPUT DATA'!L25="","",'INPUT DATA'!L25) | F29: =IF('INPUT DATA'!M25="","",'INPUT DATA'!M25) | H29: =IF('INPUT DATA'!N25="","",'INPUT DATA'!N25) | I29: =IF(H29="","",DATEDIF(H29,TODAY(),"Y")) | R29: =IF(COUNT(K29:Q29)=0,"",ROUND(AVERAGE(K29:Q29),0)) | S29: =IF(R29="","",_xlfn.RANK.AVG(R29,$R$15:$R$115))
... B64: 50 | C64: =IF('INPUT DATA'!L60="","",'INPUT DATA'!L60) | F64: =IF('INPUT DATA'!M60="","",'INPUT DATA'!M60) | H64: =IF('INPUT DATA'!N60="","",'INPUT DATA'!N60) | I64: =IF(H64="","",DATEDIF(H64,TODAY(),"Y")) | R64: =IF(COUNT(K64:Q64)=0,"",ROUND(AVERAGE(K64:Q64),0)) | S64: =IF(R64="","",_xlfn.RANK.AVG(R64,$R$15:$R$115))
B65: FEMALE
B66: 1 | C66: =IF('INPUT DATA'!Q11="","",'INPUT DATA'!Q11) | F66: =IF('INPUT DATA'!T11="","",'INPUT DATA'!T11) | H66: =IF('INPUT DATA'!S11="","",'INPUT DATA'!S11) | I66: =IF(H66="","",DATEDIF(H66,TODAY(),"Y")) | J66: F | R66: =IF(COUNT(K66:Q66)=0,"",ROUND(AVERAGE(K66:Q66),0)) | S66: =IF(R66="","",_xlfn.RANK.AVG(R66,$R$15:$R$115))
B67: 2 | C67: =IF('INPUT DATA'!Q12="","",'INPUT DATA'!Q12) | F67: =IF('INPUT DATA'!T12="","",'INPUT DATA'!T12) | H67: =IF('INPUT DATA'!S12="","",'INPUT DATA'!S12) | I67: =IF(H67="","",DATEDIF(H67,TODAY(),"Y")) | J67: F | R67: =IF(COUNT(K67:Q67)=0,"",ROUND(AVERAGE(K67:Q67),0)) | S67: =IF(R67="","",_xlfn.RANK.AVG(R67,$R$15:$R$115))
B68: 3 | C68: =IF('INPUT DATA'!Q13="","",'INPUT DATA'!Q13) | F68: =IF('INPUT DATA'!T13="","",'INPUT DATA'!T13) | H68: =IF('INPUT DATA'!S13="","",'INPUT DATA'!S13) | I68: =IF(H68="","",DATEDIF(H68,TODAY(),"Y")) | J68: F | R68: =IF(COUNT(K68:Q68)=0,"",ROUND(AVERAGE(K68:Q68),0)) | S68: =IF(R68="","",_xlfn.RANK.AVG(R68,$R$15:$R$115))
B69: 4 | C69: =IF('INPUT DATA'!Q14="","",'INPUT DATA'!Q14) | F69: =IF('INPUT DATA'!T14="","",'INPUT DATA'!T14) | H69: =IF('INPUT DATA'!S14="","",'INPUT DATA'!S14) | I69: =IF(H69="","",DATEDIF(H69,TODAY(),"Y")) | R69: =IF(COUNT(K69:Q69)=0,"",ROUND(AVERAGE(K69:Q69),0)) | S69: =IF(R69="","",_xlfn.RANK.AVG(R69,$R$15:$R$115))
B70: 5 | C70: =IF('INPUT DATA'!Q15="","",'INPUT DATA'!Q15) | F70: =IF('INPUT DATA'!T15="","",'INPUT DATA'!T15) | H70: =IF('INPUT DATA'!S15="","",'INPUT DATA'!S15) | I70: =IF(H70="","",DATEDIF(H70,TODAY(),"Y")) | R70: =IF(COUNT(K70:Q70)=0,"",ROUND(AVERAGE(K70:Q70),0)) | S70: =IF(R70="","",_xlfn.RANK.AVG(R70,$R$15:$R$115))
B71: 6 | C71: =IF('INPUT DATA'!Q16="","",'INPUT DATA'!Q16) | F71: =IF('INPUT DATA'!T16="","",'INPUT DATA'!T16) | H71: =IF('INPUT DATA'!S16="","",'INPUT DATA'!S16) | I71: =IF(H71="","",DATEDIF(H71,TODAY(),"Y")) | R71: =IF(COUNT(K71:Q71)=0,"",ROUND(AVERAGE(K71:Q71),0)) | S71: =IF(R71="","",_xlfn.RANK.AVG(R71,$R$15:$R$115))
B72: 7 | C72: =IF('INPUT DATA'!Q17="","",'INPUT DATA'!Q17) | F72: =IF('INPUT DATA'!T17="","",'INPUT DATA'!T17) | H72: =IF('INPUT DATA'!S17="","",'INPUT DATA'!S17) | I72: =IF(H72="","",DATEDIF(H72,TODAY(),"Y")) | R72: =IF(COUNT(K72:Q72)=0,"",ROUND(AVERAGE(K72:Q72),0)) | S72: =IF(R72="","",_xlfn.RANK.AVG(R72,$R$15:$R$115))
B73: 8 | C73: =IF('INPUT DATA'!Q18="","",'INPUT DATA'!Q18) | F73: =IF('INPUT DATA'!T18="","",'INPUT DATA'!T18) | H73: =IF('INPUT DATA'!S18="","",'INPUT DATA'!S18) | I73: =IF(H73="","",DATEDIF(H73,TODAY(),"Y")) | R73: =IF(COUNT(K73:Q73)=0,"",ROUND(AVERAGE(K73:Q73),0)) | S73: =IF(R73="","",_xlfn.RANK.AVG(R73,$R$15:$R$115))
B74: 9 | C74: =IF('INPUT DATA'!Q19="","",'INPUT DATA'!Q19) | F74: =IF('INPUT DATA'!T19="","",'INPUT DATA'!T19) | H74: =IF('INPUT DATA'!S19="","",'INPUT DATA'!S19) | I74: =IF(H74="","",DATEDIF(H74,TODAY(),"Y")) | R74: =IF(COUNT(K74:Q74)=0,"",ROUND(AVERAGE(K74:Q74),0)) | S74: =IF(R74="","",_xlfn.RANK.AVG(R74,$R$15:$R$115))
B75: 10 | C75: =IF('INPUT DATA'!Q20="","",'INPUT DATA'!Q20) | F75: =IF('INPUT DATA'!T20="","",'INPUT DATA'!T20) | H75: =IF('INPUT DATA'!S20="","",'INPUT DATA'!S20) | I75: =IF(H75="","",DATEDIF(H75,TODAY(),"Y")) | R75: =IF(COUNT(K75:Q75)=0,"",ROUND(AVERAGE(K75:Q75),0)) | S75: =IF(R75="","",_xlfn.RANK.AVG(R75,$R$15:$R$115))
B76: 11 | C76: =IF('INPUT DATA'!Q21="","",'INPUT DATA'!Q21) | F76: =IF('INPUT DATA'!T21="","",'INPUT DATA'!T21) | H76: =IF('INPUT DATA'!S21="","",'INPUT DATA'!S21) | I76: =IF(H76="","",DATEDIF(H76,TODAY(),"Y")) | R76: =IF(COUNT(K76:Q76)=0,"",ROUND(AVERAGE(K76:Q76),0)) | S76: =IF(R76="","",_xlfn.RANK.AVG(R76,$R$15:$R$115))
B77: 12 | C77: =IF('INPUT DATA'!Q22="","",'INPUT DATA'!Q22) | F77: =IF('INPUT DATA'!T22="","",'INPUT DATA'!T22) | H77: =IF('INPUT DATA'!S22="","",'INPUT DATA'!S22) | I77: =IF(H77="","",DATEDIF(H77,TODAY(),"Y")) | R77: =IF(COUNT(K77:Q77)=0,"",ROUND(AVERAGE(K77:Q77),0)) | S77: =IF(R77="","",_xlfn.RANK.AVG(R77,$R$15:$R$115))
B78: 13 | C78: =IF('INPUT DATA'!Q23="","",'INPUT DATA'!Q23) | F78: =IF('INPUT DATA'!T23="","",'INPUT DATA'!T23) | H78: =IF('INPUT DATA'!S23="","",'INPUT DATA'!S23) | I78: =IF(H78="","",DATEDIF(H78,TODAY(),"Y")) | R78: =IF(COUNT(K78:Q78)=0,"",ROUND(AVERAGE(K78:Q78),0)) | S78: =IF(R78="","",_xlfn.RANK.AVG(R78,$R$15:$R$115))
B79: 14 | C79: =IF('INPUT DATA'!Q24="","",'INPUT DATA'!Q24) | F79: =IF('INPUT DATA'!T24="","",'INPUT DATA'!T24) | H79: =IF('INPUT DATA'!S24="","",'INPUT DATA'!S24) | I79: =IF(H79="","",DATEDIF(H79,TODAY(),"Y")) | R79: =IF(COUNT(K79:Q79)=0,"",ROUND(AVERAGE(K79:Q79),0)) | S79: =IF(R79="","",_xlfn.RANK.AVG(R79,$R$15:$R$115))
B80: 15 | C80: =IF('INPUT DATA'!Q25="","",'INPUT DATA'!Q25) | F80: =IF('INPUT DATA'!T25="","",'INPUT DATA'!T25) | H80: =IF('INPUT DATA'!S25="","",'INPUT DATA'!S25) | I80: =IF(H80="","",DATEDIF(H80,TODAY(),"Y")) | R80: =IF(COUNT(K80:Q80)=0,"",ROUND(AVERAGE(K80:Q80),0)) | S80: =IF(R80="","",_xlfn.RANK.AVG(R80,$R$15:$R$115))
...

Sheet FINAL GRADES
A1: FINAL GRADES
C6: REGION | E6: ='INPUT DATA'!F10 -> 0 | J6: DIVISION | L6: ='INPUT DATA'!F11 -> 0
C7: SCHOOL NAME | E7: ='INPUT DATA'!F16 -> 0 | J7: SCHOOL ID | L7: ='INPUT DATA'!F15 -> 0 | P7: SCHOOL YEAR | R7: ='INPUT DATA'!F18 -> 0
B10: LEARNERS' NAMES | F10: GRADE LEVEL | H10: ='INPUT DATA'!F27 -> 0 | N10: ADVISER | P10: EUNICE FERNANDEZ
F11: SECTION | H11: ='INPUT DATA'!F28 -> 0
F12: FIRST TERM | J12: SECOND TERM | M12: THIRD TERM | P12: AVERAGE | S12: RANK
B14: MALE
B15: 1 | C15: =IF('INPUT DATA'!L11="","",'INPUT DATA'!L11) | F15: =IF(TRIM(C15)="","",IFERROR(_xlfn.XLOOKUP(TRIM(C15),'TERM 1 SUMMARY'!$C$15:$C$115,'TERM 1 SUMMARY'!$R$15:$R$115),"")) | J15: =IF(TRIM(C15)="","",IFERROR(_xlfn.XLOOKUP(TRIM(C15),'TERM 2 SUMMARY'!$C$15:$C$115,'TERM 2 SUMMARY'!$R$15:$R$115),"")) | M15: =IF(TRIM(C15)="","",IFERROR(_xlfn.XLOOKUP(TRIM(C15),'TERM 3 SUMMARY'!$C$15:$C$115,'TERM 3 SUMMARY'!$R$15:$R$115),"")) | P15: =IF(C15="","",IF(COUNT($F15:$M15)=0,"",SUM($F15:$M15)/3)) | S15: =IF(P15="","",_xlfn.RANK.AVG(P15,$P$15:$P$115))
B16: 2 | C16: =IF('INPUT DATA'!L12="","",'INPUT DATA'!L12) | F16: =IF(TRIM(C16)="","",IFERROR(_xlfn.XLOOKUP(TRIM(C16),'TERM 1 SUMMARY'!$C$15:$C$115,'TERM 1 SUMMARY'!$R$15:$R$115),"")) | J16: =IF(TRIM(C16)="","",IFERROR(_xlfn.XLOOKUP(TRIM(C16),'TERM 2 SUMMARY'!$C$15:$C$115,'TERM 2 SUMMARY'!$R$15:$R$115),"")) | M16: =IF(TRIM(C16)="","",IFERROR(_xlfn.XLOOKUP(TRIM(C16),'TERM 3 SUMMARY'!$C$15:$C$115,'TERM 3 SUMMARY'!$R$15:$R$115),"")) | P16: =IF(C16="","",IF(COUNT($F16:$M16)=0,"",SUM($F16:$M16)/3)) | S16: =IF(P16="","",_xlfn.RANK.AVG(P16,$P$15:$P$115))
B17: 3 | C17: =IF('INPUT DATA'!L13="","",'INPUT DATA'!L13) | F17: =IF(TRIM(C17)="","",IFERROR(_xlfn.XLOOKUP(TRIM(C17),'TERM 1 SUMMARY'!$C$15:$C$115,'TERM 1 SUMMARY'!$R$15:$R$115),"")) | J17: =IF(TRIM(C17)="","",IFERROR(_xlfn.XLOOKUP(TRIM(C17),'TERM 2 SUMMARY'!$C$15:$C$115,'TERM 2 SUMMARY'!$R$15:$R$115),"")) | M17: =IF(TRIM(C17)="","",IFERROR(_xlfn.XLOOKUP(TRIM(C17),'TERM 3 SUMMARY'!$C$15:$C$115,'TERM 3 SUMMARY'!$R$15:$R$115),"")) | P17: =IF(C17="","",IF(COUNT($F17:$M17)=0,"",SUM($F17:$M17)/3)) | S17: =IF(P17="","",_xlfn.RANK.AVG(P17,$P$15:$P$115))
B18: 4 | C18: =IF('INPUT DATA'!L14="","",'INPUT DATA'!L14) | F18: =IF(TRIM(C18)="","",IFERROR(_xlfn.XLOOKUP(TRIM(C18),'TERM 1 SUMMARY'!$C$15:$C$115,'TERM 1 SUMMARY'!$R$15:$R$115),"")) | J18: =IF(TRIM(C18)="","",IFERROR(_xlfn.XLOOKUP(TRIM(C18),'TERM 2 SUMMARY'!$C$15:$C$115,'TERM 2 SUMMARY'!$R$15:$R$115),"")) | M18: =IF(TRIM(C18)="","",IFERROR(_xlfn.XLOOKUP(TRIM(C18),'TERM 3 SUMMARY'!$C$15:$C$115,'TERM 3 SUMMARY'!$R$15:$R$115),"")) | P18: =IF(C18="","",IF(COUNT($F18:$M18)=0,"",SUM($F18:$M18)/3)) | S18: =IF(P18="","",_xlfn.RANK.AVG(P18,$P$15:$P$115))
B19: 5 | C19: =IF('INPUT DATA'!L15="","",'INPUT DATA'!L15) | F19: =IF(TRIM(C19)="","",IFERROR(_xlfn.XLOOKUP(TRIM(C19),'TERM 1 SUMMARY'!$C$15:$C$115,'TERM 1 SUMMARY'!$R$15:$R$115),"")) | J19: =IF(TRIM(C19)="","",IFERROR(_xlfn.XLOOKUP(TRIM(C19),'TERM 2 SUMMARY'!$C$15:$C$115,'TERM 2 SUMMARY'!$R$15:$R$115),"")) | M19: =IF(TRIM(C19)="","",IFERROR(_xlfn.XLOOKUP(TRIM(C19),'TERM 3 SUMMARY'!$C$15:$C$115,'TERM 3 SUMMARY'!$R$15:$R$115),"")) | P19: =IF(C19="","",IF(COUNT($F19:$M19)=0,"",SUM($F19:$M19)/3)) | S19: =IF(P19="","",_xlfn.RANK.AVG(P19,$P$15:$P$115))
B20: 6 | C20: =IF('INPUT DATA'!L16="","",'INPUT DATA'!L16) | F20: =IF(TRIM(C20)="","",IFERROR(_xlfn.XLOOKUP(TRIM(C20),'TERM 1 SUMMARY'!$C$15:$C$115,'TERM 1 SUMMARY'!$R$15:$R$115),"")) | J20: =IF(TRIM(C20)="","",IFERROR(_xlfn.XLOOKUP(TRIM(C20),'TERM 2 SUMMARY'!$C$15:$C$115,'TERM 2 SUMMARY'!$R$15:$R$115),"")) | M20: =IF(TRIM(C20)="","",IFERROR(_xlfn.XLOOKUP(TRIM(C20),'TERM 3 SUMMARY'!$C$15:$C$115,'TERM 3 SUMMARY'!$R$15:$R$115),"")) | P20: =IF(C20="","",IF(COUNT($F20:$M20)=0,"",SUM($F20:$M20)/3)) | S20: =IF(P20="","",_xlfn.RANK.AVG(P20,$P$15:$P$115))
B21: 7 | C21: =IF('INPUT DATA'!L17="","",'INPUT DATA'!L17) | F21: =IF(TRIM(C21)="","",IFERROR(_xlfn.XLOOKUP(TRIM(C21),'TERM 1 SUMMARY'!$C$15:$C$115,'TERM 1 SUMMARY'!$R$15:$R$115),"")) | J21: =IF(TRIM(C21)="","",IFERROR(_xlfn.XLOOKUP(TRIM(C21),'TERM 2 SUMMARY'!$C$15:$C$115,'TERM 2 SUMMARY'!$R$15:$R$115),"")) | M21: =IF(TRIM(C21)="","",IFERROR(_xlfn.XLOOKUP(TRIM(C21),'TERM 3 SUMMARY'!$C$15:$C$115,'TERM 3 SUMMARY'!$R$15:$R$115),"")) | P21: =IF(C21="","",IF(COUNT($F21:$M21)=0,"",SUM($F21:$M21)/3)) | S21: =IF(P21="","",_xlfn.RANK.AVG(P21,$P$15:$P$115))
B22: 8 | C22: =IF('INPUT DATA'!L18="","",'INPUT DATA'!L18) | F22: =IF(TRIM(C22)="","",IFERROR(_xlfn.XLOOKUP(TRIM(C22),'TERM 1 SUMMARY'!$C$15:$C$115,'TERM 1 SUMMARY'!$R$15:$R$115),"")) | J22: =IF(TRIM(C22)="","",IFERROR(_xlfn.XLOOKUP(TRIM(C22),'TERM 2 SUMMARY'!$C$15:$C$115,'TERM 2 SUMMARY'!$R$15:$R$115),"")) | M22: =IF(TRIM(C22)="","",IFERROR(_xlfn.XLOOKUP(TRIM(C22),'TERM 3 SUMMARY'!$C$15:$C$115,'TERM 3 SUMMARY'!$R$15:$R$115),"")) | P22: =IF(C22="","",IF(COUNT($F22:$M22)=0,"",SUM($F22:$M22)/3)) | S22: =IF(P22="","",_xlfn.RANK.AVG(P22,$P$15:$P$115))
B23: 9 | C23: =IF('INPUT DATA'!L19="","",'INPUT DATA'!L19) | F23: =IF(TRIM(C23)="","",IFERROR(_xlfn.XLOOKUP(TRIM(C23),'TERM 1 SUMMARY'!$C$15:$C$115,'TERM 1 SUMMARY'!$R$15:$R$115),"")) | J23: =IF(TRIM(C23)="","",IFERROR(_xlfn.XLOOKUP(TRIM(C23),'TERM 2 SUMMARY'!$C$15:$C$115,'TERM 2 SUMMARY'!$R$15:$R$115),"")) | M23: =IF(TRIM(C23)="","",IFERROR(_xlfn.XLOOKUP(TRIM(C23),'TERM 3 SUMMARY'!$C$15:$C$115,'TERM 3 SUMMARY'!$R$15:$R$115),"")) | P23: =IF(C23="","",IF(COUNT($F23:$M23)=0,"",SUM($F23:$M23)/3)) | S23: =IF(P23="","",_xlfn.RANK.AVG(P23,$P$15:$P$115))
B24: 10 | C24: =IF('INPUT DATA'!L20="","",'INPUT DATA'!L20) | F24: =IF(TRIM(C24)="","",IFERROR(_xlfn.XLOOKUP(TRIM(C24),'TERM 1 SUMMARY'!$C$15:$C$115,'TERM 1 SUMMARY'!$R$15:$R$115),"")) | J24: =IF(TRIM(C24)="","",IFERROR(_xlfn.XLOOKUP(TRIM(C24),'TERM 2 SUMMARY'!$C$15:$C$115,'TERM 2 SUMMARY'!$R$15:$R$115),"")) | M24: =IF(TRIM(C24)="","",IFERROR(_xlfn.XLOOKUP(TRIM(C24),'TERM 3 SUMMARY'!$C$15:$C$115,'TERM 3 SUMMARY'!$R$15:$R$115),"")) | P24: =IF(C24="","",IF(COUNT($F24:$M24)=0,"",SUM($F24:$M24)/3)) | S24: =IF(P24="","",_xlfn.RANK.AVG(P24,$P$15:$P$115))
B25: 11 | C25: =IF('INPUT DATA'!L21="","",'INPUT DATA'!L21) | F25: =IF(TRIM(C25)="","",IFERROR(_xlfn.XLOOKUP(TRIM(C25),'TERM 1 SUMMARY'!$C$15:$C$115,'TERM 1 SUMMARY'!$R$15:$R$115),"")) | J25: =IF(TRIM(C25)="","",IFERROR(_xlfn.XLOOKUP(TRIM(C25),'TERM 2 SUMMARY'!$C$15:$C$115,'TERM 2 SUMMARY'!$R$15:$R$115),"")) | M25: =IF(TRIM(C25)="","",IFERROR(_xlfn.XLOOKUP(TRIM(C25),'TERM 3 SUMMARY'!$C$15:$C$115,'TERM 3 SUMMARY'!$R$15:$R$115),"")) | P25: =IF(C25="","",IF(COUNT($F25:$M25)=0,"",SUM($F25:$M25)/3)) | S25: =IF(P25="","",_xlfn.RANK.AVG(P25,$P$15:$P$115))
B26: 12 | C26: =IF('INPUT DATA'!L22="","",'INPUT DATA'!L22) | F26: =IF(TRIM(C26)="","",IFERROR(_xlfn.XLOOKUP(TRIM(C26),'TERM 1 SUMMARY'!$C$15:$C$115,'TERM 1 SUMMARY'!$R$15:$R$115),"")) | J26: =IF(TRIM(C26)="","",IFERROR(_xlfn.XLOOKUP(TRIM(C26),'TERM 2 SUMMARY'!$C$15:$C$115,'TERM 2 SUMMARY'!$R$15:$R$115),"")) | M26: =IF(TRIM(C26)="","",IFERROR(_xlfn.XLOOKUP(TRIM(C26),'TERM 3 SUMMARY'!$C$15:$C$115,'TERM 3 SUMMARY'!$R$15:$R$115),"")) | P26: =IF(C26="","",IF(COUNT($F26:$M26)=0,"",SUM($F26:$M26)/3)) | S26: =IF(P26="","",_xlfn.RANK.AVG(P26,$P$15:$P$115))
... B64: 50 | C64: =IF('INPUT DATA'!L60="","",'INPUT DATA'!L60) | F64: =IF(TRIM(C64)="","",IFERROR(_xlfn.XLOOKUP(TRIM(C64),'TERM 1 SUMMARY'!$C$15:$C$115,'TERM 1 SUMMARY'!$R$15:$R$115),"")) | J64: =IF(TRIM(C64)="","",IFERROR(_xlfn.XLOOKUP(TRIM(C64),'TERM 2 SUMMARY'!$C$15:$C$115,'TERM 2 SUMMARY'!$R$15:$R$115),"")) | M64: =IF(TRIM(C64)="","",IFERROR(_xlfn.XLOOKUP(TRIM(C64),'TERM 3 SUMMARY'!$C$15:$C$115,'TERM 3 SUMMARY'!$R$15:$R$115),"")) | P64: =IF(C64="","",IF(COUNT($F64:$M64)=0,"",SUM($F64:$M64)/3)) | S64: =IF(P64="","",_xlfn.RANK.AVG(P64,$P$15:$P$115))
B65: FEMALE
B66: 1 | C66: =IF('INPUT DATA'!Q11="","",'INPUT DATA'!Q11) | F66: =IF(TRIM(C66)="","",IFERROR(_xlfn.XLOOKUP(TRIM(C66),'TERM 1 SUMMARY'!$C$66:$C$115,'TERM 1 SUMMARY'!$R$66:$R$115),"")) | J66: =IF(TRIM(C66)="","",IFERROR(_xlfn.XLOOKUP(TRIM(C66),'TERM 2 SUMMARY'!$C$66:$C$115,'TERM 2 SUMMARY'!$R$66:$R$115),"")) | M66: =IF(TRIM(C66)="","",IFERROR(_xlfn.XLOOKUP(TRIM(C66),'TERM 3 SUMMARY'!$C$66:$C$115,'TERM 3 SUMMARY'!$R$66:$R$115),"")) | P66: =IF(C66="","",IF(COUNT($F66:$M66)=0,"",SUM($F66:$M66)/3)) | S66: =IF(P66="","",_xlfn.RANK.AVG(P66,$P$15:$P$115))
B67: 2 | C67: =IF('INPUT DATA'!Q12="","",'INPUT DATA'!Q12) | F67: =IF(TRIM(C67)="","",IFERROR(_xlfn.XLOOKUP(TRIM(C67),'TERM 1 SUMMARY'!$C$66:$C$115,'TERM 1 SUMMARY'!$R$66:$R$115),"")) | J67: =IF(TRIM(C67)="","",IFERROR(_xlfn.XLOOKUP(TRIM(C67),'TERM 2 SUMMARY'!$C$66:$C$115,'TERM 2 SUMMARY'!$R$66:$R$115),"")) | M67: =IF(TRIM(C67)="","",IFERROR(_xlfn.XLOOKUP(TRIM(C67),'TERM 3 SUMMARY'!$C$66:$C$115,'TERM 3 SUMMARY'!$R$66:$R$115),"")) | P67: =IF(C67="","",IF(COUNT($F67:$M67)=0,"",SUM($F67:$M67)/3)) | S67: =IF(P67="","",_xlfn.RANK.AVG(P67,$P$15:$P$115))
B68: 3 | C68: =IF('INPUT DATA'!Q13="","",'INPUT DATA'!Q13) | F68: =IF(TRIM(C68)="","",IFERROR(_xlfn.XLOOKUP(TRIM(C68),'TERM 1 SUMMARY'!$C$66:$C$115,'TERM 1 SUMMARY'!$R$66:$R$115),"")) | J68: =IF(TRIM(C68)="","",IFERROR(_xlfn.XLOOKUP(TRIM(C68),'TERM 2 SUMMARY'!$C$66:$C$115,'TERM 2 SUMMARY'!$R$66:$R$115),"")) | M68: =IF(TRIM(C68)="","",IFERROR(_xlfn.XLOOKUP(TRIM(C68),'TERM 3 SUMMARY'!$C$66:$C$115,'TERM 3 SUMMARY'!$R$66:$R$115),"")) | P68: =IF(C68="","",IF(COUNT($F68:$M68)=0,"",SUM($F68:$M68)/3)) | S68: =IF(P68="","",_xlfn.RANK.AVG(P68,$P$15:$P$115))
B69: 4 | C69: =IF('INPUT DATA'!Q14="","",'INPUT DATA'!Q14) | F69: =IF(TRIM(C69)="","",IFERROR(_xlfn.XLOOKUP(TRIM(C69),'TERM 1 SUMMARY'!$C$66:$C$115,'TERM 1 SUMMARY'!$R$66:$R$115),"")) | J69: =IF(TRIM(C69)="","",IFERROR(_xlfn.XLOOKUP(TRIM(C69),'TERM 2 SUMMARY'!$C$66:$C$115,'TERM 2 SUMMARY'!$R$66:$R$115),"")) | M69: =IF(TRIM(C69)="","",IFERROR(_xlfn.XLOOKUP(TRIM(C69),'TERM 3 SUMMARY'!$C$66:$C$115,'TERM 3 SUMMARY'!$R$66:$R$115),"")) | P69: =IF(C69="","",IF(COUNT($F69:$M69)=0,"",SUM($F69:$M69)/3)) | S69: =IF(P69="","",_xlfn.RANK.AVG(P69,$P$15:$P$115))
B70: 5 | C70: =IF('INPUT DATA'!Q15="","",'INPUT DATA'!Q15) | F70: =IF(TRIM(C70)="","",IFERROR(_xlfn.XLOOKUP(TRIM(C70),'TERM 1 SUMMARY'!$C$66:$C$115,'TERM 1 SUMMARY'!$R$66:$R$115),"")) | J70: =IF(TRIM(C70)="","",IFERROR(_xlfn.XLOOKUP(TRIM(C70),'TERM 2 SUMMARY'!$C$66:$C$115,'TERM 2 SUMMARY'!$R$66:$R$115),"")) | M70: =IF(TRIM(C70)="","",IFERROR(_xlfn.XLOOKUP(TRIM(C70),'TERM 3 SUMMARY'!$C$66:$C$115,'TERM 3 SUMMARY'!$R$66:$R$115),"")) | P70: =IF(C70="","",IF(COUNT($F70:$M70)=0,"",SUM($F70:$M70)/3)) | S70: =IF(P70="","",_xlfn.RANK.AVG(P70,$P$15:$P$115))
B71: 6 | C71: =IF('INPUT DATA'!Q16="","",'INPUT DATA'!Q16) | F71: =IF(TRIM(C71)="","",IFERROR(_xlfn.XLOOKUP(TRIM(C71),'TERM 1 SUMMARY'!$C$66:$C$115,'TERM 1 SUMMARY'!$R$66:$R$115),"")) | J71: =IF(TRIM(C71)="","",IFERROR(_xlfn.XLOOKUP(TRIM(C71),'TERM 2 SUMMARY'!$C$66:$C$115,'TERM 2 SUMMARY'!$R$66:$R$115),"")) | M71: =IF(TRIM(C71)="","",IFERROR(_xlfn.XLOOKUP(TRIM(C71),'TERM 3 SUMMARY'!$C$66:$C$115,'TERM 3 SUMMARY'!$R$66:$R$115),"")) | P71: =IF(C71="","",IF(COUNT($F71:$M71)=0,"",SUM($F71:$M71)/3)) | S71: =IF(P71="","",_xlfn.RANK.AVG(P71,$P$15:$P$115))
B72: 7 | C72: =IF('INPUT DATA'!Q17="","",'INPUT DATA'!Q17) | F72: =IF(TRIM(C72)="","",IFERROR(_xlfn.XLOOKUP(TRIM(C72),'TERM 1 SUMMARY'!$C$66:$C$115,'TERM 1 SUMMARY'!$R$66:$R$115),"")) | J72: =IF(TRIM(C72)="","",IFERROR(_xlfn.XLOOKUP(TRIM(C72),'TERM 2 SUMMARY'!$C$66:$C$115,'TERM 2 SUMMARY'!$R$66:$R$115),"")) | M72: =IF(TRIM(C72)="","",IFERROR(_xlfn.XLOOKUP(TRIM(C72),'TERM 3 SUMMARY'!$C$66:$C$115,'TERM 3 SUMMARY'!$R$66:$R$115),"")) | P72: =IF(C72="","",IF(COUNT($F72:$M72)=0,"",SUM($F72:$M72)/3)) | S72: =IF(P72="","",_xlfn.RANK.AVG(P72,$P$15:$P$115))
B73: 8 | C73: =IF('INPUT DATA'!Q18="","",'INPUT DATA'!Q18) | F73: =IF(TRIM(C73)="","",IFERROR(_xlfn.XLOOKUP(TRIM(C73),'TERM 1 SUMMARY'!$C$66:$C$115,'TERM 1 SUMMARY'!$R$66:$R$115),"")) | J73: =IF(TRIM(C73)="","",IFERROR(_xlfn.XLOOKUP(TRIM(C73),'TERM 2 SUMMARY'!$C$66:$C$115,'TERM 2 SUMMARY'!$R$66:$R$115),"")) | M73: =IF(TRIM(C73)="","",IFERROR(_xlfn.XLOOKUP(TRIM(C73),'TERM 3 SUMMARY'!$C$66:$C$115,'TERM 3 SUMMARY'!$R$66:$R$115),"")) | P73: =IF(C73="","",IF(COUNT($F73:$M73)=0,"",SUM($F73:$M73)/3)) | S73: =IF(P73="","",_xlfn.RANK.AVG(P73,$P$15:$P$115))
B74: 9 | C74: =IF('INPUT DATA'!Q19="","",'INPUT DATA'!Q19) | F74: =IF(TRIM(C74)="","",IFERROR(_xlfn.XLOOKUP(TRIM(C74),'TERM 1 SUMMARY'!$C$66:$C$115,'TERM 1 SUMMARY'!$R$66:$R$115),"")) | J74: =IF(TRIM(C74)="","",IFERROR(_xlfn.XLOOKUP(TRIM(C74),'TERM 2 SUMMARY'!$C$66:$C$115,'TERM 2 SUMMARY'!$R$66:$R$115),"")) | M74: =IF(TRIM(C74)="","",IFERROR(_xlfn.XLOOKUP(TRIM(C74),'TERM 3 SUMMARY'!$C$66:$C$115,'TERM 3 SUMMARY'!$R$66:$R$115),"")) | P74: =IF(C74="","",IF(COUNT($F74:$M74)=0,"",SUM($F74:$M74)/3)) | S74: =IF(P74="","",_xlfn.RANK.AVG(P74,$P$15:$P$115))
B75: 10 | C75: =IF('INPUT DATA'!Q20="","",'INPUT DATA'!Q20) | F75: =IF(TRIM(C75)="","",IFERROR(_xlfn.XLOOKUP(TRIM(C75),'TERM 1 SUMMARY'!$C$66:$C$115,'TERM 1 SUMMARY'!$R$66:$R$115),"")) | J75: =IF(TRIM(C75)="","",IFERROR(_xlfn.XLOOKUP(TRIM(C75),'TERM 2 SUMMARY'!$C$66:$C$115,'TERM 2 SUMMARY'!$R$66:$R$115),"")) | M75: =IF(TRIM(C75)="","",IFERROR(_xlfn.XLOOKUP(TRIM(C75),'TERM 3 SUMMARY'!$C$66:$C$115,'TERM 3 SUMMARY'!$R$66:$R$115),"")) | P75: =IF(C75="","",IF(COUNT($F75:$M75)=0,"",SUM($F75:$M75)/3)) | S75: =IF(P75="","",_xlfn.RANK.AVG(P75,$P$15:$P$115))
B76: 11 | C76: =IF('INPUT DATA'!Q21="","",'INPUT DATA'!Q21) | F76: =IF(TRIM(C76)="","",IFERROR(_xlfn.XLOOKUP(TRIM(C76),'TERM 1 SUMMARY'!$C$66:$C$115,'TERM 1 SUMMARY'!$R$66:$R$115),"")) | J76: =IF(TRIM(C76)="","",IFERROR(_xlfn.XLOOKUP(TRIM(C76),'TERM 2 SUMMARY'!$C$66:$C$115,'TERM 2 SUMMARY'!$R$66:$R$115),"")) | M76: =IF(TRIM(C76)="","",IFERROR(_xlfn.XLOOKUP(TRIM(C76),'TERM 3 SUMMARY'!$C$66:$C$115,'TERM 3 SUMMARY'!$R$66:$R$115),"")) | P76: =IF(C76="","",IF(COUNT($F76:$M76)=0,"",SUM($F76:$M76)/3)) | S76: =IF(P76="","",_xlfn.RANK.AVG(P76,$P$15:$P$115))
B77: 12 | C77: =IF('INPUT DATA'!Q22="","",'INPUT DATA'!Q22) | F77: =IF(TRIM(C77)="","",IFERROR(_xlfn.XLOOKUP(TRIM(C77),'TERM 1 SUMMARY'!$C$66:$C$115,'TERM 1 SUMMARY'!$R$66:$R$115),"")) | J77: =IF(TRIM(C77)="","",IFERROR(_xlfn.XLOOKUP(TRIM(C77),'TERM 2 SUMMARY'!$C$66:$C$115,'TERM 2 SUMMARY'!$R$66:$R$115),"")) | M77: =IF(TRIM(C77)="","",IFERROR(_xlfn.XLOOKUP(TRIM(C77),'TERM 3 SUMMARY'!$C$66:$C$115,'TERM 3 SUMMARY'!$R$66:$R$115),"")) | P77: =IF(C77="","",IF(COUNT($F77:$M77)=0,"",SUM($F77:$M77)/3)) | S77: =IF(P77="","",_xlfn.RANK.AVG(P77,$P$15:$P$115))
... B115: 50 | C115: =IF('INPUT DATA'!Q60="","",'INPUT DATA'!Q60) | F115: =IF(TRIM(C115)="","",IFERROR(_xlfn.XLOOKUP(TRIM(C115),'TERM 1 SUMMARY'!$C$66:$C$115,'TERM 1 SUMMARY'!$R$66:$R$115),"")) | J115: =IF(TRIM(C115)="","",IFERROR(_xlfn.XLOOKUP(TRIM(C115),'TERM 2 SUMMARY'!$C$66:$C$115,'TERM 2 SUMMARY'!$R$66:$R$115),"")) | M115: =IF(TRIM(C115)="","",IFERROR(_xlfn.XLOOKUP(TRIM(C115),'TERM 3 SUMMARY'!$C$66:$C$115,'TERM 3 SUMMARY'!$R$66:$R$115),"")) | P115: =IF(C115="","",IF(COUNT($F115:$M115)=0,"",SUM($F115:$M115)/3)) | S115: =IF(P115="","",_xlfn.RANK.AVG(P115,$P$15:$P$115))

Sheet ATTENDANCE RECORD SUMMARY
A1: ATTENDANCE RECORD
D5: REGION | E5: ='INPUT DATA'!F10 -> 0 | H5: DIVISION | I5: ='INPUT DATA'!F11 -> 0
D7: SCHOOL NAME | E7: ='INPUT DATA'!F16 -> 0 | H7: SCHOOL ID | I7: ='INPUT DATA'!F15 -> 0 | L7: SCHOOL YEAR | N7: ='INPUT DATA'!F18 -> 0
B10: LEARNERS' NAMES | F10: GRADE LEVEL | G10: ='INPUT DATA'!F27 -> 0 | K10: ADVISER | L10: ='INPUT DATA'!F26 -> 0
F11: SECTION | G11: ='INPUT DATA'!F28 -> 0
F12: JUN | G12: JUL | H12: AUG | I12: SEP | J12: OCT | K12: NOV | L12: DEC | M12: JAN | N12: FEB | O12: MAR | P12: APRIL
B13: MALE
B14: 1 | C14: =IF('INPUT DATA'!L11="","",'INPUT DATA'!L11)
B15: 2 | C15: =IF('INPUT DATA'!L12="","",'INPUT DATA'!L12)
B16: 3 | C16: =IF('INPUT DATA'!L13="","",'INPUT DATA'!L13)
B17: 4 | C17: =IF('INPUT DATA'!L14="","",'INPUT DATA'!L14)
B18: 5 | C18: =IF('INPUT DATA'!L15="","",'INPUT DATA'!L15)
B19: 6 | C19: =IF('INPUT DATA'!L16="","",'INPUT DATA'!L16)
B20: 7 | C20: =IF('INPUT DATA'!L17="","",'INPUT DATA'!L17)
B21: 8 | C21: =IF('INPUT DATA'!L18="","",'INPUT DATA'!L18)
B22: 9 | C22: =IF('INPUT DATA'!L19="","",'INPUT DATA'!L19)
B23: 10 | C23: =IF('INPUT DATA'!L20="","",'INPUT DATA'!L20)
B24: 11 | C24: =IF('INPUT DATA'!L21="","",'INPUT DATA'!L21)
B25: 12 | C25: =IF('INPUT DATA'!L22="","",'INPUT DATA'!L22)
... B63: 50 | C63: =IF('INPUT DATA'!L60="","",'INPUT DATA'!L60)
B64: FEMALE
B65: 1 | C65: =IF('INPUT DATA'!Q11="","",'INPUT DATA'!Q11)
B66: 2 | C66: =IF('INPUT DATA'!Q12="","",'INPUT DATA'!Q12)
B67: 3 | C67: =IF('INPUT DATA'!Q13="","",'INPUT DATA'!Q13)
B68: 4 | C68: =IF('INPUT DATA'!Q14="","",'INPUT DATA'!Q14)
B69: 5 | C69: =IF('INPUT DATA'!Q15="","",'INPUT DATA'!Q15)
B70: 6 | C70: =IF('INPUT DATA'!Q16="","",'INPUT DATA'!Q16)
B71: 7 | C71: =IF('INPUT DATA'!Q17="","",'INPUT DATA'!Q17)
B72: 8 | C72: =IF('INPUT DATA'!Q18="","",'INPUT DATA'!Q18)
B73: 9 | C73: =IF('INPUT DATA'!Q19="","",'INPUT DATA'!Q19)
B74: 10 | C74: =IF('INPUT DATA'!Q20="","",'INPUT DATA'!Q20)
B75: 11 | C75: =IF('INPUT DATA'!Q21="","",'INPUT DATA'!Q21)
B76: 12 | C76: =IF('INPUT DATA'!Q22="","",'INPUT DATA'!Q22)
... B114: 50 | C114: =IF('INPUT DATA'!Q60="","",'INPUT DATA'!Q60)
B116: TOTAL NUMBER OF SCHOOL DAYS | E116: TOTAL | F116: JUN | G116: JUL | H116: AUG | I116: SEP | J116: OCT | K116: NOV | L116: DEC | M116: JAN | N116: FEB | O116: MAR | P116: APR
E117: =SUM(F117:P117) -> 201 | F117: 20 | G117: 20 | H117: 20 | I117: 20 | J117: 20 | K117: 20 | L117: 20 | M117: 18 | N117: 18 | O117: 20 | P117: 5

Sheet SF9 - GRADE 11 TechPro
B4: Republic of the Philippines | Q4: Month | R4: Jun | S4: Jul | T4: Aug | U4: Sep | V4: Oct | W4: Nov | X4: Dec | Y4: Jan | Z4: Feb | AA4: Mar | AB4: Apr | AC4: Total
B5: Department of Education | Q5: No. of Class Days | AC5: =SUM(R5:AB6) -> 0
B7: =#REF! -> #REF! | Q7: No. of Days Present | AC7: =SUM(R7:AB8) -> 0
B8: =#REF! -> #REF!
B9: Sta. Maria District | Q9: No. of Days Absent | R9: =ABS(R5-R7) -> 0 | S9: =ABS(S5-S7) -> 0 | T9: =ABS(T5-T7) -> 0 | U9: =ABS(U5-U7) -> 0 | V9: =ABS(V5-V7) -> 0 | W9: =ABS(W5-W7) -> 0 | X9: =ABS(X5-X7) -> 0 | Y9: =ABS(Y5-Y7) -> 0 | ... AC9: =ABS(AC5-AC7) -> 0
B10: =#REF! -> #REF!
B12: ABC ELEMENTARY SCHOOL
B14: LEARNER'S PERFORMANCE REPORT | Q14: TEACHER'S COMMENTS / REMARKS
B15: School Year 2026-2027 | Q15: Term 1
B17: Name: | H17: Age: | I17: =VLOOKUP(C17,'TERM 1 SUMMARY'!C15:R115,7,0) -> #N/A | J17: Sex: | K17: =VLOOKUP(C17,'TERM 1 SUMMARY'!C15:R115,8,0) -> #N/A
B18: LRN: | C18: =VLOOKUP(C17,'TERM 1 SUMMARY'!C15:R115,4,0) -> #N/A | H18: Grade: | I18: ='TERM 1 SUMMARY'!G9 -> 0 | J18: Section: | K18: ='TERM 1 SUMMARY'!G10 -> 0
B19: Track (SHS only): | E19: ='INPUT DATA'!F28 -> 0 | Q19: Term 2
B21: Dear Parents,
C22: This Performance Report presents your child's progress and achievement
B23: in the different learning areas. | Q23: Term 3
C24: The school welcomes you to reach out should you wish to know more about your
B25: child's learning and performance.
B27: ='INPUT DATA'!F19 -> 0 | H27: ='INPUT DATA'!F26 -> 0
B28: School Head | H28: Adviser | Q28: PARENT/S GUARDIAN'S SIGNATURE
B29: LEARNING PROGRESS AND ACHIEVEMENT | R29: Term 1
B30: Learning Areas | F30: TERM | I30: Final Grade | J30: Remarks | R30: Term 2
F31: T1 | G31: T2 | H31: T3 | R31: Term 3
B32: Core Subjects
B33: Effective Communication /Mabisang Komunikasyon | Q33: CERTIFICATE OF TRANSFER
B34: Effective Communication | F34: =IF('TERM 1 SUMMARY'!R15="","",VLOOKUP(C17,'TERM 1 SUMMARY'!C15:R115,9,0)) | G34: =IF('TERM 2 SUMMARY'!R15="","",VLOOKUP(C17,'TERM 2 SUMMARY'!C15:R115,9,0)) | H34: =IF('TERM 3 SUMMARY'!R15="","",VLOOKUP(C17,'TERM 3 SUMMARY'!C15:R115,9,0)) | Q34: This is to certify that the above-named learner has satisfactorily completed the requirements
B35: Mabisang Komunikasyon | F35: =IF('TERM 1 SUMMARY'!R15="","",VLOOKUP(C17,'TERM 1 SUMMARY'!C15:R115,10,0)) | G35: =IF('TERM 2 SUMMARY'!R15="","",VLOOKUP(C17,'TERM 2 SUMMARY'!C15:R115,10,0)) | H35: =IF('TERM 3 SUMMARY'!R15="","",VLOOKUP(C17,'TERM 3 SUMMARY'!C15:R115,10,0)) | Q35: for the grade level indicated. | AE35: =IF(COUNT(F31:H31)=0,"",ROUND((F31+G31+H31)/3,0))
B36: General Mathematics | F36: =IF('TERM 1 SUMMARY'!R15="","",VLOOKUP(C17,'TERM 1 SUMMARY'!C15:R115,11,0)) | G36: =IF('TERM 2 SUMMARY'!R15="","",VLOOKUP(C17,'TERM 2 SUMMARY'!C15:R115,11,0)) | H36: =IF('TERM 3 SUMMARY'!R15="","",VLOOKUP(C17,'TERM 3 SUMMARY'!C15:R115,11,0))
B37: General Science | F37: =IF('TERM 1 SUMMARY'!R15="","",VLOOKUP(C17,'TERM 1 SUMMARY'!C15:R115,12,0)) | G37: =IF('TERM 2 SUMMARY'!R15="","",VLOOKUP(C17,'TERM 2 SUMMARY'!C15:R115,12,0)) | H37: =IF('TERM 3 SUMMARY'!R15="","",VLOOKUP(C17,'TERM 3 SUMMARY'!C15:R115,12,0)) | Q37: Admitted to Grade:
B38: Life and Career Skills | F38: =IF('TERM 1 SUMMARY'!R15="","",VLOOKUP(C17,'TERM 1 SUMMARY'!C15:R115,13,0)) | G38: =IF('TERM 2 SUMMARY'!R15="","",VLOOKUP(C17,'TERM 2 SUMMARY'!C15:R115,13,0)) | H38: =IF('TERM 3 SUMMARY'!R15="","",VLOOKUP(C17,'TERM 3 SUMMARY'!C15:R115,13,0)) | Q38: Eligible for Admission to Grade:
B39: Pag-Aaral ng Kasanayan at Lipunang Pilipino | F39: =IF('TERM 1 SUMMARY'!R15="","",VLOOKUP(C17,'TERM 1 SUMMARY'!C15:R115,14,0)) | G39: =IF('TERM 2 SUMMARY'!R15="","",VLOOKUP(C17,'TERM 2 SUMMARY'!C15:R115,14,0)) | H39: =IF('TERM 3 SUMMARY'!R15="","",VLOOKUP(C17,'TERM 3 SUMMARY'!C15:R115,14,0)) | X39: ='INPUT DATA'!F26 -> 0
B40: Elective Subjects | Q40: Approved: | X40: Adviser
B41: TechPro Elective 1 | F41: =IF('TERM 1 SUMMARY'!R15="","",VLOOKUP(C17,'TERM 1 SUMMARY'!C15:R115,15,0)) | G41: =IF('TERM 2 SUMMARY'!R15="","",VLOOKUP(C17,'TERM 2 SUMMARY'!C15:R115,15,0)) | H41: =IF('TERM 3 SUMMARY'!R15="","",VLOOKUP(C17,'TERM 3 SUMMARY'!C15:R115,15,0)) | Q41: ='INPUT DATA'!F19 -> 0
B43: General Average | Q43: School Head
Q45: CANCELLATION OF ELIGIBILITY TO TRANSFER
B46: PERFORMANCE DESCRIPTORS
C47: Grading Scale | F47: Descriptors | I47: Remarks | Q47: Admitted in: | X47: Date:
C48: 90-100 | F48: Advancing | I48: Passed
C49: 80-89 | F49: Benchmarking | I49: Passed
C50: 75-79 | F50: Connecting | I50: Passed | Q50: ='INPUT DATA'!F19 -> 0
C51: 65-74 | F51: Developing | I51: Failed | Q51: School Head
...
