Workbook

Sheet Home

Sheet INPUT DATA
A1: Input Data Sheet for Electronic-Class Record (ECR) for Class Adviser
B7: SCHOOL INFORMATION | J7: LEARNERS' DATA
C10: REGION | E10: : | K10: MALE | M10: LRN | N10: BIRTHDATE | P10: FEMALE | R10: LRN | S10: BIRTHDATE
C11: DIVISION | E11: : | K11: 1 | P11: 1
C12: CITY/MUNICIPALITY | E12: : | K12: 2 | P12: 2
C13: DISTRICT | E13: : | K13: 3 | P13: 3
K14: 4 | P14: 4
C15: SCHOOL ID | E15: : | K15: 5 | P15: 5
C16: SCHOOL NAME | E16: : | K16: 6 | P16: 6
K17: 7 | P17: 7
C18: SCHOOL YEAR | E18: : | K18: 8 | P18: 8
C19: SCHOOL HEAD | E19: : | K19: 9 | P19: 9
K20: 10 | P20: 10
K21: 11 | P21: 11
K22: 12 | P22: 12
B23: TEACHER, GRADE LEVEL, SECTION INFORMATION | K23: 13 | P23: 13
K24: 14 | P24: 14
K25: 15 | P25: 15
C26: ADVISER | E26: : | K26: 16 | P26: 16
C27: GRADE LEVEL | E27: : | G27: (Accepts Grades 4 to 6 only) | K27: 17 | P27: 17
C28: SECTION | E28: : | K28: 18 | P28: 18
K29: 19 | P29: 19
C30: IMPORTANT NOTE: This is the official and final version of the file. All tabs are password-protected to prevent accidental formula edits and maintain the accuracy and integrity of the data. If you identify any inconsistencies or issues, particularly with the formulas, please report them for appropriate review and necessary correction. | K30: 20 | P30: 20
K31: 21 | P31: 21
K32: 22 | P32: 22
K33: 23 | P33: 23
K34: 24 | P34: 24
K35: 25 | P35: 25
B36: Sheet Protection Password: password123 | K36: 26 | P36: 26
K37: 27 | P37: 27
K38: 28 | P38: 28
K39: 29 | P39: 29
K40: 30 | P40: 30
K41: 31 | P41: 31
K42: 32 | P42: 32
K43: 33 | P43: 33
K44: 34 | P44: 34
K45: 35 | P45: 35
K46: 36 | P46: 36
K47: 37 | P47: 37
...

Sheet TERM 1 SUMMARY
A1: CLASS SUMMARY
D5: REGION | E5: =IF('INPUT DATA'!F10="","",'INPUT DATA'!F10) | I5: DIVISION | K5: =IF('INPUT DATA'!F11="","",'INPUT DATA'!F11)
D6: SCHOOL NAME | E6: =IF('INPUT DATA'!F16="","",'INPUT DATA'!F16) | I6: SCHOOL ID | K6: =IF('INPUT DATA'!F155="","",'INPUT DATA'!F15) | S6: SCHOOL YEAR | U6: =IF('INPUT DATA'!F18="","",'INPUT DATA'!F18)
B9: FIRST TERM | F9: GRADE LEVEL | G9: =IF('INPUT DATA'!F27="","",'INPUT DATA'!F27) | L9: ADVISER | N9: =IF('INPUT DATA'!F26="","",'INPUT DATA'!F26)
F10: SECTION | G10: =IF('INPUT DATA'!F28="","",'INPUT DATA'!F28)
B11: LEARNERS' NAMES | F11: LRN | H11: Date of Birth | I11: Age | J11: Sex | K11: Learning Areas | U11: Final Grade | V11: Rank
K12: Filipino | L12: English | M12: Enhanced Mathematics | N12: Enhanced Science | O12: AP | P12: GMRC/VE | Q12: EPP/TLE | R12: MAPEH
R13: M A | S13: P E H | T13: Term Grade
B15: 1 | C15: =IF('INPUT DATA'!L11="","",'INPUT DATA'!L11) | F15: =IF('INPUT DATA'!M11="","",'INPUT DATA'!M11) | H15: =IF('INPUT DATA'!N11="","",'INPUT DATA'!N11) | I15: =IF(H15="","",DATEDIF(H15,TODAY(),"Y")) | T15: =IF(COUNT($R15:$S15)=0,"",ROUND(AVERAGE(R15:S15),0)) | U15: =IF(COUNT(K15:Q15,T15)=0,"",ROUND(AVERAGE(K15:Q15,T15),0)) | V15: =IF(U15="","",_xlfn.RANK.AVG(U15,$U$15:$U$115))
B16: 2 | C16: =IF('INPUT DATA'!L12="","",'INPUT DATA'!L12) | F16: =IF('INPUT DATA'!M12="","",'INPUT DATA'!M12) | H16: =IF('INPUT DATA'!N12="","",'INPUT DATA'!N12) | I16: =IF(H16="","",DATEDIF(H16,TODAY(),"Y")) | T16: =IF(COUNT($R16:$S16)=0,"",ROUND(AVERAGE(R16:S16),0)) | U16: =IF(COUNT(K16:Q16,T16)=0,"",ROUND(AVERAGE(K16:Q16,T16),0)) | V16: =IF(U16="","",_xlfn.RANK.AVG(U16,$U$15:$U$115))
B17: 3 | C17: =IF('INPUT DATA'!L13="","",'INPUT DATA'!L13) | F17: =IF('INPUT DATA'!M13="","",'INPUT DATA'!M13) | H17: =IF('INPUT DATA'!N13="","",'INPUT DATA'!N13) | I17: =IF(H17="","",DATEDIF(H17,TODAY(),"Y")) | T17: =IF(COUNT($R17:$S17)=0,"",ROUND(AVERAGE(R17:S17),0)) | U17: =IF(COUNT(K17:Q17,T17)=0,"",ROUND(AVERAGE(K17:Q17,T17),0)) | V17: =IF(U17="","",_xlfn.RANK.AVG(U17,$U$15:$U$115))
B18: 4 | C18: =IF('INPUT DATA'!L14="","",'INPUT DATA'!L14) | F18: =IF('INPUT DATA'!M14="","",'INPUT DATA'!M14) | H18: =IF('INPUT DATA'!N14="","",'INPUT DATA'!N14) | I18: =IF(H18="","",DATEDIF(H18,TODAY(),"Y")) | T18: =IF(COUNT($R18:$S18)=0,"",ROUND(AVERAGE(R18:S18),0)) | U18: =IF(COUNT(K18:Q18,T18)=0,"",ROUND(AVERAGE(K18:Q18,T18),0)) | V18: =IF(U18="","",_xlfn.RANK.AVG(U18,$U$15:$U$115))
B19: 5 | C19: =IF('INPUT DATA'!L15="","",'INPUT DATA'!L15) | F19: =IF('INPUT DATA'!M15="","",'INPUT DATA'!M15) | H19: =IF('INPUT DATA'!N15="","",'INPUT DATA'!N15) | I19: =IF(H19="","",DATEDIF(H19,TODAY(),"Y")) | T19: =IF(COUNT($R19:$S19)=0,"",ROUND(AVERAGE(R19:S19),0)) | U19: =IF(COUNT(K19:Q19,T19)=0,"",ROUND(AVERAGE(K19:Q19,T19),0)) | V19: =IF(U19="","",_xlfn.RANK.AVG(U19,$U$15:$U$115))
B20: 6 | C20: =IF('INPUT DATA'!L16="","",'INPUT DATA'!L16) | F20: =IF('INPUT DATA'!M16="","",'INPUT DATA'!M16) | H20: =IF('INPUT DATA'!N16="","",'INPUT DATA'!N16) | I20: =IF(H20="","",DATEDIF(H20,TODAY(),"Y")) | T20: =IF(COUNT($R20:$S20)=0,"",ROUND(AVERAGE(R20:S20),0)) | U20: =IF(COUNT(K20:Q20,T20)=0,"",ROUND(AVERAGE(K20:Q20,T20),0)) | V20: =IF(U20="","",_xlfn.RANK.AVG(U20,$U$15:$U$115))
B21: 7 | C21: =IF('INPUT DATA'!L17="","",'INPUT DATA'!L17) | F21: =IF('INPUT DATA'!M17="","",'INPUT DATA'!M17) | H21: =IF('INPUT DATA'!N17="","",'INPUT DATA'!N17) | I21: =IF(H21="","",DATEDIF(H21,TODAY(),"Y")) | T21: =IF(COUNT($R21:$S21)=0,"",ROUND(AVERAGE(R21:S21),0)) | U21: =IF(COUNT(K21:Q21,T21)=0,"",ROUND(AVERAGE(K21:Q21,T21),0)) | V21: =IF(U21="","",_xlfn.RANK.AVG(U21,$U$15:$U$115))
B22: 8 | C22: =IF('INPUT DATA'!L18="","",'INPUT DATA'!L18) | F22: =IF('INPUT DATA'!M18="","",'INPUT DATA'!M18) | H22: =IF('INPUT DATA'!N18="","",'INPUT DATA'!N18) | I22: =IF(H22="","",DATEDIF(H22,TODAY(),"Y")) | T22: =IF(COUNT($R22:$S22)=0,"",ROUND(AVERAGE(R22:S22),0)) | U22: =IF(COUNT(K22:Q22,T22)=0,"",ROUND(AVERAGE(K22:Q22,T22),0)) | V22: =IF(U22="","",_xlfn.RANK.AVG(U22,$U$15:$U$115))
B23: 9 | C23: =IF('INPUT DATA'!L19="","",'INPUT DATA'!L19) | F23: =IF('INPUT DATA'!M19="","",'INPUT DATA'!M19) | H23: =IF('INPUT DATA'!N19="","",'INPUT DATA'!N19) | I23: =IF(H23="","",DATEDIF(H23,TODAY(),"Y")) | T23: =IF(COUNT($R23:$S23)=0,"",ROUND(AVERAGE(R23:S23),0)) | U23: =IF(COUNT(K23:Q23,T23)=0,"",ROUND(AVERAGE(K23:Q23,T23),0)) | V23: =IF(U23="","",_xlfn.RANK.AVG(U23,$U$15:$U$115))
B24: 10 | C24: =IF('INPUT DATA'!L20="","",'INPUT DATA'!L20) | F24: =IF('INPUT DATA'!M20="","",'INPUT DATA'!M20) | H24: =IF('INPUT DATA'!N20="","",'INPUT DATA'!N20) | I24: =IF(H24="","",DATEDIF(H24,TODAY(),"Y")) | T24: =IF(COUNT($R24:$S24)=0,"",ROUND(AVERAGE(R24:S24),0)) | U24: =IF(COUNT(K24:Q24,T24)=0,"",ROUND(AVERAGE(K24:Q24,T24),0)) | V24: =IF(U24="","",_xlfn.RANK.AVG(U24,$U$15:$U$115))
B25: 11 | C25: =IF('INPUT DATA'!L21="","",'INPUT DATA'!L21) | F25: =IF('INPUT DATA'!M21="","",'INPUT DATA'!M21) | H25: =IF('INPUT DATA'!N21="","",'INPUT DATA'!N21) | I25: =IF(H25="","",DATEDIF(H25,TODAY(),"Y")) | T25: =IF(COUNT($R25:$S25)=0,"",ROUND(AVERAGE(R25:S25),0)) | U25: =IF(COUNT(K25:Q25,T25)=0,"",ROUND(AVERAGE(K25:Q25,T25),0)) | V25: =IF(U25="","",_xlfn.RANK.AVG(U25,$U$15:$U$115))
B26: 12 | C26: =IF('INPUT DATA'!L22="","",'INPUT DATA'!L22) | F26: =IF('INPUT DATA'!M22="","",'INPUT DATA'!M22) | H26: =IF('INPUT DATA'!N22="","",'INPUT DATA'!N22) | I26: =IF(H26="","",DATEDIF(H26,TODAY(),"Y")) | T26: =IF(COUNT($R26:$S26)=0,"",ROUND(AVERAGE(R26:S26),0)) | U26: =IF(COUNT(K26:Q26,T26)=0,"",ROUND(AVERAGE(K26:Q26,T26),0)) | V26: =IF(U26="","",_xlfn.RANK.AVG(U26,$U$15:$U$115))
... B64: 50 | C64: =IF('INPUT DATA'!L60="","",'INPUT DATA'!L60) | F64: =IF('INPUT DATA'!M60="","",'INPUT DATA'!M60) | H64: =IF('INPUT DATA'!N60="","",'INPUT DATA'!N60) | I64: =IF(H64="","",DATEDIF(H64,TODAY(),"Y")) | T64: =IF(COUNT($R64:$S64)=0,"",ROUND(AVERAGE(R64:S64),0)) | U64: =IF(COUNT(K64:Q64,T64)=0,"",ROUND(AVERAGE(K64:Q64,T64),0)) | V64: =IF(U64="","",_xlfn.RANK.AVG(U64,$U$15:$U$115))
B65: FEMALE
B66: 1 | C66: =IF('INPUT DATA'!Q11="","",'INPUT DATA'!Q11) | F66: =IF('INPUT DATA'!R11="","",'INPUT DATA'!R11) | H66: =IF('INPUT DATA'!S11="","",'INPUT DATA'!S11) | I66: =IF(H66="","",DATEDIF(H66,TODAY(),"Y")) | U66: =IF(COUNT(K66:Q66,T66)=0,"",ROUND(AVERAGE(K66:Q66,T66),0)) | V66: =IF(U66="","",_xlfn.RANK.AVG(U66,$U$15:$U$115))
B67: 2 | C67: =IF('INPUT DATA'!Q12="","",'INPUT DATA'!Q12) | F67: =IF('INPUT DATA'!R12="","",'INPUT DATA'!R12) | H67: =IF('INPUT DATA'!S12="","",'INPUT DATA'!S12) | I67: =IF(H67="","",DATEDIF(H67,TODAY(),"Y")) | U67: =IF(COUNT(K67:Q67,T67)=0,"",ROUND(AVERAGE(K67:Q67,T67),0)) | V67: =IF(U67="","",_xlfn.RANK.AVG(U67,$U$15:$U$115))
B68: 3 | C68: =IF('INPUT DATA'!Q13="","",'INPUT DATA'!Q13) | F68: =IF('INPUT DATA'!R13="","",'INPUT DATA'!R13) | H68: =IF('INPUT DATA'!S13="","",'INPUT DATA'!S13) | I68: =IF(H68="","",DATEDIF(H68,TODAY(),"Y")) | U68: =IF(COUNT(K68:Q68,T68)=0,"",ROUND(AVERAGE(K68:Q68,T68),0)) | V68: =IF(U68="","",_xlfn.RANK.AVG(U68,$U$15:$U$115))
B69: 4 | C69: =IF('INPUT DATA'!Q14="","",'INPUT DATA'!Q14) | F69: =IF('INPUT DATA'!R14="","",'INPUT DATA'!R14) | H69: =IF('INPUT DATA'!S14="","",'INPUT DATA'!S14) | I69: =IF(H69="","",DATEDIF(H69,TODAY(),"Y")) | U69: =IF(COUNT(K69:Q69,T69)=0,"",ROUND(AVERAGE(K69:Q69,T69),0)) | V69: =IF(U69="","",_xlfn.RANK.AVG(U69,$U$15:$U$115))
B70: 5 | C70: =IF('INPUT DATA'!Q15="","",'INPUT DATA'!Q15) | F70: =IF('INPUT DATA'!R15="","",'INPUT DATA'!R15) | H70: =IF('INPUT DATA'!S15="","",'INPUT DATA'!S15) | I70: =IF(H70="","",DATEDIF(H70,TODAY(),"Y")) | U70: =IF(COUNT(K70:Q70,T70)=0,"",ROUND(AVERAGE(K70:Q70,T70),0)) | V70: =IF(U70="","",_xlfn.RANK.AVG(U70,$U$15:$U$115))
B71: 6 | C71: =IF('INPUT DATA'!Q16="","",'INPUT DATA'!Q16) | F71: =IF('INPUT DATA'!R16="","",'INPUT DATA'!R16) | H71: =IF('INPUT DATA'!S16="","",'INPUT DATA'!S16) | I71: =IF(H71="","",DATEDIF(H71,TODAY(),"Y")) | U71: =IF(COUNT(K71:Q71,T71)=0,"",ROUND(AVERAGE(K71:Q71,T71),0)) | V71: =IF(U71="","",_xlfn.RANK.AVG(U71,$U$15:$U$115))
B72: 7 | C72: =IF('INPUT DATA'!Q17="","",'INPUT DATA'!Q17) | F72: =IF('INPUT DATA'!R17="","",'INPUT DATA'!R17) | H72: =IF('INPUT DATA'!S17="","",'INPUT DATA'!S17) | I72: =IF(H72="","",DATEDIF(H72,TODAY(),"Y")) | U72: =IF(COUNT(K72:Q72,T72)=0,"",ROUND(AVERAGE(K72:Q72,T72),0)) | V72: =IF(U72="","",_xlfn.RANK.AVG(U72,$U$15:$U$115))
B73: 8 | C73: =IF('INPUT DATA'!Q18="","",'INPUT DATA'!Q18) | F73: =IF('INPUT DATA'!R18="","",'INPUT DATA'!R18) | H73: =IF('INPUT DATA'!S18="","",'INPUT DATA'!S18) | I73: =IF(H73="","",DATEDIF(H73,TODAY(),"Y")) | U73: =IF(COUNT(K73:Q73,T73)=0,"",ROUND(AVERAGE(K73:Q73,T73),0)) | V73: =IF(U73="","",_xlfn.RANK.AVG(U73,$U$15:$U$115))
B74: 9 | C74: =IF('INPUT DATA'!Q19="","",'INPUT DATA'!Q19) | F74: =IF('INPUT DATA'!R19="","",'INPUT DATA'!R19) | H74: =IF('INPUT DATA'!S19="","",'INPUT DATA'!S19) | I74: =IF(H74="","",DATEDIF(H74,TODAY(),"Y")) | U74: =IF(COUNT(K74:Q74,T74)=0,"",ROUND(AVERAGE(K74:Q74,T74),0)) | V74: =IF(U74="","",_xlfn.RANK.AVG(U74,$U$15:$U$115))
B75: 10 | C75: =IF('INPUT DATA'!Q20="","",'INPUT DATA'!Q20) | F75: =IF('INPUT DATA'!R20="","",'INPUT DATA'!R20) | H75: =IF('INPUT DATA'!S20="","",'INPUT DATA'!S20) | I75: =IF(H75="","",DATEDIF(H75,TODAY(),"Y")) | U75: =IF(COUNT(K75:Q75,T75)=0,"",ROUND(AVERAGE(K75:Q75,T75),0)) | V75: =IF(U75="","",_xlfn.RANK.AVG(U75,$U$15:$U$115))
B76: 11 | C76: =IF('INPUT DATA'!Q21="","",'INPUT DATA'!Q21) | F76: =IF('INPUT DATA'!R21="","",'INPUT DATA'!R21) | H76: =IF('INPUT DATA'!S21="","",'INPUT DATA'!S21) | I76: =IF(H76="","",DATEDIF(H76,TODAY(),"Y")) | U76: =IF(COUNT(K76:Q76,T76)=0,"",ROUND(AVERAGE(K76:Q76,T76),0)) | V76: =IF(U76="","",_xlfn.RANK.AVG(U76,$U$15:$U$115))
B77: 12 | C77: =IF('INPUT DATA'!Q22="","",'INPUT DATA'!Q22) | F77: =IF('INPUT DATA'!R22="","",'INPUT DATA'!R22) | H77: =IF('INPUT DATA'!S22="","",'INPUT DATA'!S22) | I77: =IF(H77="","",DATEDIF(H77,TODAY(),"Y")) | U77: =IF(COUNT(K77:Q77,T77)=0,"",ROUND(AVERAGE(K77:Q77,T77),0)) | V77: =IF(U77="","",_xlfn.RANK.AVG(U77,$U$15:$U$115))
... B115: 50 | C115: =IF('INPUT DATA'!Q60="","",'INPUT DATA'!Q60) | F115: =IF('INPUT DATA'!R60="","",'INPUT DATA'!R60) | H115: =IF('INPUT DATA'!S60="","",'INPUT DATA'!S60) | I115: =IF(H115="","",DATEDIF(H115,TODAY(),"Y")) | U115: =IF(COUNT(K115:Q115,T115)=0,"",ROUND(AVERAGE(K115:Q115,T115),0)) | V115: =IF(U115="","",_xlfn.RANK.AVG(U115,$U$15:$U$115))

Sheet TERM 2 SUMMARY
A1: CLASS SUMMARY
D5: REGION | E5: =IF('INPUT DATA'!F10="","",'INPUT DATA'!F10) | I5: DIVISION | K5: =IF('INPUT DATA'!F11="","",'INPUT DATA'!F11)
D6: SCHOOL NAME | E6: =IF('INPUT DATA'!F16="","",'INPUT DATA'!F16) | I6: SCHOOL ID | K6: =IF('INPUT DATA'!F155="","",'INPUT DATA'!F15) | S6: SCHOOL YEAR | U6: =IF('INPUT DATA'!F18="","",'INPUT DATA'!F18)
B9: SECOND TERM | F9: GRADE LEVEL | G9: =IF('INPUT DATA'!F27="","",'INPUT DATA'!F27) | L9: ADVISER | N9: =IF('INPUT DATA'!F26="","",'INPUT DATA'!F26)
F10: SECTION | G10: =IF('INPUT DATA'!F28="","",'INPUT DATA'!F28)
B11: LEARNERS' NAMES | F11: LRN | H11: Date of Birth | I11: Age | J11: Sex | K11: Learning Areas | U11: Final Grade | V11: Rank
K12: Filipino | L12: English | M12: Enhanced Mathematics | N12: Enhanced Science | O12: AP | P12: GMRC/VE | Q12: EPP/TLE | R12: MAPEH
R13: M A | S13: P E H | T13: Term Grade
B15: 1 | C15: =IF('INPUT DATA'!L11="","",'INPUT DATA'!L11) | F15: =IF('INPUT DATA'!M11="","",'INPUT DATA'!M11) | H15: =IF('INPUT DATA'!N11="","",'INPUT DATA'!N11) | I15: =IF(H15="","",DATEDIF(H15,TODAY(),"Y")) | T15: =IF(COUNT($R15:$S15)=0,"",ROUND(AVERAGE(R15:S15),0)) | U15: =IF(COUNT(K15:Q15,T15)=0,"",ROUND(AVERAGE(K15:Q15,T15),0)) | V15: =IF(U15="","",_xlfn.RANK.AVG(U15,$U$15:$U$115))
B16: 2 | C16: =IF('INPUT DATA'!L12="","",'INPUT DATA'!L12) | F16: =IF('INPUT DATA'!M12="","",'INPUT DATA'!M12) | H16: =IF('INPUT DATA'!N12="","",'INPUT DATA'!N12) | I16: =IF(H16="","",DATEDIF(H16,TODAY(),"Y")) | T16: =IF(COUNT($R16:$S16)=0,"",ROUND(AVERAGE(R16:S16),0)) | U16: =IF(COUNT(K16:Q16,T16)=0,"",ROUND(AVERAGE(K16:Q16,T16),0)) | V16: =IF(U16="","",_xlfn.RANK.AVG(U16,$U$15:$U$115))
B17: 3 | C17: =IF('INPUT DATA'!L13="","",'INPUT DATA'!L13) | F17: =IF('INPUT DATA'!M13="","",'INPUT DATA'!M13) | H17: =IF('INPUT DATA'!N13="","",'INPUT DATA'!N13) | I17: =IF(H17="","",DATEDIF(H17,TODAY(),"Y")) | T17: =IF(COUNT($R17:$S17)=0,"",ROUND(AVERAGE(R17:S17),0)) | U17: =IF(COUNT(K17:Q17,T17)=0,"",ROUND(AVERAGE(K17:Q17,T17),0)) | V17: =IF(U17="","",_xlfn.RANK.AVG(U17,$U$15:$U$115))
B18: 4 | C18: =IF('INPUT DATA'!L14="","",'INPUT DATA'!L14) | F18: =IF('INPUT DATA'!M14="","",'INPUT DATA'!M14) | H18: =IF('INPUT DATA'!N14="","",'INPUT DATA'!N14) | I18: =IF(H18="","",DATEDIF(H18,TODAY(),"Y")) | T18: =IF(COUNT($R18:$S18)=0,"",ROUND(AVERAGE(R18:S18),0)) | U18: =IF(COUNT(K18:Q18,T18)=0,"",ROUND(AVERAGE(K18:Q18,T18),0)) | V18: =IF(U18="","",_xlfn.RANK.AVG(U18,$U$15:$U$115))
B19: 5 | C19: =IF('INPUT DATA'!L15="","",'INPUT DATA'!L15) | F19: =IF('INPUT DATA'!M15="","",'INPUT DATA'!M15) | H19: =IF('INPUT DATA'!N15="","",'INPUT DATA'!N15) | I19: =IF(H19="","",DATEDIF(H19,TODAY(),"Y")) | T19: =IF(COUNT($R19:$S19)=0,"",ROUND(AVERAGE(R19:S19),0)) | U19: =IF(COUNT(K19:Q19,T19)=0,"",ROUND(AVERAGE(K19:Q19,T19),0)) | V19: =IF(U19="","",_xlfn.RANK.AVG(U19,$U$15:$U$115))
B20: 6 | C20: =IF('INPUT DATA'!L16="","",'INPUT DATA'!L16) | F20: =IF('INPUT DATA'!M16="","",'INPUT DATA'!M16) | H20: =IF('INPUT DATA'!N16="","",'INPUT DATA'!N16) | I20: =IF(H20="","",DATEDIF(H20,TODAY(),"Y")) | T20: =IF(COUNT($R20:$S20)=0,"",ROUND(AVERAGE(R20:S20),0)) | U20: =IF(COUNT(K20:Q20,T20)=0,"",ROUND(AVERAGE(K20:Q20,T20),0)) | V20: =IF(U20="","",_xlfn.RANK.AVG(U20,$U$15:$U$115))
B21: 7 | C21: =IF('INPUT DATA'!L17="","",'INPUT DATA'!L17) | F21: =IF('INPUT DATA'!M17="","",'INPUT DATA'!M17) | H21: =IF('INPUT DATA'!N17="","",'INPUT DATA'!N17) | I21: =IF(H21="","",DATEDIF(H21,TODAY(),"Y")) | T21: =IF(COUNT($R21:$S21)=0,"",ROUND(AVERAGE(R21:S21),0)) | U21: =IF(COUNT(K21:Q21,T21)=0,"",ROUND(AVERAGE(K21:Q21,T21),0)) | V21: =IF(U21="","",_xlfn.RANK.AVG(U21,$U$15:$U$115))
B22: 8 | C22: =IF('INPUT DATA'!L18="","",'INPUT DATA'!L18) | F22: =IF('INPUT DATA'!M18="","",'INPUT DATA'!M18) | H22: =IF('INPUT DATA'!N18="","",'INPUT DATA'!N18) | I22: =IF(H22="","",DATEDIF(H22,TODAY(),"Y")) | T22: =IF(COUNT($R22:$S22)=0,"",ROUND(AVERAGE(R22:S22),0)) | U22: =IF(COUNT(K22:Q22,T22)=0,"",ROUND(AVERAGE(K22:Q22,T22),0)) | V22: =IF(U22="","",_xlfn.RANK.AVG(U22,$U$15:$U$115))
B23: 9 | C23: =IF('INPUT DATA'!L19="","",'INPUT DATA'!L19) | F23: =IF('INPUT DATA'!M19="","",'INPUT DATA'!M19) | H23: =IF('INPUT DATA'!N19="","",'INPUT DATA'!N19) | I23: =IF(H23="","",DATEDIF(H23,TODAY(),"Y")) | T23: =IF(COUNT($R23:$S23)=0,"",ROUND(AVERAGE(R23:S23),0)) | U23: =IF(COUNT(K23:Q23,T23)=0,"",ROUND(AVERAGE(K23:Q23,T23),0)) | V23: =IF(U23="","",_xlfn.RANK.AVG(U23,$U$15:$U$115))
B24: 10 | C24: =IF('INPUT DATA'!L20="","",'INPUT DATA'!L20) | F24: =IF('INPUT DATA'!M20="","",'INPUT DATA'!M20) | H24: =IF('INPUT DATA'!N20="","",'INPUT DATA'!N20) | I24: =IF(H24="","",DATEDIF(H24,TODAY(),"Y")) | T24: =IF(COUNT($R24:$S24)=0,"",ROUND(AVERAGE(R24:S24),0)) | U24: =IF(COUNT(K24:Q24,T24)=0,"",ROUND(AVERAGE(K24:Q24,T24),0)) | V24: =IF(U24="","",_xlfn.RANK.AVG(U24,$U$15:$U$115))
B25: 11 | C25: =IF('INPUT DATA'!L21="","",'INPUT DATA'!L21) | F25: =IF('INPUT DATA'!M21="","",'INPUT DATA'!M21) | H25: =IF('INPUT DATA'!N21="","",'INPUT DATA'!N21) | I25: =IF(H25="","",DATEDIF(H25,TODAY(),"Y")) | T25: =IF(COUNT($R25:$S25)=0,"",ROUND(AVERAGE(R25:S25),0)) | U25: =IF(COUNT(K25:Q25,T25)=0,"",ROUND(AVERAGE(K25:Q25,T25),0)) | V25: =IF(U25="","",_xlfn.RANK.AVG(U25,$U$15:$U$115))
B26: 12 | C26: =IF('INPUT DATA'!L22="","",'INPUT DATA'!L22) | F26: =IF('INPUT DATA'!M22="","",'INPUT DATA'!M22) | H26: =IF('INPUT DATA'!N22="","",'INPUT DATA'!N22) | I26: =IF(H26="","",DATEDIF(H26,TODAY(),"Y")) | T26: =IF(COUNT($R26:$S26)=0,"",ROUND(AVERAGE(R26:S26),0)) | U26: =IF(COUNT(K26:Q26,T26)=0,"",ROUND(AVERAGE(K26:Q26,T26),0)) | V26: =IF(U26="","",_xlfn.RANK.AVG(U26,$U$15:$U$115))
... B64: 50 | C64: =IF('INPUT DATA'!L60="","",'INPUT DATA'!L60) | F64: =IF('INPUT DATA'!M60="","",'INPUT DATA'!M60) | H64: =IF('INPUT DATA'!N60="","",'INPUT DATA'!N60) | I64: =IF(H64="","",DATEDIF(H64,TODAY(),"Y")) | T64: =IF(COUNT($R64:$S64)=0,"",ROUND(AVERAGE(R64:S64),0)) | U64: =IF(COUNT(K64:Q64,T64)=0,"",ROUND(AVERAGE(K64:Q64,T64),0)) | V64: =IF(U64="","",_xlfn.RANK.AVG(U64,$U$15:$U$115))
B65: FEMALE
B66: 1 | C66: =IF('INPUT DATA'!Q11="","",'INPUT DATA'!Q11) | F66: =IF('INPUT DATA'!R11="","",'INPUT DATA'!R11) | H66: =IF('INPUT DATA'!S11="","",'INPUT DATA'!S11) | I66: =IF(H66="","",DATEDIF(H66,TODAY(),"Y")) | U66: =IF(COUNT(K66:Q66,T66)=0,"",ROUND(AVERAGE(K66:Q66,T66),0)) | V66: =IF(U66="","",_xlfn.RANK.AVG(U66,$U$15:$U$115))
B67: 2 | C67: =IF('INPUT DATA'!Q12="","",'INPUT DATA'!Q12) | F67: =IF('INPUT DATA'!R12="","",'INPUT DATA'!R12) | H67: =IF('INPUT DATA'!S12="","",'INPUT DATA'!S12) | I67: =IF(H67="","",DATEDIF(H67,TODAY(),"Y")) | U67: =IF(COUNT(K67:Q67,T67)=0,"",ROUND(AVERAGE(K67:Q67,T67),0)) | V67: =IF(U67="","",_xlfn.RANK.AVG(U67,$U$15:$U$115))
B68: 3 | C68: =IF('INPUT DATA'!Q13="","",'INPUT DATA'!Q13) | F68: =IF('INPUT DATA'!R13="","",'INPUT DATA'!R13) | H68: =IF('INPUT DATA'!S13="","",'INPUT DATA'!S13) | I68: =IF(H68="","",DATEDIF(H68,TODAY(),"Y")) | U68: =IF(COUNT(K68:Q68,T68)=0,"",ROUND(AVERAGE(K68:Q68,T68),0)) | V68: =IF(U68="","",_xlfn.RANK.AVG(U68,$U$15:$U$115))
B69: 4 | C69: =IF('INPUT DATA'!Q14="","",'INPUT DATA'!Q14) | F69: =IF('INPUT DATA'!R14="","",'INPUT DATA'!R14) | H69: =IF('INPUT DATA'!S14="","",'INPUT DATA'!S14) | I69: =IF(H69="","",DATEDIF(H69,TODAY(),"Y")) | U69: =IF(COUNT(K69:Q69,T69)=0,"",ROUND(AVERAGE(K69:Q69,T69),0)) | V69: =IF(U69="","",_xlfn.RANK.AVG(U69,$U$15:$U$115))
B70: 5 | C70: =IF('INPUT DATA'!Q15="","",'INPUT DATA'!Q15) | F70: =IF('INPUT DATA'!R15="","",'INPUT DATA'!R15) | H70: =IF('INPUT DATA'!S15="","",'INPUT DATA'!S15) | I70: =IF(H70="","",DATEDIF(H70,TODAY(),"Y")) | U70: =IF(COUNT(K70:Q70,T70)=0,"",ROUND(AVERAGE(K70:Q70,T70),0)) | V70: =IF(U70="","",_xlfn.RANK.AVG(U70,$U$15:$U$115))
B71: 6 | C71: =IF('INPUT DATA'!Q16="","",'INPUT DATA'!Q16) | F71: =IF('INPUT DATA'!R16="","",'INPUT DATA'!R16) | H71: =IF('INPUT DATA'!S16="","",'INPUT DATA'!S16) | I71: =IF(H71="","",DATEDIF(H71,TODAY(),"Y")) | U71: =IF(COUNT(K71:Q71,T71)=0,"",ROUND(AVERAGE(K71:Q71,T71),0)) | V71: =IF(U71="","",_xlfn.RANK.AVG(U71,$U$15:$U$115))
B72: 7 | C72: =IF('INPUT DATA'!Q17="","",'INPUT DATA'!Q17) | F72: =IF('INPUT DATA'!R17="","",'INPUT DATA'!R17) | H72: =IF('INPUT DATA'!S17="","",'INPUT DATA'!S17) | I72: =IF(H72="","",DATEDIF(H72,TODAY(),"Y")) | U72: =IF(COUNT(K72:Q72,T72)=0,"",ROUND(AVERAGE(K72:Q72,T72),0)) | V72: =IF(U72="","",_xlfn.RANK.AVG(U72,$U$15:$U$115))
B73: 8 | C73: =IF('INPUT DATA'!Q18="","",'INPUT DATA'!Q18) | F73: =IF('INPUT DATA'!R18="","",'INPUT DATA'!R18) | H73: =IF('INPUT DATA'!S18="","",'INPUT DATA'!S18) | I73: =IF(H73="","",DATEDIF(H73,TODAY(),"Y")) | U73: =IF(COUNT(K73:Q73,T73)=0,"",ROUND(AVERAGE(K73:Q73,T73),0)) | V73: =IF(U73="","",_xlfn.RANK.AVG(U73,$U$15:$U$115))
B74: 9 | C74: =IF('INPUT DATA'!Q19="","",'INPUT DATA'!Q19) | F74: =IF('INPUT DATA'!R19="","",'INPUT DATA'!R19) | H74: =IF('INPUT DATA'!S19="","",'INPUT DATA'!S19) | I74: =IF(H74="","",DATEDIF(H74,TODAY(),"Y")) | U74: =IF(COUNT(K74:Q74,T74)=0,"",ROUND(AVERAGE(K74:Q74,T74),0)) | V74: =IF(U74="","",_xlfn.RANK.AVG(U74,$U$15:$U$115))
B75: 10 | C75: =IF('INPUT DATA'!Q20="","",'INPUT DATA'!Q20) | F75: =IF('INPUT DATA'!R20="","",'INPUT DATA'!R20) | H75: =IF('INPUT DATA'!S20="","",'INPUT DATA'!S20) | I75: =IF(H75="","",DATEDIF(H75,TODAY(),"Y")) | U75: =IF(COUNT(K75:Q75,T75)=0,"",ROUND(AVERAGE(K75:Q75,T75),0)) | V75: =IF(U75="","",_xlfn.RANK.AVG(U75,$U$15:$U$115))
B76: 11 | C76: =IF('INPUT DATA'!Q21="","",'INPUT DATA'!Q21) | F76: =IF('INPUT DATA'!R21="","",'INPUT DATA'!R21) | H76: =IF('INPUT DATA'!S21="","",'INPUT DATA'!S21) | I76: =IF(H76="","",DATEDIF(H76,TODAY(),"Y")) | U76: =IF(COUNT(K76:Q76,T76)=0,"",ROUND(AVERAGE(K76:Q76,T76),0)) | V76: =IF(U76="","",_xlfn.RANK.AVG(U76,$U$15:$U$115))
B77: 12 | C77: =IF('INPUT DATA'!Q22="","",'INPUT DATA'!Q22) | F77: =IF('INPUT DATA'!R22="","",'INPUT DATA'!R22) | H77: =IF('INPUT DATA'!S22="","",'INPUT DATA'!S22) | I77: =IF(H77="","",DATEDIF(H77,TODAY(),"Y")) | U77: =IF(COUNT(K77:Q77,T77)=0,"",ROUND(AVERAGE(K77:Q77,T77),0)) | V77: =IF(U77="","",_xlfn.RANK.AVG(U77,$U$15:$U$115))
... B115: 50 | C115: =IF('INPUT DATA'!Q60="","",'INPUT DATA'!Q60) | F115: =IF('INPUT DATA'!R60="","",'INPUT DATA'!R60) | H115: =IF('INPUT DATA'!S60="","",'INPUT DATA'!S60) | I115: =IF(H115="","",DATEDIF(H115,TODAY(),"Y")) | U115: =IF(COUNT(K115:Q115,T115)=0,"",ROUND(AVERAGE(K115:Q115,T115),0)) | V115: =IF(U115="","",_xlfn.RANK.AVG(U115,$U$15:$U$115))

Sheet TERM 3 SUMMARY
A1: CLASS SUMMARY
D5: REGION | E5: =IF('INPUT DATA'!F10="","",'INPUT DATA'!F10) | I5: DIVISION | K5: =IF('INPUT DATA'!F11="","",'INPUT DATA'!F11)
D6: SCHOOL NAME | E6: =IF('INPUT DATA'!F16="","",'INPUT DATA'!F16) | I6: SCHOOL ID | K6: =IF('INPUT DATA'!F155="","",'INPUT DATA'!F15) | S6: SCHOOL YEAR | U6: =IF('INPUT DATA'!F18="","",'INPUT DATA'!F18)
B9: THIRD TERM | F9: GRADE LEVEL | G9: =IF('INPUT DATA'!F27="","",'INPUT DATA'!F27) | L9: ADVISER | N9: =IF('INPUT DATA'!F26="","",'INPUT DATA'!F26)
F10: SECTION | G10: =IF('INPUT DATA'!F28="","",'INPUT DATA'!F28)
B11: LEARNERS' NAMES | F11: LRN | H11: Date of Birth | I11: Age | J11: Sex | K11: Learning Areas | U11: Final Grade | V11: Rank
K12: Filipino | L12: English | M12: Enhanced Mathematics | N12: Enhanced Science | O12: AP | P12: GMRC/VE | Q12: EPP/TLE | R12: MAPEH
R13: M A | S13: P E H | T13: Term Grade
B15: 1 | C15: =IF('INPUT DATA'!L11="","",'INPUT DATA'!L11) | F15: =IF('INPUT DATA'!M11="","",'INPUT DATA'!M11) | H15: =IF('INPUT DATA'!N11="","",'INPUT DATA'!N11) | I15: =IF(H15="","",DATEDIF(H15,TODAY(),"Y")) | T15: =IF(COUNT($R15:$S15)=0,"",ROUND(AVERAGE(R15:S15),0)) | U15: =IF(COUNT(K15:Q15,T15)=0,"",ROUND(AVERAGE(K15:Q15,T15),0)) | V15: =IF(U15="","",_xlfn.RANK.AVG(U15,$U$15:$U$115))
B16: 2 | C16: =IF('INPUT DATA'!L12="","",'INPUT DATA'!L12) | F16: =IF('INPUT DATA'!M12="","",'INPUT DATA'!M12) | H16: =IF('INPUT DATA'!N12="","",'INPUT DATA'!N12) | I16: =IF(H16="","",DATEDIF(H16,TODAY(),"Y")) | T16: =IF(COUNT($R16:$S16)=0,"",ROUND(AVERAGE(R16:S16),0)) | U16: =IF(COUNT(K16:Q16,T16)=0,"",ROUND(AVERAGE(K16:Q16,T16),0)) | V16: =IF(U16="","",_xlfn.RANK.AVG(U16,$U$15:$U$115))
B17: 3 | C17: =IF('INPUT DATA'!L13="","",'INPUT DATA'!L13) | F17: =IF('INPUT DATA'!M13="","",'INPUT DATA'!M13) | H17: =IF('INPUT DATA'!N13="","",'INPUT DATA'!N13) | I17: =IF(H17="","",DATEDIF(H17,TODAY(),"Y")) | T17: =IF(COUNT($R17:$S17)=0,"",ROUND(AVERAGE(R17:S17),0)) | U17: =IF(COUNT(K17:Q17,T17)=0,"",ROUND(AVERAGE(K17:Q17,T17),0)) | V17: =IF(U17="","",_xlfn.RANK.AVG(U17,$U$15:$U$115))
B18: 4 | C18: =IF('INPUT DATA'!L14="","",'INPUT DATA'!L14) | F18: =IF('INPUT DATA'!M14="","",'INPUT DATA'!M14) | H18: =IF('INPUT DATA'!N14="","",'INPUT DATA'!N14) | I18: =IF(H18="","",DATEDIF(H18,TODAY(),"Y")) | T18: =IF(COUNT($R18:$S18)=0,"",ROUND(AVERAGE(R18:S18),0)) | U18: =IF(COUNT(K18:Q18,T18)=0,"",ROUND(AVERAGE(K18:Q18,T18),0)) | V18: =IF(U18="","",_xlfn.RANK.AVG(U18,$U$15:$U$115))
B19: 5 | C19: =IF('INPUT DATA'!L15="","",'INPUT DATA'!L15) | F19: =IF('INPUT DATA'!M15="","",'INPUT DATA'!M15) | H19: =IF('INPUT DATA'!N15="","",'INPUT DATA'!N15) | I19: =IF(H19="","",DATEDIF(H19,TODAY(),"Y")) | T19: =IF(COUNT($R19:$S19)=0,"",ROUND(AVERAGE(R19:S19),0)) | U19: =IF(COUNT(K19:Q19,T19)=0,"",ROUND(AVERAGE(K19:Q19,T19),0)) | V19: =IF(U19="","",_xlfn.RANK.AVG(U19,$U$15:$U$115))
B20: 6 | C20: =IF('INPUT DATA'!L16="","",'INPUT DATA'!L16) | F20: =IF('INPUT DATA'!M16="","",'INPUT DATA'!M16) | H20: =IF('INPUT DATA'!N16="","",'INPUT DATA'!N16) | I20: =IF(H20="","",DATEDIF(H20,TODAY(),"Y")) | T20: =IF(COUNT($R20:$S20)=0,"",ROUND(AVERAGE(R20:S20),0)) | U20: =IF(COUNT(K20:Q20,T20)=0,"",ROUND(AVERAGE(K20:Q20,T20),0)) | V20: =IF(U20="","",_xlfn.RANK.AVG(U20,$U$15:$U$115))
B21: 7 | C21: =IF('INPUT DATA'!L17="","",'INPUT DATA'!L17) | F21: =IF('INPUT DATA'!M17="","",'INPUT DATA'!M17) | H21: =IF('INPUT DATA'!N17="","",'INPUT DATA'!N17) | I21: =IF(H21="","",DATEDIF(H21,TODAY(),"Y")) | T21: =IF(COUNT($R21:$S21)=0,"",ROUND(AVERAGE(R21:S21),0)) | U21: =IF(COUNT(K21:Q21,T21)=0,"",ROUND(AVERAGE(K21:Q21,T21),0)) | V21: =IF(U21="","",_xlfn.RANK.AVG(U21,$U$15:$U$115))
B22: 8 | C22: =IF('INPUT DATA'!L18="","",'INPUT DATA'!L18) | F22: =IF('INPUT DATA'!M18="","",'INPUT DATA'!M18) | H22: =IF('INPUT DATA'!N18="","",'INPUT DATA'!N18) | I22: =IF(H22="","",DATEDIF(H22,TODAY(),"Y")) | T22: =IF(COUNT($R22:$S22)=0,"",ROUND(AVERAGE(R22:S22),0)) | U22: =IF(COUNT(K22:Q22,T22)=0,"",ROUND(AVERAGE(K22:Q22,T22),0)) | V22: =IF(U22="","",_xlfn.RANK.AVG(U22,$U$15:$U$115))
B23: 9 | C23: =IF('INPUT DATA'!L19="","",'INPUT DATA'!L19) | F23: =IF('INPUT DATA'!M19="","",'INPUT DATA'!M19) | H23: =IF('INPUT DATA'!N19="","",'INPUT DATA'!N19) | I23: =IF(H23="","",DATEDIF(H23,TODAY(),"Y")) | T23: =IF(COUNT($R23:$S23)=0,"",ROUND(AVERAGE(R23:S23),0)) | U23: =IF(COUNT(K23:Q23,T23)=0,"",ROUND(AVERAGE(K23:Q23,T23),0)) | V23: =IF(U23="","",_xlfn.RANK.AVG(U23,$U$15:$U$115))
B24: 10 | C24: =IF('INPUT DATA'!L20="","",'INPUT DATA'!L20) | F24: =IF('INPUT DATA'!M20="","",'INPUT DATA'!M20) | H24: =IF('INPUT DATA'!N20="","",'INPUT DATA'!N20) | I24: =IF(H24="","",DATEDIF(H24,TODAY(),"Y")) | T24: =IF(COUNT($R24:$S24)=0,"",ROUND(AVERAGE(R24:S24),0)) | U24: =IF(COUNT(K24:Q24,T24)=0,"",ROUND(AVERAGE(K24:Q24,T24),0)) | V24: =IF(U24="","",_xlfn.RANK.AVG(U24,$U$15:$U$115))
B25: 11 | C25: =IF('INPUT DATA'!L21="","",'INPUT DATA'!L21) | F25: =IF('INPUT DATA'!M21="","",'INPUT DATA'!M21) | H25: =IF('INPUT DATA'!N21="","",'INPUT DATA'!N21) | I25: =IF(H25="","",DATEDIF(H25,TODAY(),"Y")) | T25: =IF(COUNT($R25:$S25)=0,"",ROUND(AVERAGE(R25:S25),0)) | U25: =IF(COUNT(K25:Q25,T25)=0,"",ROUND(AVERAGE(K25:Q25,T25),0)) | V25: =IF(U25="","",_xlfn.RANK.AVG(U25,$U$15:$U$115))
B26: 12 | C26: =IF('INPUT DATA'!L22="","",'INPUT DATA'!L22) | F26: =IF('INPUT DATA'!M22="","",'INPUT DATA'!M22) | H26: =IF('INPUT DATA'!N22="","",'INPUT DATA'!N22) | I26: =IF(H26="","",DATEDIF(H26,TODAY(),"Y")) | T26: =IF(COUNT($R26:$S26)=0,"",ROUND(AVERAGE(R26:S26),0)) | U26: =IF(COUNT(K26:Q26,T26)=0,"",ROUND(AVERAGE(K26:Q26,T26),0)) | V26: =IF(U26="","",_xlfn.RANK.AVG(U26,$U$15:$U$115))
... B64: 50 | C64: =IF('INPUT DATA'!L60="","",'INPUT DATA'!L60) | F64: =IF('INPUT DATA'!M60="","",'INPUT DATA'!M60) | H64: =IF('INPUT DATA'!N60="","",'INPUT DATA'!N60) | I64: =IF(H64="","",DATEDIF(H64,TODAY(),"Y")) | T64: =IF(COUNT($R64:$S64)=0,"",ROUND(AVERAGE(R64:S64),0)) | U64: =IF(COUNT(K64:Q64,T64)=0,"",ROUND(AVERAGE(K64:Q64,T64),0)) | V64: =IF(U64="","",_xlfn.RANK.AVG(U64,$U$15:$U$115))
B65: FEMALE
B66: 1 | C66: =IF('INPUT DATA'!Q11="","",'INPUT DATA'!Q11) | F66: =IF('INPUT DATA'!R11="","",'INPUT DATA'!R11) | H66: =IF('INPUT DATA'!S11="","",'INPUT DATA'!S11) | I66: =IF(H66="","",DATEDIF(H66,TODAY(),"Y")) | U66: =IF(COUNT(K66:Q66,T66)=0,"",ROUND(AVERAGE(K66:Q66,T66),0)) | V66: =IF(U66="","",_xlfn.RANK.AVG(U66,$U$15:$U$115))
B67: 2 | C67: =IF('INPUT DATA'!Q12="","",'INPUT DATA'!Q12) | F67: =IF('INPUT DATA'!R12="","",'INPUT DATA'!R12) | H67: =IF('INPUT DATA'!S12="","",'INPUT DATA'!S12) | I67: =IF(H67="","",DATEDIF(H67,TODAY(),"Y")) | U67: =IF(COUNT(K67:Q67,T67)=0,"",ROUND(AVERAGE(K67:Q67,T67),0)) | V67: =IF(U67="","",_xlfn.RANK.AVG(U67,$U$15:$U$115))
B68: 3 | C68: =IF('INPUT DATA'!Q13="","",'INPUT DATA'!Q13) | F68: =IF('INPUT DATA'!R13="","",'INPUT DATA'!R13) | H68: =IF('INPUT DATA'!S13="","",'INPUT DATA'!S13) | I68: =IF(H68="","",DATEDIF(H68,TODAY(),"Y")) | U68: =IF(COUNT(K68:Q68,T68)=0,"",ROUND(AVERAGE(K68:Q68,T68),0)) | V68: =IF(U68="","",_xlfn.RANK.AVG(U68,$U$15:$U$115))
B69: 4 | C69: =IF('INPUT DATA'!Q14="","",'INPUT DATA'!Q14) | F69: =IF('INPUT DATA'!R14="","",'INPUT DATA'!R14) | H69: =IF('INPUT DATA'!S14="","",'INPUT DATA'!S14) | I69: =IF(H69="","",DATEDIF(H69,TODAY(),"Y")) | U69: =IF(COUNT(K69:Q69,T69)=0,"",ROUND(AVERAGE(K69:Q69,T69),0)) | V69: =IF(U69="","",_xlfn.RANK.AVG(U69,$U$15:$U$115))
B70: 5 | C70: =IF('INPUT DATA'!Q15="","",'INPUT DATA'!Q15) | F70: =IF('INPUT DATA'!R15="","",'INPUT DATA'!R15) | H70: =IF('INPUT DATA'!S15="","",'INPUT DATA'!S15) | I70: =IF(H70="","",DATEDIF(H70,TODAY(),"Y")) | U70: =IF(COUNT(K70:Q70,T70)=0,"",ROUND(AVERAGE(K70:Q70,T70),0)) | V70: =IF(U70="","",_xlfn.RANK.AVG(U70,$U$15:$U$115))
B71: 6 | C71: =IF('INPUT DATA'!Q16="","",'INPUT DATA'!Q16) | F71: =IF('INPUT DATA'!R16="","",'INPUT DATA'!R16) | H71: =IF('INPUT DATA'!S16="","",'INPUT DATA'!S16) | I71: =IF(H71="","",DATEDIF(H71,TODAY(),"Y")) | U71: =IF(COUNT(K71:Q71,T71)=0,"",ROUND(AVERAGE(K71:Q71,T71),0)) | V71: =IF(U71="","",_xlfn.RANK.AVG(U71,$U$15:$U$115))
B72: 7 | C72: =IF('INPUT DATA'!Q17="","",'INPUT DATA'!Q17) | F72: =IF('INPUT DATA'!R17="","",'INPUT DATA'!R17) | H72: =IF('INPUT DATA'!S17="","",'INPUT DATA'!S17) | I72: =IF(H72="","",DATEDIF(H72,TODAY(),"Y")) | U72: =IF(COUNT(K72:Q72,T72)=0,"",ROUND(AVERAGE(K72:Q72,T72),0)) | V72: =IF(U72="","",_xlfn.RANK.AVG(U72,$U$15:$U$115))
B73: 8 | C73: =IF('INPUT DATA'!Q18="","",'INPUT DATA'!Q18) | F73: =IF('INPUT DATA'!R18="","",'INPUT DATA'!R18) | H73: =IF('INPUT DATA'!S18="","",'INPUT DATA'!S18) | I73: =IF(H73="","",DATEDIF(H73,TODAY(),"Y")) | U73: =IF(COUNT(K73:Q73,T73)=0,"",ROUND(AVERAGE(K73:Q73,T73),0)) | V73: =IF(U73="","",_xlfn.RANK.AVG(U73,$U$15:$U$115))
B74: 9 | C74: =IF('INPUT DATA'!Q19="","",'INPUT DATA'!Q19) | F74: =IF('INPUT DATA'!R19="","",'INPUT DATA'!R19) | H74: =IF('INPUT DATA'!S19="","",'INPUT DATA'!S19) | I74: =IF(H74="","",DATEDIF(H74,TODAY(),"Y")) | U74: =IF(COUNT(K74:Q74,T74)=0,"",ROUND(AVERAGE(K74:Q74,T74),0)) | V74: =IF(U74="","",_xlfn.RANK.AVG(U74,$U$15:$U$115))
B75: 10 | C75: =IF('INPUT DATA'!Q20="","",'INPUT DATA'!Q20) | F75: =IF('INPUT DATA'!R20="","",'INPUT DATA'!R20) | H75: =IF('INPUT DATA'!S20="","",'INPUT DATA'!S20) | I75: =IF(H75="","",DATEDIF(H75,TODAY(),"Y")) | U75: =IF(COUNT(K75:Q75,T75)=0,"",ROUND(AVERAGE(K75:Q75,T75),0)) | V75: =IF(U75="","",_xlfn.RANK.AVG(U75,$U$15:$U$115))
B76: 11 | C76: =IF('INPUT DATA'!Q21="","",'INPUT DATA'!Q21) | F76: =IF('INPUT DATA'!R21="","",'INPUT DATA'!R21) | H76: =IF('INPUT DATA'!S21="","",'INPUT DATA'!S21) | I76: =IF(H76="","",DATEDIF(H76,TODAY(),"Y")) | U76: =IF(COUNT(K76:Q76,T76)=0,"",ROUND(AVERAGE(K76:Q76,T76),0)) | V76: =IF(U76="","",_xlfn.RANK.AVG(U76,$U$15:$U$115))
B77: 12 | C77: =IF('INPUT DATA'!Q22="","",'INPUT DATA'!Q22) | F77: =IF('INPUT DATA'!R22="","",'INPUT DATA'!R22) | H77: =IF('INPUT DATA'!S22="","",'INPUT DATA'!S22) | I77: =IF(H77="","",DATEDIF(H77,TODAY(),"Y")) | U77: =IF(COUNT(K77:Q77,T77)=0,"",ROUND(AVERAGE(K77:Q77,T77),0)) | V77: =IF(U77="","",_xlfn.RANK.AVG(U77,$U$15:$U$115))
... B115: 50 | C115: =IF('INPUT DATA'!Q60="","",'INPUT DATA'!Q60) | F115: =IF('INPUT DATA'!R60="","",'INPUT DATA'!R60) | H115: =IF('INPUT DATA'!S60="","",'INPUT DATA'!S60) | I115: =IF(H115="","",DATEDIF(H115,TODAY(),"Y")) | U115: =IF(COUNT(K115:Q115,T115)=0,"",ROUND(AVERAGE(K115:Q115,T115),0)) | V115: =IF(U115="","",_xlfn.RANK.AVG(U115,$U$15:$U$115))

Sheet SF9 - GRADE 4-6
B4: Republic of the Philippines | Q4: Month | R4: Jun | S4: Jul | T4: Aug | U4: Sep | V4: Oct | W4: Nov | X4: Dec | Y4: Jan | Z4: Feb | AA4: Mar | AB4: Apr | AC4: Total
B5: Department of Education | Q5: No. of Class Days | AC5: =SUM(R5:AB6) -> 0
B7: REGION | Q7: No. of Days Present | R7: =IF('ATTENDANCE RECORD SUMMARY'!F14="","",IFERROR(VLOOKUP(C17,'ATTENDANCE RECORD SUMMARY'!$C$14:$P$114,4,0),"")) | S7: =IF('ATTENDANCE RECORD SUMMARY'!F14="","",IFERROR(VLOOKUP(C17,'ATTENDANCE RECORD SUMMARY'!$C$14:$P$114,5,0),"")) | T7: =IF('ATTENDANCE RECORD SUMMARY'!F14="","",IFERROR(VLOOKUP(C17,'ATTENDANCE RECORD SUMMARY'!$C$14:$P$114,6,0),"")) | U7: =IF('ATTENDANCE RECORD SUMMARY'!F14="","",IFERROR(VLOOKUP(C17,'ATTENDANCE RECORD SUMMARY'!$C$14:$P$114,7,0),"")) | V7: =IF('ATTENDANCE RECORD SUMMARY'!F14="","",IFERROR(VLOOKUP(C17,'ATTENDANCE RECORD SUMMARY'!$C$14:$P$114,8,0),"")) | W7: =IF('ATTENDANCE RECORD SUMMARY'!F14="","",IFERROR(VLOOKUP(C17,'ATTENDANCE RECORD SUMMARY'!$C$14:$P$114,9,0),"")) | X7: =IF('ATTENDANCE RECORD SUMMARY'!F14="","",IFERROR(VLOOKUP(C17,'ATTENDANCE RECORD SUMMARY'!$C$14:$P$114,10,0),"")) | Y7: =IF('ATTENDANCE RECORD SUMMARY'!F14="","",IFERROR(VLOOKUP(C17,'ATTENDANCE RECORD SUMMARY'!$C$14:$P$114,11,0),"")) | Z7: =IF('ATTENDANCE RECORD SUMMARY'!F14="","",IFERROR(VLOOKUP(C17,'ATTENDANCE RECORD SUMMARY'!$C$14:$P$114,12,0),"")) | AA7: =IF('ATTENDANCE RECORD SUMMARY'!F14="","",IFERROR(VLOOKUP(C17,'ATTENDANCE RECORD SUMMARY'!$C$14:$P$114,13,0),"")) | AB7: =IF('ATTENDANCE RECORD SUMMARY'!F14="","",IFERROR(VLOOKUP(C17,'ATTENDANCE RECORD SUMMARY'!$C$14:$P$114,14,0),"")) | AC7: =SUM(R7:AB8) -> 0
B8: SCHOOLS DIVISION OF _____
B9: District | Q9: No. of Days Absent | R9: =IF(R7="","",ABS(R5-R7)) | S9: =IF(S7="","",ABS(S5-S7)) | T9: =IF(T7="","",ABS(T5-T7)) | U9: =IF(U7="","",ABS(U5-U7)) | V9: =IF(V7="","",ABS(V5-V7)) | W9: =IF(W7="","",ABS(W5-W7)) | X9: =IF(X7="","",ABS(X5-X7)) | Y9: =IF(Y7="","",ABS(Y5-Y7)) | ... AB9: =IF(AB7="","",ABS(AB5-AB7)) | AC9: =ABS(AC5-AC7) -> 0
B10: Municipality/City, Province
B12: ABC ELEMENTARY SCHOOL
B14: LEARNER'S PERFORMANCE REPORT | Q14: TEACHER'S COMMENTS / REMARKS
B15: School Year 2026-2027 | Q15: Term 1
B17: Name: | H17: Age: | I17: =IF(C17="","",VLOOKUP(C17,'TERM 1 SUMMARY'!C15:U115,7,0)) | J17: Sex: | K17: =IF(C17="","",VLOOKUP(C17,'TERM 1 SUMMARY'!C15:U115,8,0))
B18: LRN: | C18: =IF(C17="","",VLOOKUP(C17,'TERM 1 SUMMARY'!C15:U115,4,0)) | H18: Grade: | I18: ='TERM 1 SUMMARY'!G9 | J18: Section: | K18: ='TERM 1 SUMMARY'!G10
B19: Track (SHS only): | Q19: Term 2
B21: Dear Parents,
C22: This Performance Report presents your child's progress and achievement
B23: in the different learning areas. | Q23: Term 3
C24: The school welcomes you to reach out should you wish to know more about your
B25: child's learning and performance.
B27: =IF('INPUT DATA'!F19="","",'INPUT DATA'!F19) | H27: =IF('INPUT DATA'!F26="","",'INPUT DATA'!F26)
B28: School Head | H28: Adviser | Q28: PARENT/S GUARDIAN'S SIGNATURE
B29: LEARNING PROGRESS AND ACHIEVEMENT | R29: Term 1
B30: Learning Areas | F30: TERM | I30: Final Grade | J30: Remarks | R30: Term 2
F31: T1 | G31: T2 | H31: T3 | R31: Term 3
B32: Filipino | F32: =IF('TERM 1 SUMMARY'!U15="","",IFERROR(VLOOKUP(C17,'TERM 1 SUMMARY'!$C$15:$U$115,9,0),"")) | G32: =IF('TERM 2 SUMMARY'!T15="","",IFERROR(VLOOKUP(C17,'TERM 2 SUMMARY'!$C$15:$T$115,9,0),"")) | H32: =IF('TERM 3 SUMMARY'!T15="","",IFERROR(VLOOKUP(C17,'TERM 3 SUMMARY'!$C$15:$T$115,9,0),"")) | I32: =IF(COUNT(F32:H32)<3,"",ROUND(AVERAGE(F32:H32),0)) | J32: =IF(I32="","",IF(I32>=75,"Passed","Failed"))
B33: English | F33: =IF('TERM 1 SUMMARY'!U15="","",IFERROR(VLOOKUP(C17,'TERM 1 SUMMARY'!$C$15:$U$115,10,0),"")) | G33: =IF('TERM 2 SUMMARY'!T15="","",IFERROR(VLOOKUP(C17,'TERM 2 SUMMARY'!$C$15:$T$115,10,0),"")) | H33: =IF('TERM 3 SUMMARY'!T15="","",IFERROR(VLOOKUP(C17,'TERM 3 SUMMARY'!$C$15:$T$115,10,0),"")) | I33: =IF(COUNT(F33:H33)<3,"",ROUND(AVERAGE(F33:H33),0)) | J33: =IF(I33="","",IF(I33>=75,"Passed","Failed")) | Q33: CERTIFICATE OF TRANSFER
B34: Enhanced Mathematics | F34: =IF('TERM 1 SUMMARY'!U15="","",IFERROR(VLOOKUP(C17,'TERM 1 SUMMARY'!$C$15:$U$115,11,0),"")) | G34: =IF('TERM 2 SUMMARY'!T15="","",IFERROR(VLOOKUP(C17,'TERM 2 SUMMARY'!$C$15:$T$115,11,0),"")) | H34: =IF('TERM 3 SUMMARY'!T15="","",IFERROR(VLOOKUP(C17,'TERM 3 SUMMARY'!$C$15:$T$115,11,0),"")) | I34: =IF(COUNT(F34:H34)<3,"",ROUND(AVERAGE(F34:H34),0)) | J34: =IF(I34="","",IF(I34>=75,"Passed","Failed")) | Q34: This is to certify that the above-named learner has satisfactorily completed the requirements
B35: Enhanced Science | F35: =IF('TERM 1 SUMMARY'!U15="","",IFERROR(VLOOKUP(C17,'TERM 1 SUMMARY'!$C$15:$U$115,12,0),"")) | G35: =IF('TERM 2 SUMMARY'!T15="","",IFERROR(VLOOKUP(C17,'TERM 2 SUMMARY'!$C$15:$T$115,12,0),"")) | H35: =IF('TERM 3 SUMMARY'!T15="","",IFERROR(VLOOKUP(C17,'TERM 3 SUMMARY'!$C$15:$T$115,12,0),"")) | I35: =IF(COUNT(F35:H35)<3,"",ROUND(AVERAGE(F35:H35),0)) | J35: =IF(I35="","",IF(I35>=75,"Passed","Failed")) | Q35: for the grade level indicated. | AE35: =IF(COUNT(F31:H31)=0,"",ROUND((F31+G31+H31)/3,0))
B36: Araling Panlipunan (AP) | F36: =IF('TERM 1 SUMMARY'!U15="","",IFERROR(VLOOKUP(C17,'TERM 1 SUMMARY'!$C$15:$U$115,13,0),"")) | G36: =IF('TERM 2 SUMMARY'!T15="","",IFERROR(VLOOKUP(C17,'TERM 2 SUMMARY'!$C$15:$T$115,13,0),"")) | H36: =IF('TERM 3 SUMMARY'!T15="","",IFERROR(VLOOKUP(C17,'TERM 3 SUMMARY'!$C$15:$T$115,13,0),"")) | I36: =IF(COUNT(F36:H36)<3,"",ROUND(AVERAGE(F36:H36),0)) | J36: =IF(I36="","",IF(I36>=75,"Passed","Failed"))
B37: GMRC / Values Education | F37: =IF('TERM 1 SUMMARY'!U15="","",IFERROR(VLOOKUP(C17,'TERM 1 SUMMARY'!$C$15:$U$115,14,0),"")) | G37: =IF('TERM 2 SUMMARY'!T15="","",IFERROR(VLOOKUP(C17,'TERM 2 SUMMARY'!$C$15:$T$115,14,0),"")) | H37: =IF('TERM 3 SUMMARY'!T15="","",IFERROR(VLOOKUP(C17,'TERM 3 SUMMARY'!$C$15:$T$115,14,0),"")) | I37: =IF(COUNT(F37:H37)<3,"",ROUND(AVERAGE(F37:H37),0)) | J37: =IF(I37="","",IF(I37>=75,"Passed","Failed")) | Q37: Admitted to Grade:
B38: EPP/TLE | F38: =IF('TERM 1 SUMMARY'!U15="","",IFERROR(VLOOKUP(C17,'TERM 1 SUMMARY'!$C$15:$U$115,15,0),"")) | G38: =IF('TERM 2 SUMMARY'!T15="","",IFERROR(VLOOKUP(C17,'TERM 2 SUMMARY'!$C$15:$T$115,15,0),"")) | H38: =IF('TERM 3 SUMMARY'!T15="","",IFERROR(VLOOKUP(C17,'TERM 3 SUMMARY'!$C$15:$T$115,15,0),"")) | I38: =IF(COUNT(F38:H38)<3,"",ROUND(AVERAGE(F38:H38),0)) | J38: =IF(I38="","",IF(I38>=75,"Passed","Failed")) | Q38: Eligible for Admission to Grade:
B39: MAPEH | F39: =IF('TERM 1 SUMMARY'!T15="","",IFERROR(VLOOKUP(C17,'TERM 1 SUMMARY'!$C$15:$T$115,18,0),"")) | G39: =IF('TERM 2 SUMMARY'!T15="","",IFERROR(VLOOKUP(C17,'TERM 2 SUMMARY'!$C$15:$T$115,18,0),"")) | H39: =IF('TERM 3 SUMMARY'!T15="","",IFERROR(VLOOKUP(C17,'TERM 3 SUMMARY'!$C$15:$T$115,18,0),"")) | I39: =IF(COUNT(F39:H39)<3,"",ROUND(AVERAGE(F39:H39),0)) | J39: =IF(I39="","",IF(I39>=75,"Passed","Failed"))
B40: Music and Arts | F40: =IF('TERM 1 SUMMARY'!U15="","",IFERROR(VLOOKUP(C17,'TERM 1 SUMMARY'!$C$15:$U$115,16,0),"")) | G40: =IF('TERM 2 SUMMARY'!T15="","",IFERROR(VLOOKUP(C17,'TERM 2 SUMMARY'!$C$15:$T$115,16,0),"")) | H40: =IF('TERM 3 SUMMARY'!T15="","",IFERROR(VLOOKUP(C17,'TERM 3 SUMMARY'!$C$15:$T$115,16,0),"")) | I40: =IF(COUNT(F40:H40)<3,"",ROUND(AVERAGE(F40:H40),0)) | J40: =IF(I40="","",IF(I40>=75,"Passed","Failed")) | Q40: Approved: | X40: =IF('INPUT DATA'!F26="","",'INPUT DATA'!F26)
B41: Physical Education and Health | F41: =IF('TERM 1 SUMMARY'!U15="","",IFERROR(VLOOKUP(C17,'TERM 1 SUMMARY'!$C$15:$U$115,17,0),"")) | G41: =IF('TERM 2 SUMMARY'!T15="","",IFERROR(VLOOKUP(C17,'TERM 2 SUMMARY'!$C$15:$T$115,17,0),"")) | H41: =IF('TERM 3 SUMMARY'!T15="","",IFERROR(VLOOKUP(C17,'TERM 3 SUMMARY'!$C$15:$T$115,17,0),"")) | I41: =IF(COUNT(F41:H41)<3,"",ROUND(AVERAGE(F41:H41),0)) | J41: =IF(I41="","",IF(I41>=75,"Passed","Failed")) | Q41: =IF('INPUT DATA'!F19="","",'INPUT DATA'!F19) | X41: Adviser
B42: General Average | I42: =IF(COUNT(I32:I39)=0,"",ROUND(AVERAGE(I32:I39),0)) | J42: =IF(I42="","",IF(I42>=75,"Passed","Failed"))
Q43: School Head
B45: PERFORMANCE DESCRIPTORS | Q45: CANCELLATION OF ELIGIBILITY TO TRANSFER
C46: Grading Scale | F46: Descriptors | I46: Remarks | Q46: Admitted in: | X46: Date:
C47: 90-100 | F47: Advancing | I47: Passed
C48: 80-89 | F48: Benchmarking | I48: Passed
C49: 75-79 | F49: Connecting | I49: Passed | Q49: =IF('INPUT DATA'!F19="","",'INPUT DATA'!F19)
C50: 65-74 | F50: Developing | I50: Failed | Q50: School Head
...

Sheet ATTENDANCE RECORD SUMMARY
A1: ATTENDANCE RECORD
D5: REGION | E5: =IF('INPUT DATA'!F10="","",'INPUT DATA'!F10) | H5: DIVISION | I5: =IF('INPUT DATA'!F11="","",'INPUT DATA'!F11)
D7: SCHOOL NAME | E7: =IF('INPUT DATA'!F16="","",'INPUT DATA'!F16) | H7: SCHOOL ID | I7: =IF('INPUT DATA'!F15="","",'INPUT DATA'!F15) | L7: SCHOOL YEAR | N7: =IF('INPUT DATA'!F18="","",'INPUT DATA'!F18)
B10: LEARNERS' NAMES | F10: GRADE LEVEL | G10: =IF('INPUT DATA'!F27="","",'INPUT DATA'!F27) | K10: ADVISER | L10: =IF('INPUT DATA'!F26="","",'INPUT DATA'!F26)
F11: SECTION | G11: =IF('INPUT DATA'!F28="","",'INPUT DATA'!F28)
F12: JUN | G12: JUL | H12: AUG | I12: SEP | J12: OCT | K12: NOV | L12: DEC | M12: JAN | N12: FEB | O12: MAR | P12: APRIL
B13: MALE
B14: 1 | C14: =IF('INPUT DATA'!L11="","",'INPUT DATA'!L11)
B15: 2 | C15: =IF('INPUT DATA'!L12="","",'INPUT DATA'!L12)
B16: 3 | C16: =IF('INPUT DATA'!L13="","",'INPUT DATA'!L13)
B17: 4 | C17: =IF('INPUT DATA'!L14="","",'INPUT DATA'!L14)
B18: 5 | C18: =IF('INPUT DATA'!L15="","",'INPUT DATA'!L15)
B19: 6 | C19: =IF('INPUT DATA'!L16="","",'INPUT DATA'!L16)
B20: 7 | C20: =IF('INPUT DATA'!L17="","",'INPUT DATA'!L17)
B21: 8 | C21: =IF('INPUT DATA'!L18="","",'INPUT DATA'!L18)
B22: 9 | C22: =IF('INPUT DATA'!L19="","",'INPUT DATA'!L19)
B23: 10 | C23: =IF('INPUT DATA'!L20="","",'INPUT DATA'!L20)
B24: 11 | C24: =IF('INPUT DATA'!L21="","",'INPUT DATA'!L21)
B25: 12 | C25: =IF('INPUT DATA'!L22="","",'INPUT DATA'!L22)
... B63: 50 | C63: =IF('INPUT DATA'!L60="","",'INPUT DATA'!L60)
B64: FEMALE
B65: 1 | C65: =IF('INPUT DATA'!Q11="","",'INPUT DATA'!Q11) | F65: 15 | G65: 20 | H65: 20 | I65: 20 | J65: 17 | K65: 20 | L65: 20 | M65: 18 | N65: 18 | O65: 20 | P65: 2
B66: 2 | C66: =IF('INPUT DATA'!Q12="","",'INPUT DATA'!Q12) | F66: 20 | G66: 16 | H66: 20 | I66: 19 | J66: 20 | K66: 20 | L66: 20 | M66: 18 | N66: 18 | O66: 20 | P66: 5
B67: 3 | C67: =IF('INPUT DATA'!Q13="","",'INPUT DATA'!Q13) | F67: 18 | G67: 20 | H67: 20 | I67: 20 | J67: 20 | K67: 19 | L67: 20 | M67: 18 | N67: 18 | O67: 20 | P67: 3
B68: 4 | C68: =IF('INPUT DATA'!Q14="","",'INPUT DATA'!Q14)
B69: 5 | C69: =IF('INPUT DATA'!Q15="","",'INPUT DATA'!Q15)
B70: 6 | C70: =IF('INPUT DATA'!Q16="","",'INPUT DATA'!Q16)
B71: 7 | C71: =IF('INPUT DATA'!Q17="","",'INPUT DATA'!Q17)
B72: 8 | C72: =IF('INPUT DATA'!Q18="","",'INPUT DATA'!Q18)
B73: 9 | C73: =IF('INPUT DATA'!Q19="","",'INPUT DATA'!Q19)
B74: 10 | C74: =IF('INPUT DATA'!Q20="","",'INPUT DATA'!Q20)
B75: 11 | C75: =IF('INPUT DATA'!Q21="","",'INPUT DATA'!Q21)
B76: 12 | C76: =IF('INPUT DATA'!Q22="","",'INPUT DATA'!Q22)
B77: 13 | C77: =IF('INPUT DATA'!Q23="","",'INPUT DATA'!Q23)
B78: 14 | C78: =IF('INPUT DATA'!Q24="","",'INPUT DATA'!Q24)
B79: 15 | C79: =IF('INPUT DATA'!Q25="","",'INPUT DATA'!Q25)
... B114: 50 | C114: =IF('INPUT DATA'!Q60="","",'INPUT DATA'!Q60)
B116: TOTAL NUMBER OF SCHOOL DAYS | E116: TOTAL | F116: JUN | G116: JUL | H116: AUG | I116: SEP | J116: OCT | K116: NOV | L116: DEC | M116: JAN | N116: FEB | O116: MAR | P116: APR
E117: =SUM(F117:P117) -> 201 | F117: 20 | G117: 20 | H117: 20 | I117: 20 | J117: 20 | K117: 20 | L117: 20 | M117: 18 | N117: 18 | O117: 20 | P117: 5
