Workbook
Name PERFORMANCETASKS: #REF!
Name PT: #REF!
Name QA: #REF!
Name QUARTERLYASSESSMENT: #REF!
Name SUBJECTS: '[1]INPUT DATA'!$A$1002:$A$1005
Name Transmu_Table: #REF!
Name WRITTENWORKS: #REF!
Name WW: #REF!

Sheet INSTRUCTIONS
B2: Exclusively for K to 12 Senior High School Grade 12
B3: Instructions: Accomplishing the Electronic Class Record (ECR) for SHS Grade 12
C7: 1 | D7: Input the correct data for the following sections. Any details entered here are used throughout the e-Class Record.
E9: This template is intended exclusively for SHS Grade 12 of the existing K-12 Curriculum.
M11: SCHOOL INFO
C12: SCHOOL INFO
C13: 1 | D13: Select the Region where the school is located | K13: → | N13: REGION | S13: :
C14: 2 | D14: Input the respective Schools Division Office | K14: → | N14: DIVISION | S14: :
C16: 3 | D16: Enter the six (6) digit school ID | K16: → | N16: SCHOOL ID | S16: :
C17: 4 | D17: Enter the name of the school | K17: → | N17: SCHOOL NAME | S17: :
C18: 5 | D18: Enter the current school year | K18: → | N18: SCHOOL YEAR | S18: : | T18: 2026 – 2027
D19: Upon donwload of this ECR, the School Year (2026–2027) is already pre-filled. This cannot be updated.
M21: TEACHER, GRADE LEVEL, AND SUBJECT AREA INFO
C22: TEACHER, GRADE LEVEL, AND SUBJECT AREA INFO
C23: 6 | D23: Enter teacher's name. | K23: → | N23: TEACHER | S23: :
C24: 7 | D24: Input the grade level taught. This field only accepts 11 or 12. | K24: → | N24: GRADE LEVEL | S24: : | T24: 12
C25: 8 | D25: Enter section name. | K25: → | N25: SECTION NAME | S25: :
D26: Indicate "Various Sections" if the class is composed of learners from different sections.
C27: 9 | D27: Select a Subject Track: | N27: K-12 CURRICULUM
E28: CORE SUBJECT (ALL TRACKS) | G28: WORK IMMERSION/ CULMINATING ACTIVITY | N28: SUBJECT CATEGORY | S28: : | T28: SHS
E29: ACADEMIC TRACK (EXCEPT IMMERSION) | G29: TVL/ SPORTS/ ARTS AND DESIGN TRACK | K29: → | N29: TRACK | S29: :
C30: 10 | D30: Type the SUBJECT. | K30: → | N30: SUBJECT | S30: :
D31: Take note of the TRACK. You must select the proper track to get the correct percentage of WW, PT, and TE of your subject.
C33: 11 | D33: Type the number of terms the subject is taught: 1, 2, or 3. | K33: → | N33: NO. OF TERMS | S33: : | U33: Term Blk:
D34: For electives offered for one or two terms, indicate the "Term Block." Data may only be encoded in the sheet corresponding to the selected term. For electives offered for two terms, indicate the first term in which the elective is offered. The succeeding term will automatically be displayed. | K34: → | U34: Term Blk:
D38: A helper notification will display next to the No. of Terms Taught indicating how many Term sheets need to be accomplished.
C41: LEARNERS' NAMES | M41: LEARNERS' NAMES
C42: 12 | D42: Either manually type the learners' LRNs and names or copy from SF1 and paste onto their respective columns (Male or Female).
K43: → | N43: MALE | T43: FEMALE
C44: 13 | D44: Up to 50 learners per group (Male/Female) may be entered. Ensure that the actual class size does not exceed the prescribed maximum class size. | K44: → | N44: 1 | O44: LRN | Q44: Name | T44: 1 | U44: LRN | W44: Name
N45: 2 | T45: 2
D46: TIPS: | N46: 3 | T46: 3
D47: Press Control + Shift + V to paste values only. | N47: ↓ | T47: ↓
D48: In cases where multiple sections are handled in one class, the corresponding section may be indicated in the row immediately preceding the learners’ names, provided that sufficient rows are available. Color coding may also be used to group learners accordingly. | N48: 50 | T48: 50
L51: INSTRUCTIONS | P51: INPUT DATA | U51: Term 1 | W51: Term 2 | Y51: Term 3
C56: 2 | D56: Input the raw scores per Summative Assessment component to compute for the term grades and final grades.
C67: SUMMATIVE ASSESSMENT SCORES | M67: IMPORTANT!
C68: 1 | D68: Select the appropriate sheet for the term (Term 1, Term 2, and/or Term 3).
D69: If the subject is taught for only one or two terms, accomplish only the corresponding sheets for these terms. If the subject is taught across three terms, accomplish all Term sheets. | O69: Blank white cells | S69: Cells where the highest possible scores and actual scores should be entered.
C71: 2 | D71: Check whether the details entered in the INPUT sheet are captured correctly. | O71: Gray cells | S71: Non-editable cells; no values should be entered.
...

Sheet INPUT DATA
D2: Exclusively for K to 12 Senior High School - Grade 12
D3: Input Data Sheet for Electronic Class Record (ECR)
D4: Pursuant to DepEd Order No. 8, s. 2015 and DepEd Order No. 15, s. 2026
B7: SCHOOL INFO | L7: LEARNERS' NAMES
C10: REGION | E10: : | F10: CAR | N10: LRN | O10: MALE LEARNERS (Last, First Middle) | R10: LRN | S10: FEMALE LEARNERS (Last, First Middle)
C11: DIVISION | E11: : | M11: 1 | Q11: 1
M12: 2 | Q12: 2
C13: SCHOOL ID | E13: : | M13: 3 | Q13: 3
C14: SCHOOL NAME | E14: : | M14: 4 | Q14: 4
M15: 5 | Q15: 5
C16: SCHOOL YEAR | E16: : | F16: 2026 | G16: =IF(F16>0, "– "& F16+1,"–") -> – 2027 | M16: 6 | Q16: 6
M17: 7 | Q17: 7
M18: 8 | Q18: 8
B19: TEACHER, GRADE LEVEL, AND SUBJECT AREA INFO | M19: 9 | Q19: 9
M20: 10 | Q20: 10
M21: 11 | Q21: 11
C22: TEACHER | E22: : | M22: 12 | Q22: 12
M23: 13 | Q23: 13
C24: GRADE LEVEL | E24: : | F24: 12 | M24: 14 | Q24: 14
C25: SECTION NAME | E25: : | M25: 15 | Q25: 15
M26: 16 | Q26: 16
C27: K-12 CURRICULUM | M27: 17 | Q27: 17
C28: SUBJECT CATEGORY | E28: : | F28: SHS | M28: 18 | Q28: 18
C29: TRACK | E29: : | F29: ACADEMIC TRACK (EXCEPT IMMERSION) | M29: 19 | Q29: 19
C30: SUBJECT | E30: : | F30: Title | M30: 20 | Q30: 20
M31: 21 | Q31: 21
M32: 22 | Q32: 22
C33: NO. TERMS TAUGHT | E33: : | F33: 2 | G33: Term Blk | H33: FIRST TERM | I33: =_xlfn.IFNA(IF(F33="","",IF(F33=3,3,_xlfn.XLOOKUP(H33,HELPER!$G$31:$G$33,HELPER!$F$31:$F$33))),"") -> 1 | M33: 23 | Q33: 23
C34: =_xlfn.IFNA(_xlfn.XLOOKUP('INPUT DATA'!F33,HELPER!$F$24:$F$26,HELPER!$G$24:$G$26),"") -> Notes: Accomplish TWO (2) term sheets. 2-term electives cannot begin in Term 3. | G34: Term Blk | H34: =IFERROR(IF(F33=2,_xlfn.XLOOKUP(I33+1,HELPER!$F$31:$F$34,HELPER!$G$31:$G$34),""),"") -> SECOND TERM | I34: =IF(HELPER!G21=1,(F33&I33)*1,"") -> 21 | M34: 24 | Q34: 24
M35: 25 | Q35: 25
M36: 26 | Q36: 26
M37: 27 | Q37: 27
D38: If the subject is taught for only one or two terms, accomplish only the corresponding sheets for the terms. If the subject is taught across three terms, accomplish all Term sheets. | M38: 28 | Q38: 28
M39: 29 | Q39: 29
M40: 30 | Q40: 30
M41: 31 | Q41: 31
M42: 32 | Q42: 32
M43: 33 | Q43: 33
M44: 34 | Q44: 34
M45: 35 | Q45: 35
...

Sheet Term 1
B2: Senior High School Class Record
B3: (Pursuant to DepEd Order No. 8, s. 2015 and DepEd Order No. 15, s. 2026)
G6: REGION | H6: =UPPER('INPUT DATA'!F10) -> CAR | O6: DIVISION | P6: =UPPER('INPUT DATA'!F11) | Z6: SCHOOL ID | AA6: =IF('INPUT DATA'!F13="","",'INPUT DATA'!F13)
G7: SCHOOL NAME | H7: =UPPER('INPUT DATA'!F14) | Z7: SCHOOL YEAR | AA7: ='INPUT DATA'!F16&" "&'INPUT DATA'!G16 -> 2026 – 2027
B8: =IF(OR(HELPER!G23="1ST",HELPER!G23="1ST & 2ND",HELPER!G23="1ST, 2ND, 3RD"),"","INCORRECT SHEET. Do not use this sheet to input data.")
B9: FIRST TERM | D9: GRADE LEVEL | H9: =IFERROR(IF(B8<>"INCORRECT SHEET. Do not use this sheet to input data.",'INPUT DATA'!F24,""),"") -> 12 | J9: SECTION | N9: =IFERROR(IF(B8<>"INCORRECT SHEET. Do not use this sheet to input data.",UPPER('INPUT DATA'!F25),""),"") | Q9: SUBJECT | U9: =IFERROR(IF(B8<>"INCORRECT SHEET. Do not use this sheet to input data.",UPPER(HELPER!G10),""),"") -> TITLE
D10: TEACHER | H10: =IFERROR(IF(B8<>"INCORRECT SHEET. Do not use this sheet to input data.",UPPER('INPUT DATA'!F22),""),"") | Q10: CLUSTER | U10: =IFERROR(IF(B8<>"INCORRECT SHEET. Do not use this sheet to input data.",UPPER(HELPER!G9),""),"") -> ACADEMIC TRACK (EXCEPT IMMERSION)
D11: WRITTEN / ORAL WORKS | Q11: PRODUCT / PERFORMANCE TASKS | AD11: TERM EXAM | AG11: INITIAL GRADE | AH11: TERM GRADE
D12: =IF($U$9<>"",IFERROR(_xlfn.IFNA(HELPER!G13/100,""),""),"") -> 0.25 | Q12: =IF($U$9<>"",IFERROR(_xlfn.IFNA(HELPER!G14/100,""),""),"") -> 0.45 | AD12: =IF($U$9<>"",IFERROR(_xlfn.IFNA(HELPER!G15/100,""),""),"") -> 0.3
D13: 1 | E13: 2 | F13: 3 | G13: 4 | H13: 5 | I13: 6 | J13: 7 | K13: 8 | L13: 9 | M13: 10 | N13: TOTAL | O13: PS | P13: WS | Q13: 1 | R13: 2 | S13: 3 | T13: 4 | U13: 5 | V13: 6 | W13: 7 | X13: 8 | Y13: 9 | Z13: 10 | AA13: TOTAL | AB13: PS | AC13: WS | AD13: TE | AE13: PS | AF13: WS
B14: HIGHEST POSSIBLE SCORE | N14: =SUM(D14:M14) -> 0 | O14: 100 | P14: =D12 -> 0.25 | AA14: =SUM(Q14:Z14) -> 0 | AB14: 100 | AC14: =Q12 -> 0.45 | AE14: =IF(AD12=0,"",100) -> 100 | AF14: =AD12 -> 0.3
B15: LEARNERS' NAMES
B16: MALE
B17: 1 | C17: =IFERROR(IF(OR($B$8="INCORRECT SHEET. Do not use this sheet to input data.",'INPUT DATA'!O11=""),"",'INPUT DATA'!O11),"") | N17: =IF(COUNT(D17:M17)=0,"",SUM(D17:M17)) | O17: =IFERROR(IF(N17="","",ROUND(N17/N$14*O$14,2)),"") | P17: =IFERROR(IF(O17="","",ROUND(O17*P$14,2)),"") | AA17: =IF(COUNT(Q17:Z17)=0,"",SUM(Q17:Z17)) | AB17: =IFERROR(IF(AA17="","",ROUND(AA17/AA$14*AB$14,2)),"") | AC17: =IFERROR(IF(AB17="","",ROUND(AB17*AC$14,2)),"") | AE17: =IFERROR(IF(AD17="","",ROUND(AD17/$AD$14,2)*100),"") | AF17: =IFERROR(IF(AE17="","",ROUND(AE17*$AF$14,2)),"") | AG17: =IF(AND(C17<>"",P17<>"",AC17<>"",$AD$12=0),SUM(P17,AC17),IF(AND(C17<>"",P17<>"",AC17<>"",AF17<>"",$D$12>0,$Q$12>0,$AD$12>0),SUM(P17,AC17,AF17),"")) | AH17: =IFERROR(_xlfn.XLOOKUP(AG17,HELPER!$C$7:$C$47,HELPER!$D$7:$D$47,,1),"")
B18: 2 | C18: =IFERROR(IF(OR($B$8="INCORRECT SHEET. Do not use this sheet to input data.",'INPUT DATA'!O12=""),"",'INPUT DATA'!O12),"") | N18: =IF(COUNT(D18:M18)=0,"",SUM(D18:M18)) | O18: =IFERROR(IF(N18="","",ROUND(N18/N$14*O$14,2)),"") | P18: =IFERROR(IF(O18="","",ROUND(O18*P$14,2)),"") | AA18: =IF(COUNT(Q18:Z18)=0,"",SUM(Q18:Z18)) | AB18: =IFERROR(IF(AA18="","",ROUND(AA18/AA$14*AB$14,2)),"") | AC18: =IFERROR(IF(AB18="","",ROUND(AB18*AC$14,2)),"") | AE18: =IFERROR(IF(AD18="","",ROUND(AD18/$AD$14,2)*100),"") | AF18: =IFERROR(IF(AE18="","",ROUND(AE18*$AF$14,2)),"") | AG18: =IF(AND(C18<>"",P18<>"",AC18<>"",$AD$12=0),SUM(P18,AC18),IF(AND(C18<>"",P18<>"",AC18<>"",AF18<>"",$D$12>0,$Q$12>0,$AD$12>0),SUM(P18,AC18,AF18),"")) | AH18: =IFERROR(_xlfn.XLOOKUP(AG18,HELPER!$C$7:$C$47,HELPER!$D$7:$D$47,,1),"")
B19: 3 | C19: =IFERROR(IF(OR($B$8="INCORRECT SHEET. Do not use this sheet to input data.",'INPUT DATA'!O13=""),"",'INPUT DATA'!O13),"") | N19: =IF(COUNT(D19:M19)=0,"",SUM(D19:M19)) | O19: =IFERROR(IF(N19="","",ROUND(N19/N$14*O$14,2)),"") | P19: =IFERROR(IF(O19="","",ROUND(O19*P$14,2)),"") | AA19: =IF(COUNT(Q19:Z19)=0,"",SUM(Q19:Z19)) | AB19: =IFERROR(IF(AA19="","",ROUND(AA19/AA$14*AB$14,2)),"") | AC19: =IFERROR(IF(AB19="","",ROUND(AB19*AC$14,2)),"") | AE19: =IFERROR(IF(AD19="","",ROUND(AD19/$AD$14,2)*100),"") | AF19: =IFERROR(IF(AE19="","",ROUND(AE19*$AF$14,2)),"") | AG19: =IF(AND(C19<>"",P19<>"",AC19<>"",$AD$12=0),SUM(P19,AC19),IF(AND(C19<>"",P19<>"",AC19<>"",AF19<>"",$D$12>0,$Q$12>0,$AD$12>0),SUM(P19,AC19,AF19),"")) | AH19: =IFERROR(_xlfn.XLOOKUP(AG19,HELPER!$C$7:$C$47,HELPER!$D$7:$D$47,,1),"")
B20: 4 | C20: =IFERROR(IF(OR($B$8="INCORRECT SHEET. Do not use this sheet to input data.",'INPUT DATA'!O14=""),"",'INPUT DATA'!O14),"") | N20: =IF(COUNT(D20:M20)=0,"",SUM(D20:M20)) | O20: =IFERROR(IF(N20="","",ROUND(N20/N$14*O$14,2)),"") | P20: =IFERROR(IF(O20="","",ROUND(O20*P$14,2)),"") | AA20: =IF(COUNT(Q20:Z20)=0,"",SUM(Q20:Z20)) | AB20: =IFERROR(IF(AA20="","",ROUND(AA20/AA$14*AB$14,2)),"") | AC20: =IFERROR(IF(AB20="","",ROUND(AB20*AC$14,2)),"") | AE20: =IFERROR(IF(AD20="","",ROUND(AD20/$AD$14,2)*100),"") | AF20: =IFERROR(IF(AE20="","",ROUND(AE20*$AF$14,2)),"") | AG20: =IF(AND(C20<>"",P20<>"",AC20<>"",$AD$12=0),SUM(P20,AC20),IF(AND(C20<>"",P20<>"",AC20<>"",AF20<>"",$D$12>0,$Q$12>0,$AD$12>0),SUM(P20,AC20,AF20),"")) | AH20: =IFERROR(_xlfn.XLOOKUP(AG20,HELPER!$C$7:$C$47,HELPER!$D$7:$D$47,,1),"")
B21: 5 | C21: =IFERROR(IF(OR($B$8="INCORRECT SHEET. Do not use this sheet to input data.",'INPUT DATA'!O15=""),"",'INPUT DATA'!O15),"") | N21: =IF(COUNT(D21:M21)=0,"",SUM(D21:M21)) | O21: =IFERROR(IF(N21="","",ROUND(N21/N$14*O$14,2)),"") | P21: =IFERROR(IF(O21="","",ROUND(O21*P$14,2)),"") | AA21: =IF(COUNT(Q21:Z21)=0,"",SUM(Q21:Z21)) | AB21: =IFERROR(IF(AA21="","",ROUND(AA21/AA$14*AB$14,2)),"") | AC21: =IFERROR(IF(AB21="","",ROUND(AB21*AC$14,2)),"") | AE21: =IFERROR(IF(AD21="","",ROUND(AD21/$AD$14,2)*100),"") | AF21: =IFERROR(IF(AE21="","",ROUND(AE21*$AF$14,2)),"") | AG21: =IF(AND(C21<>"",P21<>"",AC21<>"",$AD$12=0),SUM(P21,AC21),IF(AND(C21<>"",P21<>"",AC21<>"",AF21<>"",$D$12>0,$Q$12>0,$AD$12>0),SUM(P21,AC21,AF21),"")) | AH21: =IFERROR(_xlfn.XLOOKUP(AG21,HELPER!$C$7:$C$47,HELPER!$D$7:$D$47,,1),"")
B22: 6 | C22: =IFERROR(IF(OR($B$8="INCORRECT SHEET. Do not use this sheet to input data.",'INPUT DATA'!O16=""),"",'INPUT DATA'!O16),"") | N22: =IF(COUNT(D22:M22)=0,"",SUM(D22:M22)) | O22: =IFERROR(IF(N22="","",ROUND(N22/N$14*O$14,2)),"") | P22: =IFERROR(IF(O22="","",ROUND(O22*P$14,2)),"") | AA22: =IF(COUNT(Q22:Z22)=0,"",SUM(Q22:Z22)) | AB22: =IFERROR(IF(AA22="","",ROUND(AA22/AA$14*AB$14,2)),"") | AC22: =IFERROR(IF(AB22="","",ROUND(AB22*AC$14,2)),"") | AE22: =IFERROR(IF(AD22="","",ROUND(AD22/$AD$14,2)*100),"") | AF22: =IFERROR(IF(AE22="","",ROUND(AE22*$AF$14,2)),"") | AG22: =IF(AND(C22<>"",P22<>"",AC22<>"",$AD$12=0),SUM(P22,AC22),IF(AND(C22<>"",P22<>"",AC22<>"",AF22<>"",$D$12>0,$Q$12>0,$AD$12>0),SUM(P22,AC22,AF22),"")) | AH22: =IFERROR(_xlfn.XLOOKUP(AG22,HELPER!$C$7:$C$47,HELPER!$D$7:$D$47,,1),"")
B23: 7 | C23: =IFERROR(IF(OR($B$8="INCORRECT SHEET. Do not use this sheet to input data.",'INPUT DATA'!O17=""),"",'INPUT DATA'!O17),"") | N23: =IF(COUNT(D23:M23)=0,"",SUM(D23:M23)) | O23: =IFERROR(IF(N23="","",ROUND(N23/N$14*O$14,2)),"") | P23: =IFERROR(IF(O23="","",ROUND(O23*P$14,2)),"") | AA23: =IF(COUNT(Q23:Z23)=0,"",SUM(Q23:Z23)) | AB23: =IFERROR(IF(AA23="","",ROUND(AA23/AA$14*AB$14,2)),"") | AC23: =IFERROR(IF(AB23="","",ROUND(AB23*AC$14,2)),"") | AE23: =IFERROR(IF(AD23="","",ROUND(AD23/$AD$14,2)*100),"") | AF23: =IFERROR(IF(AE23="","",ROUND(AE23*$AF$14,2)),"") | AG23: =IF(AND(C23<>"",P23<>"",AC23<>"",$AD$12=0),SUM(P23,AC23),IF(AND(C23<>"",P23<>"",AC23<>"",AF23<>"",$D$12>0,$Q$12>0,$AD$12>0),SUM(P23,AC23,AF23),"")) | AH23: =IFERROR(_xlfn.XLOOKUP(AG23,HELPER!$C$7:$C$47,HELPER!$D$7:$D$47,,1),"")
B24: 8 | C24: =IFERROR(IF(OR($B$8="INCORRECT SHEET. Do not use this sheet to input data.",'INPUT DATA'!O18=""),"",'INPUT DATA'!O18),"") | N24: =IF(COUNT(D24:M24)=0,"",SUM(D24:M24)) | O24: =IFERROR(IF(N24="","",ROUND(N24/N$14*O$14,2)),"") | P24: =IFERROR(IF(O24="","",ROUND(O24*P$14,2)),"") | AA24: =IF(COUNT(Q24:Z24)=0,"",SUM(Q24:Z24)) | AB24: =IFERROR(IF(AA24="","",ROUND(AA24/AA$14*AB$14,2)),"") | AC24: =IFERROR(IF(AB24="","",ROUND(AB24*AC$14,2)),"") | AE24: =IFERROR(IF(AD24="","",ROUND(AD24/$AD$14,2)*100),"") | AF24: =IFERROR(IF(AE24="","",ROUND(AE24*$AF$14,2)),"") | AG24: =IF(AND(C24<>"",P24<>"",AC24<>"",$AD$12=0),SUM(P24,AC24),IF(AND(C24<>"",P24<>"",AC24<>"",AF24<>"",$D$12>0,$Q$12>0,$AD$12>0),SUM(P24,AC24,AF24),"")) | AH24: =IFERROR(_xlfn.XLOOKUP(AG24,HELPER!$C$7:$C$47,HELPER!$D$7:$D$47,,1),"")
B25: 9 | C25: =IFERROR(IF(OR($B$8="INCORRECT SHEET. Do not use this sheet to input data.",'INPUT DATA'!O19=""),"",'INPUT DATA'!O19),"") | N25: =IF(COUNT(D25:M25)=0,"",SUM(D25:M25)) | O25: =IFERROR(IF(N25="","",ROUND(N25/N$14*O$14,2)),"") | P25: =IFERROR(IF(O25="","",ROUND(O25*P$14,2)),"") | AA25: =IF(COUNT(Q25:Z25)=0,"",SUM(Q25:Z25)) | AB25: =IFERROR(IF(AA25="","",ROUND(AA25/AA$14*AB$14,2)),"") | AC25: =IFERROR(IF(AB25="","",ROUND(AB25*AC$14,2)),"") | AE25: =IFERROR(IF(AD25="","",ROUND(AD25/$AD$14,2)*100),"") | AF25: =IFERROR(IF(AE25="","",ROUND(AE25*$AF$14,2)),"") | AG25: =IF(AND(C25<>"",P25<>"",AC25<>"",$AD$12=0),SUM(P25,AC25),IF(AND(C25<>"",P25<>"",AC25<>"",AF25<>"",$D$12>0,$Q$12>0,$AD$12>0),SUM(P25,AC25,AF25),"")) | AH25: =IFERROR(_xlfn.XLOOKUP(AG25,HELPER!$C$7:$C$47,HELPER!$D$7:$D$47,,1),"")
B26: 10 | C26: =IFERROR(IF(OR($B$8="INCORRECT SHEET. Do not use this sheet to input data.",'INPUT DATA'!O20=""),"",'INPUT DATA'!O20),"") | N26: =IF(COUNT(D26:M26)=0,"",SUM(D26:M26)) | O26: =IFERROR(IF(N26="","",ROUND(N26/N$14*O$14,2)),"") | P26: =IFERROR(IF(O26="","",ROUND(O26*P$14,2)),"") | AA26: =IF(COUNT(Q26:Z26)=0,"",SUM(Q26:Z26)) | AB26: =IFERROR(IF(AA26="","",ROUND(AA26/AA$14*AB$14,2)),"") | AC26: =IFERROR(IF(AB26="","",ROUND(AB26*AC$14,2)),"") | AE26: =IFERROR(IF(AD26="","",ROUND(AD26/$AD$14,2)*100),"") | AF26: =IFERROR(IF(AE26="","",ROUND(AE26*$AF$14,2)),"") | AG26: =IF(AND(C26<>"",P26<>"",AC26<>"",$AD$12=0),SUM(P26,AC26),IF(AND(C26<>"",P26<>"",AC26<>"",AF26<>"",$D$12>0,$Q$12>0,$AD$12>0),SUM(P26,AC26,AF26),"")) | AH26: =IFERROR(_xlfn.XLOOKUP(AG26,HELPER!$C$7:$C$47,HELPER!$D$7:$D$47,,1),"")
B27: 11 | C27: =IFERROR(IF(OR($B$8="INCORRECT SHEET. Do not use this sheet to input data.",'INPUT DATA'!O21=""),"",'INPUT DATA'!O21),"") | N27: =IF(COUNT(D27:M27)=0,"",SUM(D27:M27)) | O27: =IFERROR(IF(N27="","",ROUND(N27/N$14*O$14,2)),"") | P27: =IFERROR(IF(O27="","",ROUND(O27*P$14,2)),"") | AA27: =IF(COUNT(Q27:Z27)=0,"",SUM(Q27:Z27)) | AB27: =IFERROR(IF(AA27="","",ROUND(AA27/AA$14*AB$14,2)),"") | AC27: =IFERROR(IF(AB27="","",ROUND(AB27*AC$14,2)),"") | AE27: =IFERROR(IF(AD27="","",ROUND(AD27/$AD$14,2)*100),"") | AF27: =IFERROR(IF(AE27="","",ROUND(AE27*$AF$14,2)),"") | AG27: =IF(AND(C27<>"",P27<>"",AC27<>"",$AD$12=0),SUM(P27,AC27),IF(AND(C27<>"",P27<>"",AC27<>"",AF27<>"",$D$12>0,$Q$12>0,$AD$12>0),SUM(P27,AC27,AF27),"")) | AH27: =IFERROR(_xlfn.XLOOKUP(AG27,HELPER!$C$7:$C$47,HELPER!$D$7:$D$47,,1),"")
B28: 12 | C28: =IFERROR(IF(OR($B$8="INCORRECT SHEET. Do not use this sheet to input data.",'INPUT DATA'!O22=""),"",'INPUT DATA'!O22),"") | N28: =IF(COUNT(D28:M28)=0,"",SUM(D28:M28)) | O28: =IFERROR(IF(N28="","",ROUND(N28/N$14*O$14,2)),"") | P28: =IFERROR(IF(O28="","",ROUND(O28*P$14,2)),"") | AA28: =IF(COUNT(Q28:Z28)=0,"",SUM(Q28:Z28)) | AB28: =IFERROR(IF(AA28="","",ROUND(AA28/AA$14*AB$14,2)),"") | AC28: =IFERROR(IF(AB28="","",ROUND(AB28*AC$14,2)),"") | AE28: =IFERROR(IF(AD28="","",ROUND(AD28/$AD$14,2)*100),"") | AF28: =IFERROR(IF(AE28="","",ROUND(AE28*$AF$14,2)),"") | AG28: =IF(AND(C28<>"",P28<>"",AC28<>"",$AD$12=0),SUM(P28,AC28),IF(AND(C28<>"",P28<>"",AC28<>"",AF28<>"",$D$12>0,$Q$12>0,$AD$12>0),SUM(P28,AC28,AF28),"")) | AH28: =IFERROR(_xlfn.XLOOKUP(AG28,HELPER!$C$7:$C$47,HELPER!$D$7:$D$47,,1),"")
... B66: 50 | C66: =IFERROR(IF(OR($B$8="INCORRECT SHEET. Do not use this sheet to input data.",'INPUT DATA'!O60=""),"",'INPUT DATA'!O60),"") | N66: =IF(COUNT(D66:M66)=0,"",SUM(D66:M66)) | O66: =IFERROR(IF(N66="","",ROUND(N66/N$14*O$14,2)),"") | P66: =IFERROR(IF(O66="","",ROUND(O66*P$14,2)),"") | AA66: =IF(COUNT(Q66:Z66)=0,"",SUM(Q66:Z66)) | AB66: =IFERROR(IF(AA66="","",ROUND(AA66/AA$14*AB$14,2)),"") | AC66: =IFERROR(IF(AB66="","",ROUND(AB66*AC$14,2)),"") | AE66: =IFERROR(IF(AD66="","",ROUND(AD66/$AD$14,2)*100),"") | AF66: =IFERROR(IF(AE66="","",ROUND(AE66*$AF$14,2)),"") | AG66: =IF(AND(C66<>"",P66<>"",AC66<>"",$AD$12=0),SUM(P66,AC66),IF(AND(C66<>"",P66<>"",AC66<>"",AF66<>"",$D$12>0,$Q$12>0,$AD$12>0),SUM(P66,AC66,AF66),"")) | AH66: =IFERROR(_xlfn.XLOOKUP(AG66,HELPER!$C$7:$C$47,HELPER!$D$7:$D$47,,1),"")
B67: FEMALE
B68: 1 | C68: =IFERROR(IF(OR($B$8="INCORRECT SHEET. Do not use this sheet to input data.",'INPUT DATA'!S11=""),"",'INPUT DATA'!S11),"") | N68: =IF(COUNT(D68:M68)=0,"",SUM(D68:M68)) | O68: =IFERROR(IF(N68="","",ROUND(N68/N$14*O$14,2)),"") | P68: =IFERROR(IF(O68="","",ROUND(O68*P$14,2)),"") | AA68: =IF(COUNT(Q68:Z68)=0,"",SUM(Q68:Z68)) | AB68: =IFERROR(IF(AA68="","",ROUND(AA68/AA$14*AB$14,2)),"") | AC68: =IFERROR(IF(AB68="","",ROUND(AB68*AC$14,2)),"") | AE68: =IFERROR(IF(AD68="","",ROUND(AD68/$AD$14,2)*100),"") | AF68: =IFERROR(IF(AE68="","",ROUND(AE68*$AF$14,2)),"") | AG68: =IF(AND(C68<>"",P68<>"",AC68<>"",$AD$12=0),SUM(P68,AC68),IF(AND(C68<>"",P68<>"",AC68<>"",AF68<>"",$D$12>0,$Q$12>0,$AD$12>0),SUM(P68,AC68,AF68),"")) | AH68: =IFERROR(_xlfn.XLOOKUP(AG68,HELPER!$C$7:$C$47,HELPER!$D$7:$D$47,,1),"")
B69: 2 | C69: =IFERROR(IF(OR($B$8="INCORRECT SHEET. Do not use this sheet to input data.",'INPUT DATA'!S12=""),"",'INPUT DATA'!S12),"") | N69: =IF(COUNT(D69:M69)=0,"",SUM(D69:M69)) | O69: =IFERROR(IF(N69="","",ROUND(N69/N$14*O$14,2)),"") | P69: =IFERROR(IF(O69="","",ROUND(O69*P$14,2)),"") | AA69: =IF(COUNT(Q69:Z69)=0,"",SUM(Q69:Z69)) | AB69: =IFERROR(IF(AA69="","",ROUND(AA69/AA$14*AB$14,2)),"") | AC69: =IFERROR(IF(AB69="","",ROUND(AB69*AC$14,2)),"") | AE69: =IFERROR(IF(AD69="","",ROUND(AD69/$AD$14,2)*100),"") | AF69: =IFERROR(IF(AE69="","",ROUND(AE69*$AF$14,2)),"") | AG69: =IF(AND(C69<>"",P69<>"",AC69<>"",$AD$12=0),SUM(P69,AC69),IF(AND(C69<>"",P69<>"",AC69<>"",AF69<>"",$D$12>0,$Q$12>0,$AD$12>0),SUM(P69,AC69,AF69),"")) | AH69: =IFERROR(_xlfn.XLOOKUP(AG69,HELPER!$C$7:$C$47,HELPER!$D$7:$D$47,,1),"")
B70: 3 | C70: =IFERROR(IF(OR($B$8="INCORRECT SHEET. Do not use this sheet to input data.",'INPUT DATA'!S13=""),"",'INPUT DATA'!S13),"") | N70: =IF(COUNT(D70:M70)=0,"",SUM(D70:M70)) | O70: =IFERROR(IF(N70="","",ROUND(N70/N$14*O$14,2)),"") | P70: =IFERROR(IF(O70="","",ROUND(O70*P$14,2)),"") | AA70: =IF(COUNT(Q70:Z70)=0,"",SUM(Q70:Z70)) | AB70: =IFERROR(IF(AA70="","",ROUND(AA70/AA$14*AB$14,2)),"") | AC70: =IFERROR(IF(AB70="","",ROUND(AB70*AC$14,2)),"") | AE70: =IFERROR(IF(AD70="","",ROUND(AD70/$AD$14,2)*100),"") | AF70: =IFERROR(IF(AE70="","",ROUND(AE70*$AF$14,2)),"") | AG70: =IF(AND(C70<>"",P70<>"",AC70<>"",$AD$12=0),SUM(P70,AC70),IF(AND(C70<>"",P70<>"",AC70<>"",AF70<>"",$D$12>0,$Q$12>0,$AD$12>0),SUM(P70,AC70,AF70),"")) | AH70: =IFERROR(_xlfn.XLOOKUP(AG70,HELPER!$C$7:$C$47,HELPER!$D$7:$D$47,,1),"")
B71: 4 | C71: =IFERROR(IF(OR($B$8="INCORRECT SHEET. Do not use this sheet to input data.",'INPUT DATA'!S14=""),"",'INPUT DATA'!S14),"") | N71: =IF(COUNT(D71:M71)=0,"",SUM(D71:M71)) | O71: =IFERROR(IF(N71="","",ROUND(N71/N$14*O$14,2)),"") | P71: =IFERROR(IF(O71="","",ROUND(O71*P$14,2)),"") | AA71: =IF(COUNT(Q71:Z71)=0,"",SUM(Q71:Z71)) | AB71: =IFERROR(IF(AA71="","",ROUND(AA71/AA$14*AB$14,2)),"") | AC71: =IFERROR(IF(AB71="","",ROUND(AB71*AC$14,2)),"") | AE71: =IFERROR(IF(AD71="","",ROUND(AD71/$AD$14,2)*100),"") | AF71: =IFERROR(IF(AE71="","",ROUND(AE71*$AF$14,2)),"") | AG71: =IF(AND(C71<>"",P71<>"",AC71<>"",$AD$12=0),SUM(P71,AC71),IF(AND(C71<>"",P71<>"",AC71<>"",AF71<>"",$D$12>0,$Q$12>0,$AD$12>0),SUM(P71,AC71,AF71),"")) | AH71: =IFERROR(_xlfn.XLOOKUP(AG71,HELPER!$C$7:$C$47,HELPER!$D$7:$D$47,,1),"")
B72: 5 | C72: =IFERROR(IF(OR($B$8="INCORRECT SHEET. Do not use this sheet to input data.",'INPUT DATA'!S15=""),"",'INPUT DATA'!S15),"") | N72: =IF(COUNT(D72:M72)=0,"",SUM(D72:M72)) | O72: =IFERROR(IF(N72="","",ROUND(N72/N$14*O$14,2)),"") | P72: =IFERROR(IF(O72="","",ROUND(O72*P$14,2)),"") | AA72: =IF(COUNT(Q72:Z72)=0,"",SUM(Q72:Z72)) | AB72: =IFERROR(IF(AA72="","",ROUND(AA72/AA$14*AB$14,2)),"") | AC72: =IFERROR(IF(AB72="","",ROUND(AB72*AC$14,2)),"") | AE72: =IFERROR(IF(AD72="","",ROUND(AD72/$AD$14,2)*100),"") | AF72: =IFERROR(IF(AE72="","",ROUND(AE72*$AF$14,2)),"") | AG72: =IF(AND(C72<>"",P72<>"",AC72<>"",$AD$12=0),SUM(P72,AC72),IF(AND(C72<>"",P72<>"",AC72<>"",AF72<>"",$D$12>0,$Q$12>0,$AD$12>0),SUM(P72,AC72,AF72),"")) | AH72: =IFERROR(_xlfn.XLOOKUP(AG72,HELPER!$C$7:$C$47,HELPER!$D$7:$D$47,,1),"")
B73: 6 | C73: =IFERROR(IF(OR($B$8="INCORRECT SHEET. Do not use this sheet to input data.",'INPUT DATA'!S16=""),"",'INPUT DATA'!S16),"") | N73: =IF(COUNT(D73:M73)=0,"",SUM(D73:M73)) | O73: =IFERROR(IF(N73="","",ROUND(N73/N$14*O$14,2)),"") | P73: =IFERROR(IF(O73="","",ROUND(O73*P$14,2)),"") | AA73: =IF(COUNT(Q73:Z73)=0,"",SUM(Q73:Z73)) | AB73: =IFERROR(IF(AA73="","",ROUND(AA73/AA$14*AB$14,2)),"") | AC73: =IFERROR(IF(AB73="","",ROUND(AB73*AC$14,2)),"") | AE73: =IFERROR(IF(AD73="","",ROUND(AD73/$AD$14,2)*100),"") | AF73: =IFERROR(IF(AE73="","",ROUND(AE73*$AF$14,2)),"") | AG73: =IF(AND(C73<>"",P73<>"",AC73<>"",$AD$12=0),SUM(P73,AC73),IF(AND(C73<>"",P73<>"",AC73<>"",AF73<>"",$D$12>0,$Q$12>0,$AD$12>0),SUM(P73,AC73,AF73),"")) | AH73: =IFERROR(_xlfn.XLOOKUP(AG73,HELPER!$C$7:$C$47,HELPER!$D$7:$D$47,,1),"")
B74: 7 | C74: =IFERROR(IF(OR($B$8="INCORRECT SHEET. Do not use this sheet to input data.",'INPUT DATA'!S17=""),"",'INPUT DATA'!S17),"") | N74: =IF(COUNT(D74:M74)=0,"",SUM(D74:M74)) | O74: =IFERROR(IF(N74="","",ROUND(N74/N$14*O$14,2)),"") | P74: =IFERROR(IF(O74="","",ROUND(O74*P$14,2)),"") | AA74: =IF(COUNT(Q74:Z74)=0,"",SUM(Q74:Z74)) | AB74: =IFERROR(IF(AA74="","",ROUND(AA74/AA$14*AB$14,2)),"") | AC74: =IFERROR(IF(AB74="","",ROUND(AB74*AC$14,2)),"") | AE74: =IFERROR(IF(AD74="","",ROUND(AD74/$AD$14,2)*100),"") | AF74: =IFERROR(IF(AE74="","",ROUND(AE74*$AF$14,2)),"") | AG74: =IF(AND(C74<>"",P74<>"",AC74<>"",$AD$12=0),SUM(P74,AC74),IF(AND(C74<>"",P74<>"",AC74<>"",AF74<>"",$D$12>0,$Q$12>0,$AD$12>0),SUM(P74,AC74,AF74),"")) | AH74: =IFERROR(_xlfn.XLOOKUP(AG74,HELPER!$C$7:$C$47,HELPER!$D$7:$D$47,,1),"")
B75: 8 | C75: =IFERROR(IF(OR($B$8="INCORRECT SHEET. Do not use this sheet to input data.",'INPUT DATA'!S18=""),"",'INPUT DATA'!S18),"") | N75: =IF(COUNT(D75:M75)=0,"",SUM(D75:M75)) | O75: =IFERROR(IF(N75="","",ROUND(N75/N$14*O$14,2)),"") | P75: =IFERROR(IF(O75="","",ROUND(O75*P$14,2)),"") | AA75: =IF(COUNT(Q75:Z75)=0,"",SUM(Q75:Z75)) | AB75: =IFERROR(IF(AA75="","",ROUND(AA75/AA$14*AB$14,2)),"") | AC75: =IFERROR(IF(AB75="","",ROUND(AB75*AC$14,2)),"") | AE75: =IFERROR(IF(AD75="","",ROUND(AD75/$AD$14,2)*100),"") | AF75: =IFERROR(IF(AE75="","",ROUND(AE75*$AF$14,2)),"") | AG75: =IF(AND(C75<>"",P75<>"",AC75<>"",$AD$12=0),SUM(P75,AC75),IF(AND(C75<>"",P75<>"",AC75<>"",AF75<>"",$D$12>0,$Q$12>0,$AD$12>0),SUM(P75,AC75,AF75),"")) | AH75: =IFERROR(_xlfn.XLOOKUP(AG75,HELPER!$C$7:$C$47,HELPER!$D$7:$D$47,,1),"")
B76: 9 | C76: =IFERROR(IF(OR($B$8="INCORRECT SHEET. Do not use this sheet to input data.",'INPUT DATA'!S19=""),"",'INPUT DATA'!S19),"") | N76: =IF(COUNT(D76:M76)=0,"",SUM(D76:M76)) | O76: =IFERROR(IF(N76="","",ROUND(N76/N$14*O$14,2)),"") | P76: =IFERROR(IF(O76="","",ROUND(O76*P$14,2)),"") | AA76: =IF(COUNT(Q76:Z76)=0,"",SUM(Q76:Z76)) | AB76: =IFERROR(IF(AA76="","",ROUND(AA76/AA$14*AB$14,2)),"") | AC76: =IFERROR(IF(AB76="","",ROUND(AB76*AC$14,2)),"") | AE76: =IFERROR(IF(AD76="","",ROUND(AD76/$AD$14,2)*100),"") | AF76: =IFERROR(IF(AE76="","",ROUND(AE76*$AF$14,2)),"") | AG76: =IF(AND(C76<>"",P76<>"",AC76<>"",$AD$12=0),SUM(P76,AC76),IF(AND(C76<>"",P76<>"",AC76<>"",AF76<>"",$D$12>0,$Q$12>0,$AD$12>0),SUM(P76,AC76,AF76),"")) | AH76: =IFERROR(_xlfn.XLOOKUP(AG76,HELPER!$C$7:$C$47,HELPER!$D$7:$D$47,,1),"")
B77: 10 | C77: =IFERROR(IF(OR($B$8="INCORRECT SHEET. Do not use this sheet to input data.",'INPUT DATA'!S20=""),"",'INPUT DATA'!S20),"") | N77: =IF(COUNT(D77:M77)=0,"",SUM(D77:M77)) | O77: =IFERROR(IF(N77="","",ROUND(N77/N$14*O$14,2)),"") | P77: =IFERROR(IF(O77="","",ROUND(O77*P$14,2)),"") | AA77: =IF(COUNT(Q77:Z77)=0,"",SUM(Q77:Z77)) | AB77: =IFERROR(IF(AA77="","",ROUND(AA77/AA$14*AB$14,2)),"") | AC77: =IFERROR(IF(AB77="","",ROUND(AB77*AC$14,2)),"") | AE77: =IFERROR(IF(AD77="","",ROUND(AD77/$AD$14,2)*100),"") | AF77: =IFERROR(IF(AE77="","",ROUND(AE77*$AF$14,2)),"") | AG77: =IF(AND(C77<>"",P77<>"",AC77<>"",$AD$12=0),SUM(P77,AC77),IF(AND(C77<>"",P77<>"",AC77<>"",AF77<>"",$D$12>0,$Q$12>0,$AD$12>0),SUM(P77,AC77,AF77),"")) | AH77: =IFERROR(_xlfn.XLOOKUP(AG77,HELPER!$C$7:$C$47,HELPER!$D$7:$D$47,,1),"")
B78: 11 | C78: =IFERROR(IF(OR($B$8="INCORRECT SHEET. Do not use this sheet to input data.",'INPUT DATA'!S21=""),"",'INPUT DATA'!S21),"") | N78: =IF(COUNT(D78:M78)=0,"",SUM(D78:M78)) | O78: =IFERROR(IF(N78="","",ROUND(N78/N$14*O$14,2)),"") | P78: =IFERROR(IF(O78="","",ROUND(O78*P$14,2)),"") | AA78: =IF(COUNT(Q78:Z78)=0,"",SUM(Q78:Z78)) | AB78: =IFERROR(IF(AA78="","",ROUND(AA78/AA$14*AB$14,2)),"") | AC78: =IFERROR(IF(AB78="","",ROUND(AB78*AC$14,2)),"") | AE78: =IFERROR(IF(AD78="","",ROUND(AD78/$AD$14,2)*100),"") | AF78: =IFERROR(IF(AE78="","",ROUND(AE78*$AF$14,2)),"") | AG78: =IF(AND(C78<>"",P78<>"",AC78<>"",$AD$12=0),SUM(P78,AC78),IF(AND(C78<>"",P78<>"",AC78<>"",AF78<>"",$D$12>0,$Q$12>0,$AD$12>0),SUM(P78,AC78,AF78),"")) | AH78: =IFERROR(_xlfn.XLOOKUP(AG78,HELPER!$C$7:$C$47,HELPER!$D$7:$D$47,,1),"")
B79: 12 | C79: =IFERROR(IF(OR($B$8="INCORRECT SHEET. Do not use this sheet to input data.",'INPUT DATA'!S22=""),"",'INPUT DATA'!S22),"") | N79: =IF(COUNT(D79:M79)=0,"",SUM(D79:M79)) | O79: =IFERROR(IF(N79="","",ROUND(N79/N$14*O$14,2)),"") | P79: =IFERROR(IF(O79="","",ROUND(O79*P$14,2)),"") | AA79: =IF(COUNT(Q79:Z79)=0,"",SUM(Q79:Z79)) | AB79: =IFERROR(IF(AA79="","",ROUND(AA79/AA$14*AB$14,2)),"") | AC79: =IFERROR(IF(AB79="","",ROUND(AB79*AC$14,2)),"") | AE79: =IFERROR(IF(AD79="","",ROUND(AD79/$AD$14,2)*100),"") | AF79: =IFERROR(IF(AE79="","",ROUND(AE79*$AF$14,2)),"") | AG79: =IF(AND(C79<>"",P79<>"",AC79<>"",$AD$12=0),SUM(P79,AC79),IF(AND(C79<>"",P79<>"",AC79<>"",AF79<>"",$D$12>0,$Q$12>0,$AD$12>0),SUM(P79,AC79,AF79),"")) | AH79: =IFERROR(_xlfn.XLOOKUP(AG79,HELPER!$C$7:$C$47,HELPER!$D$7:$D$47,,1),"")
... B117: 50 | C117: =IFERROR(IF(OR($B$8="INCORRECT SHEET. Do not use this sheet to input data.",'INPUT DATA'!S60=""),"",'INPUT DATA'!S60),"") | N117: =IF(COUNT(D117:M117)=0,"",SUM(D117:M117)) | O117: =IFERROR(IF(N117="","",ROUND(N117/N$14*O$14,2)),"") | P117: =IFERROR(IF(O117="","",ROUND(O117*P$14,2)),"") | AA117: =IF(COUNT(Q117:Z117)=0,"",SUM(Q117:Z117)) | AB117: =IFERROR(IF(AA117="","",ROUND(AA117/AA$14*AB$14,2)),"") | AC117: =IFERROR(IF(AB117="","",ROUND(AB117*AC$14,2)),"") | AE117: =IFERROR(IF(AD117="","",ROUND(AD117/$AD$14,2)*100),"") | AF117: =IFERROR(IF(AE117="","",ROUND(AE117*$AF$14,2)),"") | AG117: =IF(AND(C117<>"",P117<>"",AC117<>"",$AD$12=0),SUM(P117,AC117),IF(AND(C117<>"",P117<>"",AC117<>"",AF117<>"",$D$12>0,$Q$12>0,$AD$12>0),SUM(P117,AC117,AF117),"")) | AH117: =IFERROR(_xlfn.XLOOKUP(AG117,HELPER!$C$7:$C$47,HELPER!$D$7:$D$47,,1),"")
...

Sheet Term 2
B2: Senior High School Class Record
B3: (Pursuant to DepEd Order No. 8, s. 2015 and DepEd Order No. 15, s. 2026)
G6: REGION | H6: =UPPER('INPUT DATA'!F10) -> CAR | O6: DIVISION | P6: =UPPER('INPUT DATA'!F11) | Z6: SCHOOL ID | AA6: =IF('INPUT DATA'!F13="","",'INPUT DATA'!F13)
G7: SCHOOL NAME | H7: =UPPER('INPUT DATA'!F14) | Z7: SCHOOL YEAR | AA7: ='INPUT DATA'!F16&" "&'INPUT DATA'!G16 -> 2026 – 2027
B8: =IF(OR(HELPER!G23="2ND",HELPER!G23="1ST & 2ND",HELPER!G23="2ND & 3RD",HELPER!G23="1ST, 2ND, 3RD"),"","INCORRECT SHEET. Do not use this sheet to input data.")
B9: SECOND TERM | D9: GRADE LEVEL | H9: =IFERROR(IF(B8<>"INCORRECT SHEET. Do not use this sheet to input data.",'INPUT DATA'!F24,""),"") -> 12 | J9: SECTION | N9: =IFERROR(IF(B8<>"INCORRECT SHEET. Do not use this sheet to input data.",UPPER('INPUT DATA'!F25),""),"") | Q9: SUBJECT | U9: =IFERROR(IF(B8<>"INCORRECT SHEET. Do not use this sheet to input data.",UPPER(HELPER!G10),""),"") -> TITLE
D10: TEACHER | H10: =IFERROR(IF(B8<>"INCORRECT SHEET. Do not use this sheet to input data.",UPPER('INPUT DATA'!F22),""),"") | Q10: CLUSTER | U10: =IFERROR(IF(B8<>"INCORRECT SHEET. Do not use this sheet to input data.",UPPER(HELPER!G9),""),"") -> ACADEMIC TRACK (EXCEPT IMMERSION)
D11: WRITTEN / ORAL WORKS | Q11: PRODUCT / PERFORMANCE TASKS | AD11: TERM EXAM | AG11: INITIAL GRADE | AH11: TERM GRADE
D12: =IF($U$9<>"",IFERROR(_xlfn.IFNA(HELPER!G13/100,""),""),"") -> 0.25 | Q12: =IF($U$9<>"",IFERROR(_xlfn.IFNA(HELPER!G14/100,""),""),"") -> 0.45 | AD12: =IF($U$9<>"",IFERROR(_xlfn.IFNA(HELPER!G15/100,""),""),"") -> 0.3
D13: 1 | E13: 2 | F13: 3 | G13: 4 | H13: 5 | I13: 6 | J13: 7 | K13: 8 | L13: 9 | M13: 10 | N13: TOTAL | O13: PS | P13: WS | Q13: 1 | R13: 2 | S13: 3 | T13: 4 | U13: 5 | V13: 6 | W13: 7 | X13: 8 | Y13: 9 | Z13: 10 | AA13: TOTAL | AB13: PS | AC13: WS | AD13: TE | AE13: PS | AF13: WS
B14: HIGHEST POSSIBLE SCORE | N14: =SUM(D14:M14) -> 0 | O14: 100 | P14: =D12 -> 0.25 | AA14: =SUM(Q14:Z14) -> 0 | AB14: 100 | AC14: =Q12 -> 0.45 | AE14: =IF(AD12=0,"",100) -> 100 | AF14: =AD12 -> 0.3
B15: LEARNERS' NAMES
B16: MALE
B17: 1 | C17: =IFERROR(IF(OR($B$8="INCORRECT SHEET. Do not use this sheet to input data.",'INPUT DATA'!O11=""),"",'INPUT DATA'!O11),"") | N17: =IF(COUNT(D17:M17)=0,"",SUM(D17:M17)) | O17: =IFERROR(IF(N17="","",ROUND(N17/N$14*O$14,2)),"") | P17: =IFERROR(IF(O17="","",ROUND(O17*P$14,2)),"") | AA17: =IF(COUNT(Q17:Z17)=0,"",SUM(Q17:Z17)) | AB17: =IFERROR(IF(AA17="","",ROUND(AA17/AA$14*AB$14,2)),"") | AC17: =IFERROR(IF(AB17="","",ROUND(AB17*AC$14,2)),"") | AE17: =IFERROR(IF(AD17="","",ROUND(AD17/$AD$14,2)*100),"") | AF17: =IFERROR(IF(AE17="","",ROUND(AE17*$AF$14,2)),"") | AG17: =IF(AND(C17<>"",P17<>"",AC17<>"",$AD$12=0),SUM(P17,AC17),IF(AND(C17<>"",P17<>"",AC17<>"",AF17<>"",$D$12>0,$Q$12>0,$AD$12>0),SUM(P17,AC17,AF17),"")) | AH17: =IFERROR(_xlfn.XLOOKUP(AG17,HELPER!$C$7:$C$47,HELPER!$D$7:$D$47,,1),"")
B18: 2 | C18: =IFERROR(IF(OR($B$8="INCORRECT SHEET. Do not use this sheet to input data.",'INPUT DATA'!O12=""),"",'INPUT DATA'!O12),"") | N18: =IF(COUNT(D18:M18)=0,"",SUM(D18:M18)) | O18: =IFERROR(IF(N18="","",ROUND(N18/N$14*O$14,2)),"") | P18: =IFERROR(IF(O18="","",ROUND(O18*P$14,2)),"") | AA18: =IF(COUNT(Q18:Z18)=0,"",SUM(Q18:Z18)) | AB18: =IFERROR(IF(AA18="","",ROUND(AA18/AA$14*AB$14,2)),"") | AC18: =IFERROR(IF(AB18="","",ROUND(AB18*AC$14,2)),"") | AE18: =IFERROR(IF(AD18="","",ROUND(AD18/$AD$14,2)*100),"") | AF18: =IFERROR(IF(AE18="","",ROUND(AE18*$AF$14,2)),"") | AG18: =IF(AND(C18<>"",P18<>"",AC18<>"",$AD$12=0),SUM(P18,AC18),IF(AND(C18<>"",P18<>"",AC18<>"",AF18<>"",$D$12>0,$Q$12>0,$AD$12>0),SUM(P18,AC18,AF18),"")) | AH18: =IFERROR(_xlfn.XLOOKUP(AG18,HELPER!$C$7:$C$47,HELPER!$D$7:$D$47,,1),"")
B19: 3 | C19: =IFERROR(IF(OR($B$8="INCORRECT SHEET. Do not use this sheet to input data.",'INPUT DATA'!O13=""),"",'INPUT DATA'!O13),"") | N19: =IF(COUNT(D19:M19)=0,"",SUM(D19:M19)) | O19: =IFERROR(IF(N19="","",ROUND(N19/N$14*O$14,2)),"") | P19: =IFERROR(IF(O19="","",ROUND(O19*P$14,2)),"") | AA19: =IF(COUNT(Q19:Z19)=0,"",SUM(Q19:Z19)) | AB19: =IFERROR(IF(AA19="","",ROUND(AA19/AA$14*AB$14,2)),"") | AC19: =IFERROR(IF(AB19="","",ROUND(AB19*AC$14,2)),"") | AE19: =IFERROR(IF(AD19="","",ROUND(AD19/$AD$14,2)*100),"") | AF19: =IFERROR(IF(AE19="","",ROUND(AE19*$AF$14,2)),"") | AG19: =IF(AND(C19<>"",P19<>"",AC19<>"",$AD$12=0),SUM(P19,AC19),IF(AND(C19<>"",P19<>"",AC19<>"",AF19<>"",$D$12>0,$Q$12>0,$AD$12>0),SUM(P19,AC19,AF19),"")) | AH19: =IFERROR(_xlfn.XLOOKUP(AG19,HELPER!$C$7:$C$47,HELPER!$D$7:$D$47,,1),"")
B20: 4 | C20: =IFERROR(IF(OR($B$8="INCORRECT SHEET. Do not use this sheet to input data.",'INPUT DATA'!O14=""),"",'INPUT DATA'!O14),"") | N20: =IF(COUNT(D20:M20)=0,"",SUM(D20:M20)) | O20: =IFERROR(IF(N20="","",ROUND(N20/N$14*O$14,2)),"") | P20: =IFERROR(IF(O20="","",ROUND(O20*P$14,2)),"") | AA20: =IF(COUNT(Q20:Z20)=0,"",SUM(Q20:Z20)) | AB20: =IFERROR(IF(AA20="","",ROUND(AA20/AA$14*AB$14,2)),"") | AC20: =IFERROR(IF(AB20="","",ROUND(AB20*AC$14,2)),"") | AE20: =IFERROR(IF(AD20="","",ROUND(AD20/$AD$14,2)*100),"") | AF20: =IFERROR(IF(AE20="","",ROUND(AE20*$AF$14,2)),"") | AG20: =IF(AND(C20<>"",P20<>"",AC20<>"",$AD$12=0),SUM(P20,AC20),IF(AND(C20<>"",P20<>"",AC20<>"",AF20<>"",$D$12>0,$Q$12>0,$AD$12>0),SUM(P20,AC20,AF20),"")) | AH20: =IFERROR(_xlfn.XLOOKUP(AG20,HELPER!$C$7:$C$47,HELPER!$D$7:$D$47,,1),"")
B21: 5 | C21: =IFERROR(IF(OR($B$8="INCORRECT SHEET. Do not use this sheet to input data.",'INPUT DATA'!O15=""),"",'INPUT DATA'!O15),"") | N21: =IF(COUNT(D21:M21)=0,"",SUM(D21:M21)) | O21: =IFERROR(IF(N21="","",ROUND(N21/N$14*O$14,2)),"") | P21: =IFERROR(IF(O21="","",ROUND(O21*P$14,2)),"") | AA21: =IF(COUNT(Q21:Z21)=0,"",SUM(Q21:Z21)) | AB21: =IFERROR(IF(AA21="","",ROUND(AA21/AA$14*AB$14,2)),"") | AC21: =IFERROR(IF(AB21="","",ROUND(AB21*AC$14,2)),"") | AE21: =IFERROR(IF(AD21="","",ROUND(AD21/$AD$14,2)*100),"") | AF21: =IFERROR(IF(AE21="","",ROUND(AE21*$AF$14,2)),"") | AG21: =IF(AND(C21<>"",P21<>"",AC21<>"",$AD$12=0),SUM(P21,AC21),IF(AND(C21<>"",P21<>"",AC21<>"",AF21<>"",$D$12>0,$Q$12>0,$AD$12>0),SUM(P21,AC21,AF21),"")) | AH21: =IFERROR(_xlfn.XLOOKUP(AG21,HELPER!$C$7:$C$47,HELPER!$D$7:$D$47,,1),"")
B22: 6 | C22: =IFERROR(IF(OR($B$8="INCORRECT SHEET. Do not use this sheet to input data.",'INPUT DATA'!O16=""),"",'INPUT DATA'!O16),"") | N22: =IF(COUNT(D22:M22)=0,"",SUM(D22:M22)) | O22: =IFERROR(IF(N22="","",ROUND(N22/N$14*O$14,2)),"") | P22: =IFERROR(IF(O22="","",ROUND(O22*P$14,2)),"") | AA22: =IF(COUNT(Q22:Z22)=0,"",SUM(Q22:Z22)) | AB22: =IFERROR(IF(AA22="","",ROUND(AA22/AA$14*AB$14,2)),"") | AC22: =IFERROR(IF(AB22="","",ROUND(AB22*AC$14,2)),"") | AE22: =IFERROR(IF(AD22="","",ROUND(AD22/$AD$14,2)*100),"") | AF22: =IFERROR(IF(AE22="","",ROUND(AE22*$AF$14,2)),"") | AG22: =IF(AND(C22<>"",P22<>"",AC22<>"",$AD$12=0),SUM(P22,AC22),IF(AND(C22<>"",P22<>"",AC22<>"",AF22<>"",$D$12>0,$Q$12>0,$AD$12>0),SUM(P22,AC22,AF22),"")) | AH22: =IFERROR(_xlfn.XLOOKUP(AG22,HELPER!$C$7:$C$47,HELPER!$D$7:$D$47,,1),"")
B23: 7 | C23: =IFERROR(IF(OR($B$8="INCORRECT SHEET. Do not use this sheet to input data.",'INPUT DATA'!O17=""),"",'INPUT DATA'!O17),"") | N23: =IF(COUNT(D23:M23)=0,"",SUM(D23:M23)) | O23: =IFERROR(IF(N23="","",ROUND(N23/N$14*O$14,2)),"") | P23: =IFERROR(IF(O23="","",ROUND(O23*P$14,2)),"") | AA23: =IF(COUNT(Q23:Z23)=0,"",SUM(Q23:Z23)) | AB23: =IFERROR(IF(AA23="","",ROUND(AA23/AA$14*AB$14,2)),"") | AC23: =IFERROR(IF(AB23="","",ROUND(AB23*AC$14,2)),"") | AE23: =IFERROR(IF(AD23="","",ROUND(AD23/$AD$14,2)*100),"") | AF23: =IFERROR(IF(AE23="","",ROUND(AE23*$AF$14,2)),"") | AG23: =IF(AND(C23<>"",P23<>"",AC23<>"",$AD$12=0),SUM(P23,AC23),IF(AND(C23<>"",P23<>"",AC23<>"",AF23<>"",$D$12>0,$Q$12>0,$AD$12>0),SUM(P23,AC23,AF23),"")) | AH23: =IFERROR(_xlfn.XLOOKUP(AG23,HELPER!$C$7:$C$47,HELPER!$D$7:$D$47,,1),"")
B24: 8 | C24: =IFERROR(IF(OR($B$8="INCORRECT SHEET. Do not use this sheet to input data.",'INPUT DATA'!O18=""),"",'INPUT DATA'!O18),"") | N24: =IF(COUNT(D24:M24)=0,"",SUM(D24:M24)) | O24: =IFERROR(IF(N24="","",ROUND(N24/N$14*O$14,2)),"") | P24: =IFERROR(IF(O24="","",ROUND(O24*P$14,2)),"") | AA24: =IF(COUNT(Q24:Z24)=0,"",SUM(Q24:Z24)) | AB24: =IFERROR(IF(AA24="","",ROUND(AA24/AA$14*AB$14,2)),"") | AC24: =IFERROR(IF(AB24="","",ROUND(AB24*AC$14,2)),"") | AE24: =IFERROR(IF(AD24="","",ROUND(AD24/$AD$14,2)*100),"") | AF24: =IFERROR(IF(AE24="","",ROUND(AE24*$AF$14,2)),"") | AG24: =IF(AND(C24<>"",P24<>"",AC24<>"",$AD$12=0),SUM(P24,AC24),IF(AND(C24<>"",P24<>"",AC24<>"",AF24<>"",$D$12>0,$Q$12>0,$AD$12>0),SUM(P24,AC24,AF24),"")) | AH24: =IFERROR(_xlfn.XLOOKUP(AG24,HELPER!$C$7:$C$47,HELPER!$D$7:$D$47,,1),"")
B25: 9 | C25: =IFERROR(IF(OR($B$8="INCORRECT SHEET. Do not use this sheet to input data.",'INPUT DATA'!O19=""),"",'INPUT DATA'!O19),"") | N25: =IF(COUNT(D25:M25)=0,"",SUM(D25:M25)) | O25: =IFERROR(IF(N25="","",ROUND(N25/N$14*O$14,2)),"") | P25: =IFERROR(IF(O25="","",ROUND(O25*P$14,2)),"") | AA25: =IF(COUNT(Q25:Z25)=0,"",SUM(Q25:Z25)) | AB25: =IFERROR(IF(AA25="","",ROUND(AA25/AA$14*AB$14,2)),"") | AC25: =IFERROR(IF(AB25="","",ROUND(AB25*AC$14,2)),"") | AE25: =IFERROR(IF(AD25="","",ROUND(AD25/$AD$14,2)*100),"") | AF25: =IFERROR(IF(AE25="","",ROUND(AE25*$AF$14,2)),"") | AG25: =IF(AND(C25<>"",P25<>"",AC25<>"",$AD$12=0),SUM(P25,AC25),IF(AND(C25<>"",P25<>"",AC25<>"",AF25<>"",$D$12>0,$Q$12>0,$AD$12>0),SUM(P25,AC25,AF25),"")) | AH25: =IFERROR(_xlfn.XLOOKUP(AG25,HELPER!$C$7:$C$47,HELPER!$D$7:$D$47,,1),"")
B26: 10 | C26: =IFERROR(IF(OR($B$8="INCORRECT SHEET. Do not use this sheet to input data.",'INPUT DATA'!O20=""),"",'INPUT DATA'!O20),"") | N26: =IF(COUNT(D26:M26)=0,"",SUM(D26:M26)) | O26: =IFERROR(IF(N26="","",ROUND(N26/N$14*O$14,2)),"") | P26: =IFERROR(IF(O26="","",ROUND(O26*P$14,2)),"") | AA26: =IF(COUNT(Q26:Z26)=0,"",SUM(Q26:Z26)) | AB26: =IFERROR(IF(AA26="","",ROUND(AA26/AA$14*AB$14,2)),"") | AC26: =IFERROR(IF(AB26="","",ROUND(AB26*AC$14,2)),"") | AE26: =IFERROR(IF(AD26="","",ROUND(AD26/$AD$14,2)*100),"") | AF26: =IFERROR(IF(AE26="","",ROUND(AE26*$AF$14,2)),"") | AG26: =IF(AND(C26<>"",P26<>"",AC26<>"",$AD$12=0),SUM(P26,AC26),IF(AND(C26<>"",P26<>"",AC26<>"",AF26<>"",$D$12>0,$Q$12>0,$AD$12>0),SUM(P26,AC26,AF26),"")) | AH26: =IFERROR(_xlfn.XLOOKUP(AG26,HELPER!$C$7:$C$47,HELPER!$D$7:$D$47,,1),"")
B27: 11 | C27: =IFERROR(IF(OR($B$8="INCORRECT SHEET. Do not use this sheet to input data.",'INPUT DATA'!O21=""),"",'INPUT DATA'!O21),"") | N27: =IF(COUNT(D27:M27)=0,"",SUM(D27:M27)) | O27: =IFERROR(IF(N27="","",ROUND(N27/N$14*O$14,2)),"") | P27: =IFERROR(IF(O27="","",ROUND(O27*P$14,2)),"") | AA27: =IF(COUNT(Q27:Z27)=0,"",SUM(Q27:Z27)) | AB27: =IFERROR(IF(AA27="","",ROUND(AA27/AA$14*AB$14,2)),"") | AC27: =IFERROR(IF(AB27="","",ROUND(AB27*AC$14,2)),"") | AE27: =IFERROR(IF(AD27="","",ROUND(AD27/$AD$14,2)*100),"") | AF27: =IFERROR(IF(AE27="","",ROUND(AE27*$AF$14,2)),"") | AG27: =IF(AND(C27<>"",P27<>"",AC27<>"",$AD$12=0),SUM(P27,AC27),IF(AND(C27<>"",P27<>"",AC27<>"",AF27<>"",$D$12>0,$Q$12>0,$AD$12>0),SUM(P27,AC27,AF27),"")) | AH27: =IFERROR(_xlfn.XLOOKUP(AG27,HELPER!$C$7:$C$47,HELPER!$D$7:$D$47,,1),"")
B28: 12 | C28: =IFERROR(IF(OR($B$8="INCORRECT SHEET. Do not use this sheet to input data.",'INPUT DATA'!O22=""),"",'INPUT DATA'!O22),"") | N28: =IF(COUNT(D28:M28)=0,"",SUM(D28:M28)) | O28: =IFERROR(IF(N28="","",ROUND(N28/N$14*O$14,2)),"") | P28: =IFERROR(IF(O28="","",ROUND(O28*P$14,2)),"") | AA28: =IF(COUNT(Q28:Z28)=0,"",SUM(Q28:Z28)) | AB28: =IFERROR(IF(AA28="","",ROUND(AA28/AA$14*AB$14,2)),"") | AC28: =IFERROR(IF(AB28="","",ROUND(AB28*AC$14,2)),"") | AE28: =IFERROR(IF(AD28="","",ROUND(AD28/$AD$14,2)*100),"") | AF28: =IFERROR(IF(AE28="","",ROUND(AE28*$AF$14,2)),"") | AG28: =IF(AND(C28<>"",P28<>"",AC28<>"",$AD$12=0),SUM(P28,AC28),IF(AND(C28<>"",P28<>"",AC28<>"",AF28<>"",$D$12>0,$Q$12>0,$AD$12>0),SUM(P28,AC28,AF28),"")) | AH28: =IFERROR(_xlfn.XLOOKUP(AG28,HELPER!$C$7:$C$47,HELPER!$D$7:$D$47,,1),"")
... B66: 50 | C66: =IFERROR(IF(OR($B$8="INCORRECT SHEET. Do not use this sheet to input data.",'INPUT DATA'!O60=""),"",'INPUT DATA'!O60),"") | N66: =IF(COUNT(D66:M66)=0,"",SUM(D66:M66)) | O66: =IFERROR(IF(N66="","",ROUND(N66/N$14*O$14,2)),"") | P66: =IFERROR(IF(O66="","",ROUND(O66*P$14,2)),"") | AA66: =IF(COUNT(Q66:Z66)=0,"",SUM(Q66:Z66)) | AB66: =IFERROR(IF(AA66="","",ROUND(AA66/AA$14*AB$14,2)),"") | AC66: =IFERROR(IF(AB66="","",ROUND(AB66*AC$14,2)),"") | AE66: =IFERROR(IF(AD66="","",ROUND(AD66/$AD$14,2)*100),"") | AF66: =IFERROR(IF(AE66="","",ROUND(AE66*$AF$14,2)),"") | AG66: =IF(AND(C66<>"",P66<>"",AC66<>"",$AD$12=0),SUM(P66,AC66),IF(AND(C66<>"",P66<>"",AC66<>"",AF66<>"",$D$12>0,$Q$12>0,$AD$12>0),SUM(P66,AC66,AF66),"")) | AH66: =IFERROR(_xlfn.XLOOKUP(AG66,HELPER!$C$7:$C$47,HELPER!$D$7:$D$47,,1),"")
B67: FEMALE
B68: 1 | C68: =IFERROR(IF(OR($B$8="INCORRECT SHEET. Do not use this sheet to input data.",'INPUT DATA'!S11=""),"",'INPUT DATA'!S11),"") | N68: =IF(COUNT(D68:M68)=0,"",SUM(D68:M68)) | O68: =IFERROR(IF(N68="","",ROUND(N68/N$14*O$14,2)),"") | P68: =IFERROR(IF(O68="","",ROUND(O68*P$14,2)),"") | AA68: =IF(COUNT(Q68:Z68)=0,"",SUM(Q68:Z68)) | AB68: =IFERROR(IF(AA68="","",ROUND(AA68/AA$14*AB$14,2)),"") | AC68: =IFERROR(IF(AB68="","",ROUND(AB68*AC$14,2)),"") | AE68: =IFERROR(IF(AD68="","",ROUND(AD68/$AD$14,2)*100),"") | AF68: =IFERROR(IF(AE68="","",ROUND(AE68*$AF$14,2)),"") | AG68: =IF(AND(C68<>"",P68<>"",AC68<>"",$AD$12=0),SUM(P68,AC68),IF(AND(C68<>"",P68<>"",AC68<>"",AF68<>"",$D$12>0,$Q$12>0,$AD$12>0),SUM(P68,AC68,AF68),"")) | AH68: =IFERROR(_xlfn.XLOOKUP(AG68,HELPER!$C$7:$C$47,HELPER!$D$7:$D$47,,1),"")
B69: 2 | C69: =IFERROR(IF(OR($B$8="INCORRECT SHEET. Do not use this sheet to input data.",'INPUT DATA'!S12=""),"",'INPUT DATA'!S12),"") | N69: =IF(COUNT(D69:M69)=0,"",SUM(D69:M69)) | O69: =IFERROR(IF(N69="","",ROUND(N69/N$14*O$14,2)),"") | P69: =IFERROR(IF(O69="","",ROUND(O69*P$14,2)),"") | AA69: =IF(COUNT(Q69:Z69)=0,"",SUM(Q69:Z69)) | AB69: =IFERROR(IF(AA69="","",ROUND(AA69/AA$14*AB$14,2)),"") | AC69: =IFERROR(IF(AB69="","",ROUND(AB69*AC$14,2)),"") | AE69: =IFERROR(IF(AD69="","",ROUND(AD69/$AD$14,2)*100),"") | AF69: =IFERROR(IF(AE69="","",ROUND(AE69*$AF$14,2)),"") | AG69: =IF(AND(C69<>"",P69<>"",AC69<>"",$AD$12=0),SUM(P69,AC69),IF(AND(C69<>"",P69<>"",AC69<>"",AF69<>"",$D$12>0,$Q$12>0,$AD$12>0),SUM(P69,AC69,AF69),"")) | AH69: =IFERROR(_xlfn.XLOOKUP(AG69,HELPER!$C$7:$C$47,HELPER!$D$7:$D$47,,1),"")
B70: 3 | C70: =IFERROR(IF(OR($B$8="INCORRECT SHEET. Do not use this sheet to input data.",'INPUT DATA'!S13=""),"",'INPUT DATA'!S13),"") | N70: =IF(COUNT(D70:M70)=0,"",SUM(D70:M70)) | O70: =IFERROR(IF(N70="","",ROUND(N70/N$14*O$14,2)),"") | P70: =IFERROR(IF(O70="","",ROUND(O70*P$14,2)),"") | AA70: =IF(COUNT(Q70:Z70)=0,"",SUM(Q70:Z70)) | AB70: =IFERROR(IF(AA70="","",ROUND(AA70/AA$14*AB$14,2)),"") | AC70: =IFERROR(IF(AB70="","",ROUND(AB70*AC$14,2)),"") | AE70: =IFERROR(IF(AD70="","",ROUND(AD70/$AD$14,2)*100),"") | AF70: =IFERROR(IF(AE70="","",ROUND(AE70*$AF$14,2)),"") | AG70: =IF(AND(C70<>"",P70<>"",AC70<>"",$AD$12=0),SUM(P70,AC70),IF(AND(C70<>"",P70<>"",AC70<>"",AF70<>"",$D$12>0,$Q$12>0,$AD$12>0),SUM(P70,AC70,AF70),"")) | AH70: =IFERROR(_xlfn.XLOOKUP(AG70,HELPER!$C$7:$C$47,HELPER!$D$7:$D$47,,1),"")
B71: 4 | C71: =IFERROR(IF(OR($B$8="INCORRECT SHEET. Do not use this sheet to input data.",'INPUT DATA'!S14=""),"",'INPUT DATA'!S14),"") | N71: =IF(COUNT(D71:M71)=0,"",SUM(D71:M71)) | O71: =IFERROR(IF(N71="","",ROUND(N71/N$14*O$14,2)),"") | P71: =IFERROR(IF(O71="","",ROUND(O71*P$14,2)),"") | AA71: =IF(COUNT(Q71:Z71)=0,"",SUM(Q71:Z71)) | AB71: =IFERROR(IF(AA71="","",ROUND(AA71/AA$14*AB$14,2)),"") | AC71: =IFERROR(IF(AB71="","",ROUND(AB71*AC$14,2)),"") | AE71: =IFERROR(IF(AD71="","",ROUND(AD71/$AD$14,2)*100),"") | AF71: =IFERROR(IF(AE71="","",ROUND(AE71*$AF$14,2)),"") | AG71: =IF(AND(C71<>"",P71<>"",AC71<>"",$AD$12=0),SUM(P71,AC71),IF(AND(C71<>"",P71<>"",AC71<>"",AF71<>"",$D$12>0,$Q$12>0,$AD$12>0),SUM(P71,AC71,AF71),"")) | AH71: =IFERROR(_xlfn.XLOOKUP(AG71,HELPER!$C$7:$C$47,HELPER!$D$7:$D$47,,1),"")
B72: 5 | C72: =IFERROR(IF(OR($B$8="INCORRECT SHEET. Do not use this sheet to input data.",'INPUT DATA'!S15=""),"",'INPUT DATA'!S15),"") | N72: =IF(COUNT(D72:M72)=0,"",SUM(D72:M72)) | O72: =IFERROR(IF(N72="","",ROUND(N72/N$14*O$14,2)),"") | P72: =IFERROR(IF(O72="","",ROUND(O72*P$14,2)),"") | AA72: =IF(COUNT(Q72:Z72)=0,"",SUM(Q72:Z72)) | AB72: =IFERROR(IF(AA72="","",ROUND(AA72/AA$14*AB$14,2)),"") | AC72: =IFERROR(IF(AB72="","",ROUND(AB72*AC$14,2)),"") | AE72: =IFERROR(IF(AD72="","",ROUND(AD72/$AD$14,2)*100),"") | AF72: =IFERROR(IF(AE72="","",ROUND(AE72*$AF$14,2)),"") | AG72: =IF(AND(C72<>"",P72<>"",AC72<>"",$AD$12=0),SUM(P72,AC72),IF(AND(C72<>"",P72<>"",AC72<>"",AF72<>"",$D$12>0,$Q$12>0,$AD$12>0),SUM(P72,AC72,AF72),"")) | AH72: =IFERROR(_xlfn.XLOOKUP(AG72,HELPER!$C$7:$C$47,HELPER!$D$7:$D$47,,1),"")
B73: 6 | C73: =IFERROR(IF(OR($B$8="INCORRECT SHEET. Do not use this sheet to input data.",'INPUT DATA'!S16=""),"",'INPUT DATA'!S16),"") | N73: =IF(COUNT(D73:M73)=0,"",SUM(D73:M73)) | O73: =IFERROR(IF(N73="","",ROUND(N73/N$14*O$14,2)),"") | P73: =IFERROR(IF(O73="","",ROUND(O73*P$14,2)),"") | AA73: =IF(COUNT(Q73:Z73)=0,"",SUM(Q73:Z73)) | AB73: =IFERROR(IF(AA73="","",ROUND(AA73/AA$14*AB$14,2)),"") | AC73: =IFERROR(IF(AB73="","",ROUND(AB73*AC$14,2)),"") | AE73: =IFERROR(IF(AD73="","",ROUND(AD73/$AD$14,2)*100),"") | AF73: =IFERROR(IF(AE73="","",ROUND(AE73*$AF$14,2)),"") | AG73: =IF(AND(C73<>"",P73<>"",AC73<>"",$AD$12=0),SUM(P73,AC73),IF(AND(C73<>"",P73<>"",AC73<>"",AF73<>"",$D$12>0,$Q$12>0,$AD$12>0),SUM(P73,AC73,AF73),"")) | AH73: =IFERROR(_xlfn.XLOOKUP(AG73,HELPER!$C$7:$C$47,HELPER!$D$7:$D$47,,1),"")
B74: 7 | C74: =IFERROR(IF(OR($B$8="INCORRECT SHEET. Do not use this sheet to input data.",'INPUT DATA'!S17=""),"",'INPUT DATA'!S17),"") | N74: =IF(COUNT(D74:M74)=0,"",SUM(D74:M74)) | O74: =IFERROR(IF(N74="","",ROUND(N74/N$14*O$14,2)),"") | P74: =IFERROR(IF(O74="","",ROUND(O74*P$14,2)),"") | AA74: =IF(COUNT(Q74:Z74)=0,"",SUM(Q74:Z74)) | AB74: =IFERROR(IF(AA74="","",ROUND(AA74/AA$14*AB$14,2)),"") | AC74: =IFERROR(IF(AB74="","",ROUND(AB74*AC$14,2)),"") | AE74: =IFERROR(IF(AD74="","",ROUND(AD74/$AD$14,2)*100),"") | AF74: =IFERROR(IF(AE74="","",ROUND(AE74*$AF$14,2)),"") | AG74: =IF(AND(C74<>"",P74<>"",AC74<>"",$AD$12=0),SUM(P74,AC74),IF(AND(C74<>"",P74<>"",AC74<>"",AF74<>"",$D$12>0,$Q$12>0,$AD$12>0),SUM(P74,AC74,AF74),"")) | AH74: =IFERROR(_xlfn.XLOOKUP(AG74,HELPER!$C$7:$C$47,HELPER!$D$7:$D$47,,1),"")
B75: 8 | C75: =IFERROR(IF(OR($B$8="INCORRECT SHEET. Do not use this sheet to input data.",'INPUT DATA'!S18=""),"",'INPUT DATA'!S18),"") | N75: =IF(COUNT(D75:M75)=0,"",SUM(D75:M75)) | O75: =IFERROR(IF(N75="","",ROUND(N75/N$14*O$14,2)),"") | P75: =IFERROR(IF(O75="","",ROUND(O75*P$14,2)),"") | AA75: =IF(COUNT(Q75:Z75)=0,"",SUM(Q75:Z75)) | AB75: =IFERROR(IF(AA75="","",ROUND(AA75/AA$14*AB$14,2)),"") | AC75: =IFERROR(IF(AB75="","",ROUND(AB75*AC$14,2)),"") | AE75: =IFERROR(IF(AD75="","",ROUND(AD75/$AD$14,2)*100),"") | AF75: =IFERROR(IF(AE75="","",ROUND(AE75*$AF$14,2)),"") | AG75: =IF(AND(C75<>"",P75<>"",AC75<>"",$AD$12=0),SUM(P75,AC75),IF(AND(C75<>"",P75<>"",AC75<>"",AF75<>"",$D$12>0,$Q$12>0,$AD$12>0),SUM(P75,AC75,AF75),"")) | AH75: =IFERROR(_xlfn.XLOOKUP(AG75,HELPER!$C$7:$C$47,HELPER!$D$7:$D$47,,1),"")
B76: 9 | C76: =IFERROR(IF(OR($B$8="INCORRECT SHEET. Do not use this sheet to input data.",'INPUT DATA'!S19=""),"",'INPUT DATA'!S19),"") | N76: =IF(COUNT(D76:M76)=0,"",SUM(D76:M76)) | O76: =IFERROR(IF(N76="","",ROUND(N76/N$14*O$14,2)),"") | P76: =IFERROR(IF(O76="","",ROUND(O76*P$14,2)),"") | AA76: =IF(COUNT(Q76:Z76)=0,"",SUM(Q76:Z76)) | AB76: =IFERROR(IF(AA76="","",ROUND(AA76/AA$14*AB$14,2)),"") | AC76: =IFERROR(IF(AB76="","",ROUND(AB76*AC$14,2)),"") | AE76: =IFERROR(IF(AD76="","",ROUND(AD76/$AD$14,2)*100),"") | AF76: =IFERROR(IF(AE76="","",ROUND(AE76*$AF$14,2)),"") | AG76: =IF(AND(C76<>"",P76<>"",AC76<>"",$AD$12=0),SUM(P76,AC76),IF(AND(C76<>"",P76<>"",AC76<>"",AF76<>"",$D$12>0,$Q$12>0,$AD$12>0),SUM(P76,AC76,AF76),"")) | AH76: =IFERROR(_xlfn.XLOOKUP(AG76,HELPER!$C$7:$C$47,HELPER!$D$7:$D$47,,1),"")
B77: 10 | C77: =IFERROR(IF(OR($B$8="INCORRECT SHEET. Do not use this sheet to input data.",'INPUT DATA'!S20=""),"",'INPUT DATA'!S20),"") | N77: =IF(COUNT(D77:M77)=0,"",SUM(D77:M77)) | O77: =IFERROR(IF(N77="","",ROUND(N77/N$14*O$14,2)),"") | P77: =IFERROR(IF(O77="","",ROUND(O77*P$14,2)),"") | AA77: =IF(COUNT(Q77:Z77)=0,"",SUM(Q77:Z77)) | AB77: =IFERROR(IF(AA77="","",ROUND(AA77/AA$14*AB$14,2)),"") | AC77: =IFERROR(IF(AB77="","",ROUND(AB77*AC$14,2)),"") | AE77: =IFERROR(IF(AD77="","",ROUND(AD77/$AD$14,2)*100),"") | AF77: =IFERROR(IF(AE77="","",ROUND(AE77*$AF$14,2)),"") | AG77: =IF(AND(C77<>"",P77<>"",AC77<>"",$AD$12=0),SUM(P77,AC77),IF(AND(C77<>"",P77<>"",AC77<>"",AF77<>"",$D$12>0,$Q$12>0,$AD$12>0),SUM(P77,AC77,AF77),"")) | AH77: =IFERROR(_xlfn.XLOOKUP(AG77,HELPER!$C$7:$C$47,HELPER!$D$7:$D$47,,1),"")
B78: 11 | C78: =IFERROR(IF(OR($B$8="INCORRECT SHEET. Do not use this sheet to input data.",'INPUT DATA'!S21=""),"",'INPUT DATA'!S21),"") | N78: =IF(COUNT(D78:M78)=0,"",SUM(D78:M78)) | O78: =IFERROR(IF(N78="","",ROUND(N78/N$14*O$14,2)),"") | P78: =IFERROR(IF(O78="","",ROUND(O78*P$14,2)),"") | AA78: =IF(COUNT(Q78:Z78)=0,"",SUM(Q78:Z78)) | AB78: =IFERROR(IF(AA78="","",ROUND(AA78/AA$14*AB$14,2)),"") | AC78: =IFERROR(IF(AB78="","",ROUND(AB78*AC$14,2)),"") | AE78: =IFERROR(IF(AD78="","",ROUND(AD78/$AD$14,2)*100),"") | AF78: =IFERROR(IF(AE78="","",ROUND(AE78*$AF$14,2)),"") | AG78: =IF(AND(C78<>"",P78<>"",AC78<>"",$AD$12=0),SUM(P78,AC78),IF(AND(C78<>"",P78<>"",AC78<>"",AF78<>"",$D$12>0,$Q$12>0,$AD$12>0),SUM(P78,AC78,AF78),"")) | AH78: =IFERROR(_xlfn.XLOOKUP(AG78,HELPER!$C$7:$C$47,HELPER!$D$7:$D$47,,1),"")
B79: 12 | C79: =IFERROR(IF(OR($B$8="INCORRECT SHEET. Do not use this sheet to input data.",'INPUT DATA'!S22=""),"",'INPUT DATA'!S22),"") | N79: =IF(COUNT(D79:M79)=0,"",SUM(D79:M79)) | O79: =IFERROR(IF(N79="","",ROUND(N79/N$14*O$14,2)),"") | P79: =IFERROR(IF(O79="","",ROUND(O79*P$14,2)),"") | AA79: =IF(COUNT(Q79:Z79)=0,"",SUM(Q79:Z79)) | AB79: =IFERROR(IF(AA79="","",ROUND(AA79/AA$14*AB$14,2)),"") | AC79: =IFERROR(IF(AB79="","",ROUND(AB79*AC$14,2)),"") | AE79: =IFERROR(IF(AD79="","",ROUND(AD79/$AD$14,2)*100),"") | AF79: =IFERROR(IF(AE79="","",ROUND(AE79*$AF$14,2)),"") | AG79: =IF(AND(C79<>"",P79<>"",AC79<>"",$AD$12=0),SUM(P79,AC79),IF(AND(C79<>"",P79<>"",AC79<>"",AF79<>"",$D$12>0,$Q$12>0,$AD$12>0),SUM(P79,AC79,AF79),"")) | AH79: =IFERROR(_xlfn.XLOOKUP(AG79,HELPER!$C$7:$C$47,HELPER!$D$7:$D$47,,1),"")
... B117: 50 | C117: =IFERROR(IF(OR($B$8="INCORRECT SHEET. Do not use this sheet to input data.",'INPUT DATA'!S60=""),"",'INPUT DATA'!S60),"") | N117: =IF(COUNT(D117:M117)=0,"",SUM(D117:M117)) | O117: =IFERROR(IF(N117="","",ROUND(N117/N$14*O$14,2)),"") | P117: =IFERROR(IF(O117="","",ROUND(O117*P$14,2)),"") | AA117: =IF(COUNT(Q117:Z117)=0,"",SUM(Q117:Z117)) | AB117: =IFERROR(IF(AA117="","",ROUND(AA117/AA$14*AB$14,2)),"") | AC117: =IFERROR(IF(AB117="","",ROUND(AB117*AC$14,2)),"") | AE117: =IFERROR(IF(AD117="","",ROUND(AD117/$AD$14,2)*100),"") | AF117: =IFERROR(IF(AE117="","",ROUND(AE117*$AF$14,2)),"") | AG117: =IF(AND(C117<>"",P117<>"",AC117<>"",$AD$12=0),SUM(P117,AC117),IF(AND(C117<>"",P117<>"",AC117<>"",AF117<>"",$D$12>0,$Q$12>0,$AD$12>0),SUM(P117,AC117,AF117),"")) | AH117: =IFERROR(_xlfn.XLOOKUP(AG117,HELPER!$C$7:$C$47,HELPER!$D$7:$D$47,,1),"")
...

Sheet Term 3
B2: Senior High School Class Record
B3: (Pursuant to DepEd Order No. 8, s. 2015 and DepEd Order No. 15, s. 2026)
G6: REGION | H6: =UPPER('INPUT DATA'!F10) -> CAR | O6: DIVISION | P6: =UPPER('INPUT DATA'!F11) | Z6: SCHOOL ID | AA6: =IF('INPUT DATA'!F13="","",'INPUT DATA'!F13)
G7: SCHOOL NAME | H7: =UPPER('INPUT DATA'!F14) | Z7: SCHOOL YEAR | AA7: ='INPUT DATA'!F16&" "&'INPUT DATA'!G16 -> 2026 – 2027
B8: =IF(OR(HELPER!G23="3RD",HELPER!G23="2ND & 3RD",HELPER!G23="1ST, 2ND, 3RD"),"","INCORRECT SHEET. Do not use this sheet to input data.") -> INCORRECT SHEET. Do not use this sheet to input data.
B9: THIRD TERM | D9: GRADE LEVEL | H9: =IFERROR(IF(B8<>"INCORRECT SHEET. Do not use this sheet to input data.",'INPUT DATA'!F24,""),"") | J9: SECTION | N9: =IFERROR(IF(B8<>"INCORRECT SHEET. Do not use this sheet to input data.",UPPER('INPUT DATA'!F25),""),"") | Q9: SUBJECT | U9: =IFERROR(IF(B8<>"INCORRECT SHEET. Do not use this sheet to input data.",UPPER(HELPER!G10),""),"")
D10: TEACHER | H10: =IFERROR(IF(B8<>"INCORRECT SHEET. Do not use this sheet to input data.",UPPER('INPUT DATA'!F22),""),"") | Q10: CLUSTER | U10: =IFERROR(IF(B8<>"INCORRECT SHEET. Do not use this sheet to input data.",UPPER(HELPER!G9),""),"")
D11: WRITTEN / ORAL WORKS | Q11: PRODUCT / PERFORMANCE TASKS | AD11: TERM EXAM | AG11: INITIAL GRADE | AH11: TERM GRADE
D12: =IF($U$9<>"",IFERROR(_xlfn.IFNA(HELPER!G13/100,""),""),"") | Q12: =IF($U$9<>"",IFERROR(_xlfn.IFNA(HELPER!G14/100,""),""),"") | AD12: =IF($U$9<>"",IFERROR(_xlfn.IFNA(HELPER!G15/100,""),""),"")
D13: 1 | E13: 2 | F13: 3 | G13: 4 | H13: 5 | I13: 6 | J13: 7 | K13: 8 | L13: 9 | M13: 10 | N13: TOTAL | O13: PS | P13: WS | Q13: 1 | R13: 2 | S13: 3 | T13: 4 | U13: 5 | V13: 6 | W13: 7 | X13: 8 | Y13: 9 | Z13: 10 | AA13: TOTAL | AB13: PS | AC13: WS | AD13: TE | AE13: PS | AF13: WS
B14: HIGHEST POSSIBLE SCORE | N14: =SUM(D14:M14) -> 0 | O14: 100 | P14: =D12 | AA14: =SUM(Q14:Z14) -> 0 | AB14: 100 | AC14: =Q12 | AE14: =IF(AD12=0,"",100) -> 100 | AF14: =AD12
B15: LEARNERS' NAMES
B16: MALE
B17: 1 | C17: =IFERROR(IF(OR($B$8="INCORRECT SHEET. Do not use this sheet to input data.",'INPUT DATA'!O11=""),"",'INPUT DATA'!O11),"") | N17: =IF(COUNT(D17:M17)=0,"",SUM(D17:M17)) | O17: =IFERROR(IF(N17="","",ROUND(N17/N$14*O$14,2)),"") | P17: =IFERROR(IF(O17="","",ROUND(O17*P$14,2)),"") | AA17: =IF(COUNT(Q17:Z17)=0,"",SUM(Q17:Z17)) | AB17: =IFERROR(IF(AA17="","",ROUND(AA17/AA$14*AB$14,2)),"") | AC17: =IFERROR(IF(AB17="","",ROUND(AB17*AC$14,2)),"") | AE17: =IFERROR(IF(AD17="","",ROUND(AD17/$AD$14,2)*100),"") | AF17: =IFERROR(IF(AE17="","",ROUND(AE17*$AF$14,2)),"") | AG17: =IF(AND(C17<>"",P17<>"",AC17<>"",$AD$12=0),SUM(P17,AC17),IF(AND(C17<>"",P17<>"",AC17<>"",AF17<>"",$D$12>0,$Q$12>0,$AD$12>0),SUM(P17,AC17,AF17),"")) | AH17: =IFERROR(_xlfn.XLOOKUP(AG17,HELPER!$C$7:$C$47,HELPER!$D$7:$D$47,,1),"")
B18: 2 | C18: =IFERROR(IF(OR($B$8="INCORRECT SHEET. Do not use this sheet to input data.",'INPUT DATA'!O12=""),"",'INPUT DATA'!O12),"") | N18: =IF(COUNT(D18:M18)=0,"",SUM(D18:M18)) | O18: =IFERROR(IF(N18="","",ROUND(N18/N$14*O$14,2)),"") | P18: =IFERROR(IF(O18="","",ROUND(O18*P$14,2)),"") | AA18: =IF(COUNT(Q18:Z18)=0,"",SUM(Q18:Z18)) | AB18: =IFERROR(IF(AA18="","",ROUND(AA18/AA$14*AB$14,2)),"") | AC18: =IFERROR(IF(AB18="","",ROUND(AB18*AC$14,2)),"") | AE18: =IFERROR(IF(AD18="","",ROUND(AD18/$AD$14,2)*100),"") | AF18: =IFERROR(IF(AE18="","",ROUND(AE18*$AF$14,2)),"") | AG18: =IF(AND(C18<>"",P18<>"",AC18<>"",$AD$12=0),SUM(P18,AC18),IF(AND(C18<>"",P18<>"",AC18<>"",AF18<>"",$D$12>0,$Q$12>0,$AD$12>0),SUM(P18,AC18,AF18),"")) | AH18: =IFERROR(_xlfn.XLOOKUP(AG18,HELPER!$C$7:$C$47,HELPER!$D$7:$D$47,,1),"")
B19: 3 | C19: =IFERROR(IF(OR($B$8="INCORRECT SHEET. Do not use this sheet to input data.",'INPUT DATA'!O13=""),"",'INPUT DATA'!O13),"") | N19: =IF(COUNT(D19:M19)=0,"",SUM(D19:M19)) | O19: =IFERROR(IF(N19="","",ROUND(N19/N$14*O$14,2)),"") | P19: =IFERROR(IF(O19="","",ROUND(O19*P$14,2)),"") | AA19: =IF(COUNT(Q19:Z19)=0,"",SUM(Q19:Z19)) | AB19: =IFERROR(IF(AA19="","",ROUND(AA19/AA$14*AB$14,2)),"") | AC19: =IFERROR(IF(AB19="","",ROUND(AB19*AC$14,2)),"") | AE19: =IFERROR(IF(AD19="","",ROUND(AD19/$AD$14,2)*100),"") | AF19: =IFERROR(IF(AE19="","",ROUND(AE19*$AF$14,2)),"") | AG19: =IF(AND(C19<>"",P19<>"",AC19<>"",$AD$12=0),SUM(P19,AC19),IF(AND(C19<>"",P19<>"",AC19<>"",AF19<>"",$D$12>0,$Q$12>0,$AD$12>0),SUM(P19,AC19,AF19),"")) | AH19: =IFERROR(_xlfn.XLOOKUP(AG19,HELPER!$C$7:$C$47,HELPER!$D$7:$D$47,,1),"")
B20: 4 | C20: =IFERROR(IF(OR($B$8="INCORRECT SHEET. Do not use this sheet to input data.",'INPUT DATA'!O14=""),"",'INPUT DATA'!O14),"") | N20: =IF(COUNT(D20:M20)=0,"",SUM(D20:M20)) | O20: =IFERROR(IF(N20="","",ROUND(N20/N$14*O$14,2)),"") | P20: =IFERROR(IF(O20="","",ROUND(O20*P$14,2)),"") | AA20: =IF(COUNT(Q20:Z20)=0,"",SUM(Q20:Z20)) | AB20: =IFERROR(IF(AA20="","",ROUND(AA20/AA$14*AB$14,2)),"") | AC20: =IFERROR(IF(AB20="","",ROUND(AB20*AC$14,2)),"") | AE20: =IFERROR(IF(AD20="","",ROUND(AD20/$AD$14,2)*100),"") | AF20: =IFERROR(IF(AE20="","",ROUND(AE20*$AF$14,2)),"") | AG20: =IF(AND(C20<>"",P20<>"",AC20<>"",$AD$12=0),SUM(P20,AC20),IF(AND(C20<>"",P20<>"",AC20<>"",AF20<>"",$D$12>0,$Q$12>0,$AD$12>0),SUM(P20,AC20,AF20),"")) | AH20: =IFERROR(_xlfn.XLOOKUP(AG20,HELPER!$C$7:$C$47,HELPER!$D$7:$D$47,,1),"")
B21: 5 | C21: =IFERROR(IF(OR($B$8="INCORRECT SHEET. Do not use this sheet to input data.",'INPUT DATA'!O15=""),"",'INPUT DATA'!O15),"") | N21: =IF(COUNT(D21:M21)=0,"",SUM(D21:M21)) | O21: =IFERROR(IF(N21="","",ROUND(N21/N$14*O$14,2)),"") | P21: =IFERROR(IF(O21="","",ROUND(O21*P$14,2)),"") | AA21: =IF(COUNT(Q21:Z21)=0,"",SUM(Q21:Z21)) | AB21: =IFERROR(IF(AA21="","",ROUND(AA21/AA$14*AB$14,2)),"") | AC21: =IFERROR(IF(AB21="","",ROUND(AB21*AC$14,2)),"") | AE21: =IFERROR(IF(AD21="","",ROUND(AD21/$AD$14,2)*100),"") | AF21: =IFERROR(IF(AE21="","",ROUND(AE21*$AF$14,2)),"") | AG21: =IF(AND(C21<>"",P21<>"",AC21<>"",$AD$12=0),SUM(P21,AC21),IF(AND(C21<>"",P21<>"",AC21<>"",AF21<>"",$D$12>0,$Q$12>0,$AD$12>0),SUM(P21,AC21,AF21),"")) | AH21: =IFERROR(_xlfn.XLOOKUP(AG21,HELPER!$C$7:$C$47,HELPER!$D$7:$D$47,,1),"")
B22: 6 | C22: =IFERROR(IF(OR($B$8="INCORRECT SHEET. Do not use this sheet to input data.",'INPUT DATA'!O16=""),"",'INPUT DATA'!O16),"") | N22: =IF(COUNT(D22:M22)=0,"",SUM(D22:M22)) | O22: =IFERROR(IF(N22="","",ROUND(N22/N$14*O$14,2)),"") | P22: =IFERROR(IF(O22="","",ROUND(O22*P$14,2)),"") | AA22: =IF(COUNT(Q22:Z22)=0,"",SUM(Q22:Z22)) | AB22: =IFERROR(IF(AA22="","",ROUND(AA22/AA$14*AB$14,2)),"") | AC22: =IFERROR(IF(AB22="","",ROUND(AB22*AC$14,2)),"") | AE22: =IFERROR(IF(AD22="","",ROUND(AD22/$AD$14,2)*100),"") | AF22: =IFERROR(IF(AE22="","",ROUND(AE22*$AF$14,2)),"") | AG22: =IF(AND(C22<>"",P22<>"",AC22<>"",$AD$12=0),SUM(P22,AC22),IF(AND(C22<>"",P22<>"",AC22<>"",AF22<>"",$D$12>0,$Q$12>0,$AD$12>0),SUM(P22,AC22,AF22),"")) | AH22: =IFERROR(_xlfn.XLOOKUP(AG22,HELPER!$C$7:$C$47,HELPER!$D$7:$D$47,,1),"")
